Workbook

Sheet 2025分析表
A1: TP出勤-請假 | C1: 總累計 (0.5小時/單位) | D1: 1月累計 (0.5小時/單位) | E1: 2月累計 (0.5小時/單位) | F1: 3月累計 (0.5小時/單位) | G1: 4月累計 (0.5小時/單位) | H1: 5月累計 (0.5小時/單位) | I1: 6月累計 (0.5小時/單位) | J1: 7月累計 (0.5小時/單位) | K1: 8月累計 (0.5小時/單位) | L1: 9月累計 (0.5小時/單位) | M1: 10月累計 (0.5小時/單位) | N1: 11月累計 (0.5小時/單位) | O1: 12月累計 (0.5小時/單位) | P1: 11月累計 (0.5小時/單位) | Q1: 12累計 (0.5小時/單位) | R1: 2025月份請假直條圖(1~10月)
A2: NO. | B2: 姓名
A3: 1 | B3: 郭先弘 | C3: =SUM(D3:O3) -> 0 | D3: =TP1月份請假!C3 -> 0 | E3: =TP2月份請假!C3 -> 0 | F3: =TP3月份請假!C3 -> 0 | G3: =TP4月份請假!C3 -> 0 | H3: =TP5月份請假!C3 -> 0 | I3: =TP6月份請假!C3 -> 0 | J3: =TP7月份請假!C3 -> 0 | K3: =TP8月份請假!C3 -> 0 | L3: =TP9月份請假!C3 -> 0 | M3: =TP10月份請假!C3 -> 0 | P3: =TP11月份請假!C3 -> 0 | Q3: =TP12月份請假!C3 -> 0
A4: 2 | B4: 陳淑芬 | C4: =SUM(D4:O4) -> 85 | D4: =TP1月份請假!C4 -> 10 | E4: =TP2月份請假!C4 -> 0 | F4: =TP3月份請假!C4 -> 1 | G4: =TP4月份請假!C4 -> 20 | H4: =TP5月份請假!C4 -> 2 | I4: =TP6月份請假!C4 -> 0 | J4: =TP7月份請假!C4 -> 8 | K4: =TP8月份請假!C4 -> 17 | L4: =TP9月份請假!C4 -> 2 | M4: =TP10月份請假!C4 -> 25 | P4: =TP11月份請假!C4 -> 8 | Q4: =TP12月份請假!C4 -> 4
A5: 3 | B5: 林世彬 | C5: =SUM(D5:O5) -> 45 | D5: =TP1月份請假!C5 -> 0 | E5: =TP2月份請假!C5 -> 4 | F5: =TP3月份請假!C5 -> 0 | G5: =TP4月份請假!C5 -> 5 | H5: =TP5月份請假!C5 -> 2 | I5: =TP6月份請假!C5 -> 10 | J5: =TP7月份請假!C5 -> 13 | K5: =TP8月份請假!C5 -> 1 | L5: =TP9月份請假!C5 -> 2 | M5: =TP10月份請假!C5 -> 8 | P5: =TP11月份請假!C5 -> 0 | Q5: =TP12月份請假!C5 -> 8
A6: 4 | B6: 何彥璋 | C6: =SUM(D6:O6) -> 185 | D6: =TP1月份請假!C6 -> 0 | E6: =TP2月份請假!C6 -> 24 | F6: =TP3月份請假!C6 -> 40 | G6: =TP4月份請假!C6 -> 18 | H6: =TP5月份請假!C6 -> 10 | I6: =TP6月份請假!C6 -> 32 | J6: =TP7月份請假!C6 -> 3 | K6: =TP8月份請假!C6 -> 18 | L6: =TP9月份請假!C6 -> 0 | M6: =TP10月份請假!C6 -> 40 | P6: =TP11月份請假!C6 -> 0 | Q6: =TP12月份請假!C6 -> 16
A7: 5 | B7: 吳嘉銘 | C7: =SUM(D7:O7) -> 88 | D7: =TP1月份請假!C7 -> 16 | E7: =TP2月份請假!C7 -> 16 | F7: =TP3月份請假!C7 -> 0 | G7: =TP4月份請假!C7 -> 8 | H7: =TP5月份請假!C7 -> 0 | I7: =TP6月份請假!C7 -> 16 | J7: =TP7月份請假!C7 -> 32 | K7: =TP8月份請假!C7 -> 0 | L7: =TP9月份請假!C7 -> 0 | M7: =TP10月份請假!C7 -> 0 | P7: =TP11月份請假!C7 -> 16 | Q7: =TP12月份請假!C7 -> 0
A8: 6 | B8: 林詠書 | C8: =SUM(D8:O8) -> 190 | D8: =TP1月份請假!C8 -> 32 | E8: =TP2月份請假!C8 -> 24 | F8: =TP3月份請假!C8 -> 16 | G8: =TP4月份請假!C8 -> 6 | H8: =TP5月份請假!C8 -> 0 | I8: =TP6月份請假!C8 -> 0 | J8: =TP7月份請假!C8 -> 48 | K8: =TP8月份請假!C8 -> 0 | L8: =TP9月份請假!C8 -> 16 | M8: =TP10月份請假!C8 -> 48 | P8: =TP11月份請假!C8 -> 16 | Q8: =TP12月份請假!C8 -> 4
A9: 7 | B9: 謝秉宏 | C9: =SUM(D9:O9) -> 208 | D9: =TP1月份請假!C9 -> 24 | E9: =TP2月份請假!C9 -> 24 | F9: =TP3月份請假!C9 -> 16 | G9: =TP4月份請假!C9 -> 33 | H9: =TP5月份請假!C9 -> 0 | I9: =TP6月份請假!C9 -> 18 | J9: =TP7月份請假!C9 -> 27 | K9: =TP8月份請假!C9 -> 48 | L9: =TP9月份請假!C9 -> 0 | M9: =TP10月份請假!C9 -> 18 | P9: =TP11月份請假!C9 -> 27 | Q9: =TP12月份請假!C9 -> 28
A10: 8 | B10: 林建宏 | C10: =SUM(D10:O10) -> 16 | D10: =TP1月份請假!C10 -> 0 | E10: =TP2月份請假!C10 -> 0 | F10: =TP3月份請假!C10 -> 0 | G10: =TP4月份請假!C10 -> 0 | H10: =TP5月份請假!C10 -> 0 | I10: =TP6月份請假!C10 -> 0 | J10: =TP7月份請假!C10 -> 0 | K10: =TP8月份請假!C10 -> 16 | L10: =TP9月份請假!C10 -> 0 | M10: =TP10月份請假!C10 -> 0 | P10: =TP11月份請假!C10 -> 16 | Q10: =TP12月份請假!C10 -> 0
A11: 9 | B11: 蘇景郁 | C11: =SUM(D11:O11) -> 77 | D11: =TP1月份請假!C11 -> 0 | E11: =TP2月份請假!C11 -> 24 | F11: =TP3月份請假!C11 -> 16 | G11: =TP4月份請假!C11 -> 20 | H11: =TP5月份請假!C11 -> 0 | I11: =TP6月份請假!C11 -> 16 | J11: =TP7月份請假!C11 -> 1 | K11: =TP8月份請假!C11 -> 0 | L11: =TP9月份請假!C11 -> 0 | M11: =TP10月份請假!C11 -> 0 | P11: =TP11月份請假!C11 -> 16 | Q11: =TP12月份請假!C11 -> 0
A12: 10 | B12: 潘其昌 | C12: =SUM(D12:O12) -> 96 | D12: =TP1月份請假!C12 -> 0 | E12: =TP2月份請假!C12 -> 16 | F12: =TP3月份請假!C12 -> 16 | G12: =TP4月份請假!C12 -> 16 | H12: =TP5月份請假!C12 -> 24 | I12: =TP6月份請假!C12 -> 8 | J12: =TP7月份請假!C12 -> 0 | K12: =TP8月份請假!C12 -> 0 | L12: =TP9月份請假!C12 -> 16 | M12: =TP10月份請假!C12 -> 0 | P12: =TP11月份請假!C12 -> 8 | Q12: =TP12月份請假!C12 -> 16
A13: 11 | B13: 陳俊男 | C13: =SUM(D13:O13) -> 94 | D13: =TP1月份請假!C13 -> 2 | E13: =TP2月份請假!C13 -> 16 | F13: =TP3月份請假!C13 -> 4 | G13: =TP4月份請假!C13 -> 32 | H13: =TP5月份請假!C13 -> 24 | I13: =TP6月份請假!C13 -> 8 | J13: =TP7月份請假!C13 -> 0 | K13: =TP8月份請假!C13 -> 8 | L13: =TP9月份請假!C13 -> 0 | M13: =TP10月份請假!C13 -> 0 | P13: =TP11月份請假!C13 -> 16 | Q13: =TP12月份請假!C13 -> 0
A14: 12 | B14: 林政宏 | C14: =SUM(D14:O14) -> 128 | D14: =TP1月份請假!C14 -> 0 | E14: =TP2月份請假!C14 -> 64 | F14: =TP3月份請假!C14 -> 32 | G14: =TP4月份請假!C14 -> 16 | H14: =TP5月份請假!C14 -> 0 | I14: =TP6月份請假!C14 -> 0 | J14: =TP7月份請假!C14 -> 8 | K14: =TP8月份請假!C14 -> 8 | L14: =TP9月份請假!C14 -> 0 | M14: =TP10月份請假!C14 -> 0 | P14: =TP11月份請假!C14 -> 8 | Q14: =TP12月份請假!C14 -> 16
A15: 13 | B15: 陸長遠 | C15: =SUM(D15:O15) -> 176 | D15: =TP1月份請假!C15 -> 16 | E15: =TP2月份請假!C15 -> 56 | F15: =TP3月份請假!C15 -> 17 | G15: =TP4月份請假!C15 -> 16 | H15: =TP5月份請假!C15 -> 0 | I15: =TP6月份請假!C15 -> 0 | J15: =TP7月份請假!C15 -> 18 | K15: =TP8月份請假!C15 -> 0 | L15: =TP9月份請假!C15 -> 16 | M15: =TP10月份請假!C15 -> 37 | P15: =TP11月份請假!C15 -> 16 | Q15: =TP12月份請假!C15 -> 10
A16: 13 | B16: 劉益豪 | C16: =SUM(D16:O16) -> 130 | D16: =TP1月份請假!C16 -> 0 | E16: =TP2月份請假!C16 -> 16 | F16: =TP3月份請假!C16 -> 0 | G16: =TP4月份請假!C16 -> 32 | H16: =TP5月份請假!C16 -> 18 | I16: =TP6月份請假!C16 -> 0 | J16: =TP7月份請假!C16 -> 16 | K16: =TP8月份請假!C16 -> 16 | L16: =TP9月份請假!C16 -> 16 | M16: =TP10月份請假!C16 -> 16 | P16: =TP11月份請假!C16 -> 8 | Q16: =TP12月份請假!C16 -> 0
A17: 14 | B17: 李威漢 | C17: =SUM(D17:O17) -> 76 | D17: =TP1月份請假!C17 -> 16 | E17: =TP2月份請假!C17 -> 16 | F17: =TP3月份請假!C17 -> 0 | G17: =TP4月份請假!C17 -> 0 | H17: =TP5月份請假!C17 -> 16 | I17: =TP6月份請假!C17 -> 16 | J17: =TP7月份請假!C17 -> 0 | K17: =TP8月份請假!C17 -> 5 | L17: =TP9月份請假!C17 -> 7 | M17: =TP10月份請假!C17 -> 0 | P17: =TP11月份請假!C17 -> 16 | Q17: =TP12月份請假!C17 -> 48
A18: 15 | B18: 王挺翰 | C18: =SUM(D18:O18) -> 96 | D18: =TP1月份請假!C18 -> 16 | E18: =TP2月份請假!C18 -> 16 | F18: =TP3月份請假!C18 -> 0 | G18: =TP4月份請假!C18 -> 0 | H18: =TP5月份請假!C18 -> 16 | I18: =TP6月份請假!C18 -> 0 | J18: =TP7月份請假!C18 -> 32 | K18: =TP8月份請假!C18 -> 0 | L18: =TP9月份請假!C18 -> 16 | M18: =TP10月份請假!C18 -> 0 | P18: =TP11月份請假!C18 -> 16 | Q18: =TP12月份請假!C18 -> 48
A19: 16 | B19: 李又誠 | C19: =SUM(D19:O19) -> 72 | D19: =TP1月份請假!C19 -> 0 | E19: =TP2月份請假!C19 -> 0 | F19: =TP3月份請假!C19 -> 8 | G19: =TP4月份請假!C19 -> 8 | H19: =TP5月份請假!C19 -> 16 | I19: =TP6月份請假!C19 -> 8 | J19: =TP7月份請假!C20 -> 32 | K19: =TP8月份請假!C19 -> 0 | L19: =TP9月份請假!C21 -> 0 | M19: =TP10月份請假!C21 -> 0 | P19: =TP11月份請假!C19 -> 10 | Q19: =TP12月份請假!C19 -> 12
A21: TP出勤-加班 | C21: 總累計 (0.5小時/單位) | D21: 1月累計 (0.5小時/單位) | E21: 2月累計 (0.5小時/單位) | F21: 3月累計 (0.5小時/單位) | G21: 4月累計 (0.5小時/單位) | H21: 5月累計 (0.5小時/單位) | I21: 6月累計 (0.5小時/單位) | J21: 7月累計 (0.5小時/單位) | K21: 8月累計 (0.5小時/單位) | L21: 9月累計 (0.5小時/單位) | M21: 10月累計 (0.5小時/單位) | N21: 11月累計 (0.5小時/單位) | O21: 12月累計 (0.5小時/單位) | P21: 11月累計 (0.5小時/單位) | Q21: 12累計 (0.5小時/單位) | R21: 2025月份加班直條圖(1~10月)
A22: NO. | B22: 姓名
A23: 1 | B23: 郭先弘 | C23: =SUM(D23:O23) -> 0 | D23: =TP1月份加班!C3 -> 0 | E23: =TP2月份加班!C3 -> 0 | F23: =TP3月份加班!C3 -> 0 | G23: =TP4月份加班!C3 -> 0 | H23: =TP5月份加班!C3 -> 0 | I23: =TP6月份加班!C3 -> 0 | J23: =TP7月份加班!C3 -> 0 | K23: =TP8月份加班!C3 -> 0 | L23: =TP9月份加班!C3 -> 0 | M23: =TP10月份加班!C3 -> 0 | P23: =TP11月份加班!C3 -> 0 | Q23: =TP12月份加班!C3 -> 0
A24: 2 | B24: 陳淑芬 | C24: =SUM(D24:O24) -> 74 | D24: =TP1月份加班!C4 -> 0 | E24: =TP2月份加班!C4 -> 0 | F24: =TP3月份加班!C4 -> 35 | G24: =TP4月份加班!C4 -> 17 | H24: =TP5月份加班!C4 -> 17 | I24: =TP6月份加班!C4 -> 2 | J24: =TP7月份加班!C4 -> 3 | K24: =TP8月份加班!C4 -> 0 | L24: =TP9月份加班!C4 -> 0 | M24: =TP10月份加班!C4 -> 0 | P24: =TP11月份加班!C4 -> 0 | Q24: =TP12月份加班!C4 -> 0
A25: 3 | B25: 林世彬 | C25: =SUM(D25:O25) -> 10 | D25: =TP1月份加班!C5 -> 0 | E25: =TP2月份加班!C5 -> 8 | F25: =TP3月份加班!C5 -> 0 | G25: =TP4月份加班!C5 -> 2 | H25: =TP5月份加班!C5 -> 0 | I25: =TP6月份加班!C5 -> 0 | J25: =TP7月份加班!C5 -> 0 | K25: =TP8月份加班!C5 -> 0 | L25: =TP9月份加班!C5 -> 0 | M25: =TP10月份加班!C5 -> 0 | P25: =TP11月份加班!C5 -> 0 | Q25: =TP12月份加班!C5 -> 8
A26: 4 | B26: 何彥璋 | C26: =SUM(D26:O26) -> 175 | D26: =TP1月份加班!C6 -> 4 | E26: =TP2月份加班!C6 -> 10 | F26: =TP3月份加班!C6 -> 29 | G26: =TP4月份加班!C6 -> 55 | H26: =TP5月份加班!C6 -> 12 | I26: =TP6月份加班!C6 -> 18 | J26: =TP7月份加班!C6 -> 6 | K26: =TP8月份加班!C6 -> 27 | L26: =TP9月份加班!C6 -> 6 | M26: =TP10月份加班!C6 -> 8 | P26: =TP11月份加班!C6 -> 20 | Q26: =TP12月份加班!C6 -> 12
A27: 5 | B27: 吳嘉銘 | C27: =SUM(D27:O27) -> 398 | D27: =TP1月份加班!C7 -> 18 | E27: =TP2月份加班!C7 -> 16 | F27: =TP3月份加班!C7 -> 21 | G27: =TP4月份加班!C7 -> 2 | H27: =TP5月份加班!C7 -> 53 | I27: =TP6月份加班!C7 -> 83 | J27: =TP7月份加班!C7 -> 0 | K27: =TP8月份加班!C7 -> 38 | L27: =TP9月份加班!C7 -> 94 | M27: =TP10月份加班!C7 -> 73 | P27: =TP11月份加班!C7 -> 56 | Q27: =TP12月份加班!C7 -> 96
A28: 6 | B28: 林詠書 | C28: =SUM(D28:O28) -> 274 | D28: =TP1月份加班!C8 -> 7 | E28: =TP2月份加班!C8 -> 12 | F28: =TP3月份加班!C8 -> 24 | G28: =TP4月份加班!C8 -> 6 | H28: =TP5月份加班!C8 -> 45 | I28: =TP6月份加班!C8 -> 98 | J28: =TP7月份加班!C8 -> 7 | K28: =TP8月份加班!C8 -> 45 | L28: =TP9月份加班!C8 -> 16 | M28: =TP10月份加班!C8 -> 14 | P28: =TP11月份加班!C8 -> 20 | Q28: =TP12月份加班!C8 -> 16
A29: 7 | B29: 謝秉宏 | C29: =SUM(D29:O29) -> 188 | D29: =TP1月份加班!C9 -> 6 | E29: =TP2月份加班!C9 -> 0 | F29: =TP3月份加班!C9 -> 32 | G29: =TP4月份加班!C9 -> 54 | H29: =TP5月份加班!C9 -> 20 | I29: =TP6月份加班!C9 -> 17 | J29: =TP7月份加班!C9 -> 19 | K29: =TP8月份加班!C9 -> 26 | L29: =TP9月份加班!C9 -> 6 | M29: =TP10月份加班!C9 -> 8 | P29: =TP11月份加班!C9 -> 5 | Q29: =TP12月份加班!C9 -> 7
A30: 8 | B30: 林建宏 | C30: =SUM(D30:O30) -> 137 | D30: =TP1月份加班!C10 -> 0 | E30: =TP2月份加班!C10 -> 0 | F30: =TP3月份加班!C10 -> 0 | G30: =TP4月份加班!C10 -> 0 | H30: =TP5月份加班!C10 -> 30 | I30: =TP6月份加班!C10 -> 52 | J30: =TP7月份加班!C10 -> 0 | K30: =TP8月份加班!C10 -> 22 | L30: =TP9月份加班!C10 -> 12 | M30: =TP10月份加班!C10 -> 21 | P30: =TP11月份加班!C10 -> 17 | Q30: =TP12月份加班!C10 -> 0
A31: 9 | B31: 蘇景郁 | C31: =SUM(D31:O31) -> 296 | D31: =TP1月份加班!C11 -> 0 | E31: =TP2月份加班!C11 -> 0 | F31: =TP3月份加班!C11 -> 2 | G31: =TP4月份加班!C11 -> 12 | H31: =TP5月份加班!C11 -> 24 | I31: =TP6月份加班!C11 -> 14 | J31: =TP7月份加班!C11 -> 33 | K31: =TP8月份加班!C11 -> 57 | L31: =TP9月份加班!C11 -> 93 | M31: =TP10月份加班!C11 -> 61 | P31: =TP11月份加班!C11 -> 63 | Q31: =TP12月份加班!C11 -> 74
A32: 10 | B32: 潘其昌 | C32: =SUM(D32:O32) -> 113 | D32: =TP1月份加班!C12 -> 0 | E32: =TP2月份加班!C12 -> 0 | F32: =TP3月份加班!C12 -> 25 | G32: =TP4月份加班!C12 -> 26 | H32: =TP5月份加班!C12 -> 6 | I32: =TP6月份加班!C12 -> 4 | J32: =TP7月份加班!C12 -> 13 | K32: =TP8月份加班!C12 -> 39 | L32: =TP9月份加班!C12 -> 0 | M32: =TP10月份加班!C12 -> 0 | P32: =TP11月份加班!C12 -> 58 | Q32: =TP12月份加班!C12 -> 17
A33: 11 | B33: 陳俊男 | C33: =SUM(D33:O33) -> 341 | D33: =TP1月份加班!C13 -> 0 | E33: =TP2月份加班!C13 -> 0 | F33: =TP3月份加班!C13 -> 26 | G33: =TP4月份加班!C13 -> 58 | H33: =TP5月份加班!C13 -> 4 | I33: =TP6月份加班!C13 -> 3 | J33: =TP7月份加班!C13 -> 5 | K33: =TP8月份加班!C13 -> 48 | L33: =TP9月份加班!C13 -> 98 | M33: =TP10月份加班!C13 -> 99 | P33: =TP11月份加班!C13 -> 69 | Q33: =TP12月份加班!C13 -> 98
A34: 12 | B34: 林政宏 | C34: =SUM(D34:O34) -> 327 | D34: =TP1月份加班!C14 -> 0 | E34: =TP2月份加班!C14 -> 18 | F34: =TP3月份加班!C14 -> 32 | G34: =TP4月份加班!C14 -> 42 | H34: =TP5月份加班!C14 -> 20 | I34: =TP6月份加班!C14 -> 23 | J34: =TP7月份加班!C14 -> 0 | K34: =TP8月份加班!C14 -> 48 | L34: =TP9月份加班!C14 -> 52 | M34: =TP10月份加班!C14 -> 92 | P34: =TP11月份加班!C14 -> 74 | Q34: =TP12月份加班!C14 -> 111
A35: 13 | B35: 劉益豪 | C35: =SUM(D35:O35) -> 199 | D35: =TP1月份加班!C16 -> 18 | E35: =TP2月份加班!C16 -> 16 | F35: =TP3月份加班!C16 -> 0 | G35: =TP4月份加班!C16 -> 12 | H35: =TP5月份加班!C16 -> 72 | I35: =TP6月份加班!C16 -> 48 | J35: =TP7月份加班!C16 -> 0 | K35: =TP8月份加班!C16 -> 0 | L35: =TP9月份加班!C16 -> 0 | M35: =TP10月份加班!C16 -> 33 | P35: =TP11月份加班!C15 -> 82 | Q35: =TP12月份加班!C15 -> 30
A36: 14 | B36: 李威漢 | C36: =SUM(D36:O36) -> 128 | D36: =TP1月份加班!C17 -> 18 | E36: =TP2月份加班!C17 -> 25 | F36: =TP3月份加班!C17 -> 0 | G36: =TP4月份加班!C17 -> 0 | H36: =TP5月份加班!C17 -> 0 | I36: =TP6月份加班!C17 -> 25 | J36: =TP7月份加班!C17 -> 14 | K36: =TP8月份加班!C17 -> 0 | L36: =TP9月份加班!C17 -> 10 | M36: =TP10月份加班!C17 -> 36 | P36: =TP11月份加班!C16 -> 92 | Q36: =TP12月份加班!C16 -> 144
A37: 15 | B37: 王挺翰 | C37: =SUM(D37:O37) -> 206 | D37: =TP1月份加班!C18 -> 18 | E37: =TP2月份加班!C18 -> 25 | F37: =TP3月份加班!C18 -> 0 | G37: =TP4月份加班!C18 -> 0 | H37: =TP5月份加班!C18 -> 38 | I37: =TP6月份加班!C18 -> 79 | J37: =TP7月份加班!C18 -> 0 | K37: =TP8月份加班!C18 -> 0 | L37: =TP9月份加班!C18 -> 10 | M37: =TP10月份加班!C18 -> 36 | P37: =TP11月份加班!C17 -> 71 | Q37: =TP12月份加班!C17 -> 21
A38: 16 | B38: 李又誠 | C38: =SUM(D38:O38) -> 57 | D38: =TP1月份加班!C19 -> 0 | E38: =TP2月份加班!C19 -> 0 | F38: =TP3月份加班!C19 -> 3 | G38: =TP4月份加班!C19 -> 10 | H38: =TP5月份加班!C19 -> 0 | I38: =TP6月份加班!C19 -> 23 | J38: =TP7月份加班!C20 -> 0 | K38: =TP8月份加班!C19 -> 4 | L38: =TP9月份加班!C19 -> 1 | M38: =TP10月份加班!C19 -> 16 | P38: =TP11月份加班!C18 -> 71 | Q38: =TP12月份加班!C18 -> 21
A40: TP出勤-加班減請假 | C40: 總累計 (0.5小時/單位) | D40: 1月累計 (0.5小時/單位) | E40: 2月累計 (0.5小時/單位) | F40: 3月累計 (0.5小時/單位) | G40: 4月累計 (0.5小時/單位) | H40: 5月累計 (0.5小時/單位) | I40: 6月累計 (0.5小時/單位) | J40: 7月累計 (0.5小時/單位) | K40: 8月累計 (0.5小時/單位) | L40: 9月累計 (0.5小時/單位) | M40: 10月累計 (0.5小時/單位) | N40: 11月累計 (0.5小時/單位) | O40: 12月累計 (0.5小時/單位) | P40: 11月累計 (0.5小時/單位) | Q40: 12累計 (0.5小時/單位) | R40: 2025月份加班減請假直條圖(1~10月)
A41: NO. | B41: 姓名
A42: 1 | B42: 郭先弘 | C42: =SUM(D42:Q42) -> 0 | D42: =D23-D3 -> 0 | E42: =E23-E3 -> 0 | F42: =F23-F3 -> 0 | G42: =G23-G3 -> 0 | H42: =H23-H3 -> 0 | I42: =I23-I3 -> 0 | J42: =J23-J3 -> 0 | K42: =K23-K3 -> 0 | ... Q42: =Q23-Q3 -> 0
...

Sheet TP加班累計-請假總合_2025
A1: TP(加班-請假) | C1: 一月累計單位 (0.5小時/單位) | D1: 二月累計單位 (0.5小時/單位) | E1: 三月累計單位 (0.5小時/單位) | F1: 四月累計單位 (0.5小時/單位) | G1: 五月累計單位 (0.5小時/單位) | H1: 六月累計單位 (0.5小時/單位) | I1: 七月累計單位 (0.5小時/單位) | J1: 八月累計單位 (0.5小時/單位) | K1: 九月累計單位 (0.5小時/單位) | L1: 十月累計單位 (0.5小時/單位) | M1: 十一月累計單位 (0.5小時/單位) | N1: 十二月累計單位 (0.5小時/單位) | O1: 2025總累計單位 (0.5小時/單位) | P1: 校正歸零用(不可刪) | R1: 2025總累計單位(扣GKT) (0.5小時/單位) | S1: GTK加班費申報扣除時數 (5/17~6/29) | U1: GTK加班費申報扣除時數 (8月) | W1: GTK加班費申報扣除時數 (9月) | Y1: GTK加班費申報扣除時數 10月) | AA1: GTK加班費申報扣除時數 (11月) | AC1: GTK加班費申報扣除時數 (12月)
A2: NO. | B2: 姓名 | S2: (0.5小時/單位) | T2: 小時 | U2: (0.5小時/單位) | V2: 小時 | W2: (0.5小時/單位) | X2: 小時 | Y2: (0.5小時/單位) | Z2: 小時 | AA2: (0.5小時/單位) | AB2: 小時 | AC2: (0.5小時/單位) | AD2: 小時
A3: 1 | B3: 郭先弘 | C3: =TP1月份加班!C3-TP1月份請假!C3 -> 0 | D3: =TP2月份加班!C3-TP2月份請假!C3 -> 0 | E3: =TP3月份加班!C3-TP3月份請假!C3 -> 0 | F3: =TP4月份加班!C3-TP4月份請假!C3 -> 0 | G3: =TP5月份加班!C3-TP5月份請假!C3 -> 0 | H3: =TP6月份加班!C3-TP6月份請假!C3 -> 0 | I3: =TP7月份加班!C3-TP7月份請假!C3 -> 0 | J3: =TP8月份加班!C3-TP8月份請假!C3 -> 0 | K3: =TP9月份加班!C3-TP9月份請假!C3 -> 0 | L3: =TP10月份加班!C3-TP10月份請假!C3 -> 0 | M3: =TP11月份加班!C3-TP11月份請假!C3 -> 0 | N3: =TP12月份加班!C3-TP12月份請假!C3 -> 0 | O3: =SUM(C3:N3)+P3 -> 0 | P3: 0 | Q3: =O3+P3 -> 0 | R3: =O3-S3-U3-W3-Y3-AA3-AC3 -> 0 | S3: =T3*2 -> 0 | T3: 0 | U3: 0 | V3: =U3*0.5 -> 0 | W3: 0 | X3: =W3*0.5 -> 0 | Y3: 0 | Z3: =Y3*0.5 -> 0 | AA3: 0 | AB3: =AA3*0.5 -> 0 | AC3: 0 | AD3: =AC3*0.5 -> 0
A4: 2 | B4: 陳淑芬 | C4: =TP1月份加班!C4-TP1月份請假!C4 -> -10 | D4: =TP2月份加班!C4-TP2月份請假!C4 -> 0 | E4: =TP3月份加班!C4-TP3月份請假!C4 -> 34 | F4: =TP4月份加班!C4-TP4月份請假!C4 -> -3 | G4: =TP5月份加班!C4-TP5月份請假!C4 -> 15 | H4: =TP6月份加班!C4-TP6月份請假!C4 -> 2 | I4: =TP7月份加班!C4-TP7月份請假!C4 -> -5 | J4: =TP8月份加班!C4-TP8月份請假!C4 -> -17 | K4: =TP9月份加班!C4-TP9月份請假!C4 -> -2 | L4: =TP10月份加班!C4-TP10月份請假!C4 -> -25 | M4: =TP11月份加班!C4-TP11月份請假!C4 -> -8 | N4: =TP12月份加班!C4-TP12月份請假!C4 -> -4 | O4: =SUM(C4:N4)+P4 -> -23 | P4: 0 | Q4: =O4+P4 -> -23 | R4: =O4-S4-U4-W4-Y4-AA4-AC4 -> -23 | S4: =T4*2 -> 0 | T4: 0 | U4: 0 | V4: =U4*0.5 -> 0 | W4: 0 | X4: =W4*0.5 -> 0 | Y4: 0 | Z4: =Y4*0.5 -> 0 | AA4: 0 | AB4: =AA4*0.5 -> 0 | AC4: 0 | AD4: =AC4*0.5 -> 0
A5: 3 | B5: 林世彬 | C5: =TP1月份加班!C5-TP1月份請假!C5 -> 0 | D5: =TP2月份加班!C5-TP2月份請假!C5 -> 4 | E5: =TP3月份加班!C5-TP3月份請假!C5 -> 0 | F5: =TP4月份加班!C5-TP4月份請假!C5 -> -3 | G5: =TP5月份加班!C5-TP5月份請假!C5 -> -2 | H5: =TP6月份加班!C5-TP6月份請假!C5 -> -10 | I5: =TP7月份加班!C5-TP7月份請假!C5 -> -13 | J5: =TP8月份加班!C5-TP8月份請假!C5 -> -1 | K5: =TP9月份加班!C5-TP9月份請假!C5 -> -2 | L5: =TP10月份加班!C5-TP10月份請假!C5 -> -8 | M5: =TP11月份加班!C5-TP11月份請假!C5 -> 0 | N5: =TP12月份加班!C5-TP12月份請假!C5 -> 0 | O5: =SUM(C5:N5)+P5 -> -88 | P5: -53 | Q5: =O5+P5 -> -141 | R5: =O5-S5-U5-W5-Y5-AA5-AC5 -> -88 | S5: =T5*2 -> 0 | T5: 0 | U5: 0 | V5: =U5*0.5 -> 0 | W5: 0 | X5: =W5*0.5 -> 0 | Y5: 0 | Z5: =Y5*0.5 -> 0 | AA5: 0 | AB5: =AA5*0.5 -> 0 | AC5: 0 | AD5: =AC5*0.5 -> 0
A6: 4 | B6: 何彥璋 | C6: =TP1月份加班!C6-TP1月份請假!C6 -> 4 | D6: =TP2月份加班!C6-TP2月份請假!C6 -> -14 | E6: =TP3月份加班!C6-TP3月份請假!C6 -> -11 | F6: =TP4月份加班!C6-TP4月份請假!C6 -> 37 | G6: =TP5月份加班!C6-TP5月份請假!C6 -> 2 | H6: =TP6月份加班!C6-TP6月份請假!C6 -> -14 | I6: =TP7月份加班!C6-TP7月份請假!C6 -> 3 | J6: =TP8月份加班!C6-TP8月份請假!C6 -> 9 | K6: =TP9月份加班!C6-TP9月份請假!C6 -> 6 | L6: =TP10月份加班!C6-TP10月份請假!C6 -> -32 | M6: =TP11月份加班!C6-TP11月份請假!C6 -> 20 | N6: =TP12月份加班!C6-TP12月份請假!C6 -> -4 | O6: =SUM(C6:N6)+P6 -> 3 | P6: -3 | Q6: =O6+P6 -> 0 | R6: =O6-S6-U6-W6-Y6-AA6-AC6 -> 3 | S6: =T6*2 -> 0 | T6: 0 | U6: 0 | V6: =U6*0.5 -> 0 | W6: 0 | X6: =W6*0.5 -> 0 | Y6: 0 | Z6: =Y6*0.5 -> 0 | AA6: 0 | AB6: =AA6*0.5 -> 0 | AC6: 0 | AD6: =AC6*0.5 -> 0
A7: 5 | B7: 吳嘉銘 | C7: =TP1月份加班!C7-TP1月份請假!C7 -> 2 | D7: =TP2月份加班!C7-TP2月份請假!C7 -> 0 | E7: =TP3月份加班!C7-TP3月份請假!C7 -> 21 | F7: =TP4月份加班!C7-TP4月份請假!C7 -> -6 | G7: =TP5月份加班!C7-TP5月份請假!C7 -> 53 | H7: =TP6月份加班!C7-TP6月份請假!C7 -> 67 | I7: =TP7月份加班!C7-TP7月份請假!C7 -> -32 | J7: =TP8月份加班!C7-TP8月份請假!C7 -> 38 | K7: =TP9月份加班!C7-TP9月份請假!C7 -> 94 | L7: =TP10月份加班!C7-TP10月份請假!C7 -> 73 | M7: =TP11月份加班!C7-TP11月份請假!C7 -> 40 | N7: =TP12月份加班!C7-TP12月份請假!C7 -> 96 | O7: =SUM(C7:N7)+P7 -> 422 | P7: -24 | Q7: =O7+P7 -> 398 | R7: =O7-S7-U7-W7-Y7-AA7-AC7 -> -5.8 | S7: =T7*2 -> 106.8 | T7: 53.4 | U7: 32 | V7: =U7*0.5 -> 16 | W7: 88 | X7: =W7*0.5 -> 44 | Y7: 65 | Z7: =Y7*0.5 -> 32.5 | AA7: 48 | AB7: =AA7*0.5 -> 24 | AC7: 88 | AD7: =AC7*0.5 -> 44
A8: 6 | B8: 林詠書 | C8: =TP1月份加班!C8-TP1月份請假!C8 -> -25 | D8: =TP2月份加班!C8-TP2月份請假!C8 -> -12 | E8: =TP3月份加班!C8-TP3月份請假!C8 -> 8 | F8: =TP4月份加班!C8-TP4月份請假!C8 -> 0 | G8: =TP5月份加班!C8-TP5月份請假!C8 -> 45 | H8: =TP6月份加班!C8-TP6月份請假!C8 -> 98 | I8: =TP7月份加班!C8-TP7月份請假!C8 -> -41 | J8: =TP8月份加班!C8-TP8月份請假!C8 -> 45 | K8: =TP9月份加班!C8-TP9月份請假!C8 -> 0 | L8: =TP10月份加班!C8-TP10月份請假!C8 -> -34 | M8: =TP11月份加班!C8-TP11月份請假!C8 -> 4 | N8: =TP12月份加班!C8-TP12月份請假!C8 -> 12 | O8: =SUM(C8:N8)+P8 -> 129 | P8: 29 | Q8: =O8+P8 -> 158 | R8: =O8-S8-U8-W8-Y8-AA8-AC8 -> 6.6 | S8: =T8*2 -> 82.4 | T8: 41.2 | U8: 32 | V8: =U8*0.5 -> 16 | W8: 8 | X8: =W8*0.5 -> 4 | Y8: 0 | Z8: =Y8*0.5 -> 0 | AA8: 0 | AB8: =AA8*0.5 -> 0 | AC8: 0 | AD8: =AC8*0.5 -> 0
A9: 7 | B9: 謝秉宏 | C9: =TP1月份加班!C9-TP1月份請假!C9 -> -18 | D9: =TP2月份加班!C9-TP2月份請假!C9 -> -24 | E9: =TP3月份加班!C9-TP3月份請假!C9 -> 16 | F9: =TP4月份加班!C9-TP4月份請假!C9 -> 21 | G9: =TP5月份加班!C9-TP5月份請假!C9 -> 20 | H9: =TP6月份加班!C9-TP6月份請假!C9 -> -1 | I9: =TP7月份加班!C9-TP7月份請假!C9 -> -8 | J9: =TP8月份加班!C9-TP8月份請假!C9 -> -22 | K9: =TP9月份加班!C9-TP9月份請假!C9 -> 6 | L9: =TP10月份加班!C9-TP10月份請假!C9 -> -10 | M9: =TP11月份加班!C9-TP11月份請假!C9 -> -22 | N9: =TP12月份加班!C9-TP12月份請假!C9 -> -21 | O9: =SUM(C9:N9)+P9 -> -57 | P9: 6 | Q9: =O9+P9 -> -51 | R9: =O9-S9-U9-W9-Y9-AA9-AC9 -> -57 | S9: =T9*2 -> 0 | T9: 0 | U9: 0 | V9: =U9*0.5 -> 0 | W9: 0 | X9: =W9*0.5 -> 0 | Y9: 0 | Z9: =Y9*0.5 -> 0 | AA9: 0 | AB9: =AA9*0.5 -> 0 | AC9: 0 | AD9: =AC9*0.5 -> 0
A10: 8 | B10: 林建宏 | C10: =TP1月份加班!C10-TP1月份請假!C10 -> 0 | D10: =TP2月份加班!C10-TP2月份請假!C10 -> 0 | E10: =TP3月份加班!C10-TP3月份請假!C10 -> 0 | F10: =TP4月份加班!C10-TP4月份請假!C10 -> 0 | G10: =TP5月份加班!C10-TP5月份請假!C10 -> 30 | H10: =TP6月份加班!C10-TP6月份請假!C10 -> 52 | I10: =TP7月份加班!C10-TP7月份請假!C10 -> 0 | J10: =TP8月份加班!C10-TP8月份請假!C10 -> 6 | K10: =TP9月份加班!C10-TP9月份請假!C10 -> 12 | L10: =TP10月份加班!C10-TP10月份請假!C10 -> 21 | M10: =TP11月份加班!C10-TP11月份請假!C10 -> 1 | N10: =TP12月份加班!C10-TP12月份請假!C10 -> 0 | O10: =SUM(C10:N10)+P10 -> 122 | P10: 0 | Q10: =O10+P10 -> 122 | R10: =O10-S10-U10-W10-Y10-AA10-AC10 -> 28.4 | S10: =T10*2 -> 61.6 | T10: 30.8 | U10: 20 | V10: =U10*0.5 -> 10 | W10: 12 | X10: =W10*0.5 -> 6 | Y10: 0 | Z10: =Y10*0.5 -> 0 | AA10: 0 | AB10: =AA10*0.5 -> 0 | AC10: 0 | AD10: =AC10*0.5 -> 0
A11: 9 | B11: 蘇景郁 | C11: =TP1月份加班!C11-TP1月份請假!C11 -> 0 | D11: =TP2月份加班!C11-TP2月份請假!C11 -> -24 | E11: =TP3月份加班!C11-TP3月份請假!C11 -> -14 | F11: =TP4月份加班!C11-TP4月份請假!C11 -> -8 | G11: =TP5月份加班!C11-TP5月份請假!C11 -> 24 | H11: =TP6月份加班!C11-TP6月份請假!C11 -> -2 | I11: =TP7月份加班!C11-TP7月份請假!C11 -> 32 | J11: =TP8月份加班!C11-TP8月份請假!C11 -> 57 | K11: =TP9月份加班!C11-TP9月份請假!C11 -> 93 | L11: =TP10月份加班!C11-TP10月份請假!C11 -> 61 | M11: =TP11月份加班!C11-TP11月份請假!C11 -> 47 | N11: =TP12月份加班!C11-TP12月份請假!C11 -> 74 | O11: =SUM(C11:N11)+P11 -> 294 | P11: -46 | Q11: =O11+P11 -> 248 | R11: =O11-S11-U11-W11-Y11-AA11-AC11 -> -6 | S11: =T11*2 -> 7 | T11: 3.5 | U11: 32 | V11: =U11*0.5 -> 16 | W11: 87 | X11: =W11*0.5 -> 43.5 | Y11: 53 | Z11: =Y11*0.5 -> 26.5 | AA11: 53 | AB11: =AA11*0.5 -> 26.5 | AC11: 68 | AD11: =AC11*0.5 -> 34
A12: 10 | B12: 潘其昌 | C12: =TP1月份加班!C12-TP1月份請假!C12 -> 0 | D12: =TP2月份加班!C12-TP2月份請假!C12 -> -16 | E12: =TP3月份加班!C12-TP3月份請假!C12 -> 9 | F12: =TP4月份加班!C12-TP4月份請假!C12 -> 10 | G12: =TP5月份加班!C12-TP5月份請假!C12 -> -18 | H12: =TP6月份加班!C12-TP6月份請假!C12 -> -4 | I12: =TP7月份加班!C12-TP7月份請假!C12 -> 13 | J12: =TP8月份加班!C12-TP8月份請假!C12 -> 39 | K12: =TP9月份加班!C12-TP9月份請假!C12 -> -16 | L12: =TP10月份加班!C12-TP10月份請假!C12 -> 0 | M12: =TP11月份加班!C12-TP11月份請假!C12 -> 50 | N12: =TP12月份加班!C12-TP12月份請假!C12 -> 1 | O12: =SUM(C12:N12)+P12 -> 75 | P12: 7 | Q12: =O12+P12 -> 82 | R12: =O12-S12-U12-W12-Y12-AA12-AC12 -> 75 | S12: =T12*2 -> 0 | T12: 0 | U12: 0 | V12: =U12*0.5 -> 0 | W12: 0 | X12: =W12*0.5 -> 0 | Y12: 0 | Z12: =Y12*0.5 -> 0 | AA12: 0 | AB12: =AA12*0.5 -> 0 | AC12: 0 | AD12: =AC12*0.5 -> 0
A13: 11 | B13: 陳俊男 | C13: =TP1月份加班!C13-TP1月份請假!C13 -> -2 | D13: =TP2月份加班!C13-TP2月份請假!C13 -> -16 | E13: =TP3月份加班!C13-TP3月份請假!C13 -> 22 | F13: =TP4月份加班!C13-TP4月份請假!C13 -> 26 | G13: =TP5月份加班!C13-TP5月份請假!C13 -> -20 | H13: =TP6月份加班!C13-TP6月份請假!C13 -> -5 | I13: =TP7月份加班!C13-TP7月份請假!C13 -> 5 | J13: =TP8月份加班!C13-TP8月份請假!C13 -> 40 | K13: =TP9月份加班!C13-TP9月份請假!C13 -> 98 | L13: =TP10月份加班!C13-TP10月份請假!C13 -> 99 | M13: =TP11月份加班!C13-TP11月份請假!C13 -> 53 | N13: =TP12月份加班!C13-TP12月份請假!C13 -> 98 | O13: =SUM(C13:N13)+P13 -> 398 | P13: 0 | Q13: =O13+P13 -> 398 | R13: =O13-S13-U13-W13-Y13-AA13-AC13 -> 22 | S13: =T13*2 -> 0 | T13: 0 | U13: 40 | V13: =U13*0.5 -> 20 | W13: 92 | X13: =W13*0.5 -> 46 | Y13: 91 | Z13: =Y13*0.5 -> 45.5 | AA13: 63 | AB13: =AA13*0.5 -> 31.5 | AC13: 90 | AD13: =AC13*0.5 -> 45
A14: 12 | B14: 林政宏 | C14: =TP1月份加班!C14-TP1月份請假!C14 -> 0 | D14: =TP2月份加班!C14-TP2月份請假!C14 -> -46 | E14: =TP3月份加班!C14-TP3月份請假!C14 -> 0 | F14: =TP4月份加班!C14-TP4月份請假!C14 -> 26 | G14: =TP5月份加班!C14-TP5月份請假!C14 -> 20 | H14: =TP6月份加班!C14-TP6月份請假!C14 -> 23 | I14: =TP7月份加班!C14-TP7月份請假!C14 -> -8 | J14: =TP8月份加班!C14-TP8月份請假!C14 -> 40 | K14: =TP9月份加班!C14-TP9月份請假!C14 -> 52 | L14: =TP10月份加班!C14-TP10月份請假!C14 -> 92 | M14: =TP11月份加班!C14-TP11月份請假!C14 -> 66 | N14: =TP12月份加班!C14-TP12月份請假!C14 -> 95 | O14: =SUM(C14:N14)+P14 -> 406 | P14: 46 | Q14: =O14+P14 -> 452 | R14: =O14-S14-U14-W14-Y14-AA14-AC14 -> 107 | S14: =T14*2 -> 0 | T14: 0 | U14: 40 | V14: =U14*0.5 -> 20 | W14: 48 | X14: =W14*0.5 -> 24 | Y14: 40 | Z14: =Y14*0.5 -> 20 | AA14: 66 | AB14: =AA14*0.5 -> 33 | AC14: 105 | AD14: =AC14*0.5 -> 52.5
A15: 13 | B15: 劉益豪 | C15: =TP1月份加班!C15-TP1月份請假!C15 -> 8 | D15: =TP2月份加班!C15-TP2月份請假!C15 -> -48 | E15: =TP3月份加班!C15-TP3月份請假!C15 -> -17 | F15: =TP4月份加班!C15-TP4月份請假!C15 -> -16 | G15: =TP5月份加班!C15-TP5月份請假!C15 -> 40 | H15: =TP6月份加班!C15-TP6月份請假!C15 -> 96 | I15: =TP7月份加班!C15-TP7月份請假!C15 -> -11 | J15: =TP8月份加班!C15-TP8月份請假!C15 -> 76 | K15: =TP9月份加班!C15-TP9月份請假!C15 -> 41 | L15: =TP10月份加班!C15-TP10月份請假!C15 -> 23 | M15: =TP11月份加班!C15-TP11月份請假!C15 -> 66 | N15: =TP12月份加班!C15-TP12月份請假!C15 -> 20 | O15: =SUM(C15:N15)+P15 -> 335 | P15: 57 | Q15: =O15+P15 -> 392 | R15: =O15-S15-U15-W15-Y15-AA15-AC15 -> 184 | S15: =T15*2 -> 43 | T15: 21.5 | U15: 64 | V15: =U15*0.5 -> 32 | W15: 44 | X15: =W15*0.5 -> 22 | Y15: 0 | Z15: =Y15*0.5 -> 0 | AA15: 0 | AB15: =AA15*0.5 -> 0 | AC15: 0 | AD15: =AC15*0.5 -> 0
A16: 14 | B16: 李威漢 | C16: =TP1月份加班!C16-TP1月份請假!C16 -> 18 | D16: =TP2月份加班!C16-TP2月份請假!C16 -> 0 | E16: =TP3月份加班!C16-TP3月份請假!C16 -> 0 | F16: =TP4月份加班!C16-TP4月份請假!C16 -> -20 | G16: =TP5月份加班!C16-TP5月份請假!C16 -> 54 | H16: =TP6月份加班!C16-TP6月份請假!C16 -> 48 | I16: =TP7月份加班!C16-TP7月份請假!C16 -> -16 | J16: =TP8月份加班!C16-TP8月份請假!C16 -> -16 | K16: =TP9月份加班!C16-TP9月份請假!C16 -> -16 | L16: =TP10月份加班!C16-TP10月份請假!C16 -> 17 | M16: =TP11月份加班!C16-TP11月份請假!C16 -> 84 | N16: =TP12月份加班!C16-TP12月份請假!C16 -> 144 | O16: =SUM(C16:N16)+P16 -> 284 | P16: -13 | Q16: =O16+P16 -> 271 | R16: =O16-S16-U16-W16-Y16-AA16-AC16 -> 9.8 | S16: =T16*2 -> 44.2 | T16: 22.1 | U16: 0 | V16: =U16*0.5 -> 0 | W16: 0 | X16: =W16*0.5 -> 0 | Y16: 24 | Z16: =Y16*0.5 -> 12 | AA16: 70 | AB16: =AA16*0.5 -> 35 | AC16: 136 | AD16: =AC16*0.5 -> 68
A17: 15 | B17: 王挺翰 | C17: =TP1月份加班!C17-TP1月份請假!C17 -> 2 | D17: =TP2月份加班!C17-TP2月份請假!C17 -> 9 | E17: =TP3月份加班!C17-TP3月份請假!C17 -> 0 | F17: =TP4月份加班!C17-TP4月份請假!C17 -> 0 | G17: =TP5月份加班!C17-TP5月份請假!C17 -> -16 | H17: =TP6月份加班!C17-TP6月份請假!C17 -> 9 | I17: =TP7月份加班!C17-TP7月份請假!C17 -> 14 | J17: =TP8月份加班!C17-TP8月份請假!C17 -> -5 | K17: =TP9月份加班!C17-TP9月份請假!C17 -> 3 | L17: =TP10月份加班!C17-TP10月份請假!C17 -> 36 | M17: =TP11月份加班!C17-TP11月份請假!C17 -> 55 | N17: =TP12月份加班!C17-TP12月份請假!C17 -> -27 | O17: =SUM(C17:N17)+P17 -> 80 | P17: 0 | Q17: =O17+P17 -> 80 | R17: =O17-S17-U17-W17-Y17-AA17-AC17 -> 80 | S17: =T17*2 -> 0 | T17: 0 | U17: 0 | V17: =U17*0.5 -> 0 | W17: 0 | X17: =W17*0.5 -> 0 | Y17: 0 | Z17: =Y17*0.5 -> 0 | AA17: 0 | AB17: =AA17*0.5 -> 0 | AC17: 0 | AD17: =AC17*0.5 -> 0
A18: 16 | B18: 李又誠 | C18: =TP1月份加班!C18-TP1月份請假!C18 -> 2 | D18: =TP2月份加班!C18-TP2月份請假!C18 -> 9 | E18: =TP3月份加班!C18-TP3月份請假!C18 -> 0 | F18: =TP4月份加班!C18-TP4月份請假!C18 -> 0 | G18: =TP5月份加班!C18-TP5月份請假!C18 -> 22 | H18: =TP6月份加班!C18-TP6月份請假!C18 -> 79 | I18: =TP7月份加班!C18-TP7月份請假!C18 -> -32 | J18: =TP8月份加班!C18-TP8月份請假!C18 -> 0 | K18: =TP9月份加班!C18-TP9月份請假!C18 -> -6 | L18: =TP10月份加班!C18-TP10月份請假!C18 -> 36 | M18: =TP11月份加班!C18-TP11月份請假!C18 -> 55 | N18: =TP12月份加班!C18-TP12月份請假!C18 -> -27 | O18: =SUM(C18:N18)+P18 -> 138 | P18: 0 | Q18: =O18+P18 -> 138 | R18: =O18-S18-U18-W18-Y18-AA18-AC18 -> 39.8 | S18: =T18*2 -> 98.2 | T18: 49.1 | U18: 0 | V18: =U18*0.5 -> 0 | W18: 0 | X18: =W18*0.5 -> 0 | Y18: 0 | Z18: =Y18*0.5 -> 0 | AA18: 0 | AB18: =AA18*0.5 -> 0 | AC18: 0 | AD18: =AC18*0.5 -> 0
A19: 17 | B19: 徐亞維 | E19: =TP3月份加班!C19-TP3月份請假!C19 -> -5 | F19: =TP4月份加班!C19-TP4月份請假!C19 -> 2 | G19: =TP5月份加班!C19-TP5月份請假!C19 -> -16 | H19: =TP6月份加班!C19-TP6月份請假!C19 -> 15 | I19: =TP7月份加班!C19-TP7月份請假!C19 -> 14 | J19: =TP8月份加班!C19-TP8月份請假!C19 -> 4 | K19: =TP9月份加班!C19-TP9月份請假!C21 -> 1 | L19: =TP10月份加班!C19-TP10月份請假!C21 -> 16 | M19: =TP11月份加班!C19-TP11月份請假!C19 -> 19 | N19: =TP12月份加班!C19-TP12月份請假!C19 -> 7 | O19: =SUM(C19:N19)+P19 -> 57 | P19: 0 | Q19: =O19+P19 -> 57 | R19: =O19-S19-U19-W19-Y19-AA19-AC19 -> 57 | S19: =T19*2 -> 0 | T19: 0 | U19: 0 | V19: =U19*0.5 -> 0 | W19: 0 | X19: =W19*0.5 -> 0 | Y19: 0 | Z19: =Y19*0.5 -> 0 | AA19: 0 | AB19: =AA19*0.5 -> 0 | AC19: 0 | AD19: =AC19*0.5 -> 0
A20: 18 | B20: 陳明生 | E20: =TP3月份加班!C20-TP3月份請假!C20 -> 0 | F20: =TP4月份加班!C20-TP4月份請假!C20 -> 0 | G20: =TP5月份加班!C20-TP5月份請假!C20 -> 30 | H20: =TP6月份加班!C20-TP6月份請假!C20 -> 32 | I20: =TP7月份加班!C20-TP7月份請假!C20 -> -32 | J20: =TP8月份加班!C20-TP8月份請假!C20 -> 36 | K20: =TP9月份加班!C20-TP9月份請假!C22 -> 19 | L20: =TP10月份加班!C20-TP10月份請假!C22 -> 16 | M20: =TP11月份加班!C20-TP11月份請假!C20 -> 46 | N20: =TP12月份加班!C20-TP12月份請假!C20 -> 81 | O20: =SUM(C20:N20)+P20 -> 228 | R20: =O20-S20-U20-W20-Y20-AA20-AC20 -> 147.2 | S20: =T20*2 -> 36.8 | T20: 18.4 | U20: 32 | V20: =U20*0.5 -> 16 | W20: 12 | X20: =W20*0.5 -> 6 | Y20: 0 | Z20: =Y20*0.5 -> 0 | AA20: 0 | AB20: =AA20*0.5 -> 0 | AC20: 0 | AD20: =AC20*0.5 -> 0
A21: 1.紅字代表請假單位大於加班單位 2.當年度6月後累計天數超過96單位(6天)之人員，定期通知提醒該員按時休假。 3.當年度年底(12/31)未休完之單位時數可累計至下年度前3個月使用，最高累計單位時數為112單位(7天)，超過則不採計。 4.第2項之天數未依規定休完則直接歸零計。 5.第2項之天數如因任務/出差等因素未休完則由主管依個案處理。 6.提報加班時數超過3單位請填寫上加班原因(例: 3單位，XXX專案DOE)。 7.請補休(填出勤確認單)最長連續時數以16單位(1天)為上限(填出勤單不要超過1天以上)。 8.此補休辦法(填出勤確認單)請大家一起維護，被人資發現告發後此單位時數一但被歸零則無法補發。 9.補休(填出勤確認單)申請規則:當月最多申請次數4或 5次(依當月有幾週為準)、當週最多申請2次、不得連兩天上班日(含跨週)以上請補休(例:星期一下班、星期二上班、星期二下班未刷卡即算連兩天)。

Sheet TP出勤12月份
A1: TP出勤 | C1: 45627 | D1: 45628 | E1: 45629 | F1: 45630 | G1: 45631 | H1: 45632 | I1: 45633 | J1: 45634 | K1: 45635 | L1: 45636 | M1: 45637 | N1: 45638 | O1: 45639 | P1: 45640 | Q1: 45641 | R1: 45642 | S1: 45643 | T1: 45644 | U1: 45645 | V1: 45646 | W1: 45647 | X1: 45648 | Y1: 45649 | Z1: 45650 | AA1: 45651 | AB1: 45652 | AC1: 45653 | AD1: 45654 | AE1: 45655 | AF1: 45656 | AG1: 45657
A2: NO. | B2: 姓名
A3: 1 | B3: 郭先弘 | C3: 出差 | D3: 出差 | E3: 出差 | F3: 出差 | G3: 出差 | J3: 出差 | K3: 出差 | L3: 出差 | M3: 出差 | N3: 出差 | Q3: 出差 | R3: 出差 | S3: 出差 | T3: 出差 | U3: 出差 | X3: 出差 | Y3: ✓ | Z3: ✓ | AB3: 體檢假 | AE3: ✓ | AF3: ✓ | AG3: ✓
A4: 2 | B4: 陳淑芬 | C4: ✓ | D4: ✓ | E4: ✓ | F4: ✓ | G4: ✓ | J4: ✓ | K4: ✓ | L4: ✓ | M4: ✓ | N4: ✓ | Q4: ✓ | R4: ✓ | S4: ✓ | T4: ✓ | U4: ✓ | X4: ✓ | Y4: ✓ | Z4: ✓ | AB4: ✓ | AE4: ✓ | AF4: ✓ | AG4: ✓
A5: 3 | B5: 林世彬 | C5: ✓ | D5: ✓ | E5: ✓ | F5: ✓ | G5: ✓ | J5: ✓ | K5: ✓ | L5: ✓ | M5: ✓ | N5: ✓ | Q5: ✓ | R5: ✓ | S5: ✓ | T5: ✓ | U5: ✓ | X5: ✓ | Y5: ✓ | Z5: ✓ | AB5: ✓ | AE5: ✓ | AF5: ✓ | AG5: ✓
A6: 4 | B6: 何彥璋 | C6: 出差 | D6: 出差 | E6: 出差 | F6: 出差 | G6: 出差 | J6: 出差 | K6: 出差 | L6: 出差 | M6: 出差 | N6: 出差 | Q6: 出差 | R6: 出差 | S6: 出差 | T6: 出差 | U6: ◎ | X6: ✓ | Y6: ✓ | Z6: ✓ | AB6: ✓ | AE6: ✓ | AF6: ✓ | AG6: ✓
A7: 5 | B7: 吳嘉銘 | C7: 出差 | D7: 出差 | E7: 出差 | F7: 出差 | G7: 出差 | J7: 出差 | K7: 出差 | L7: 出差 | M7: 出差 | N7: 出差 | Q7: 出差 | R7: 出差 | S7: 出差 | T7: 出差 | U7: 出差 | X7: 出差 | Y7: 出差 | Z7: 出差 | AB7: 出差 | AE7: 出差 | AF7: 出差 | AG7: 出差
A8: 6 | B8: 林詠書 | C8: ✓ | D8: ✓ | E8: ✓ | F8: ✓ | G8: ✓ | J8: ✓ | K8: ✓ | L8: ✓ | M8: 請假 | N8: ✓ | Q8: ✓ | R8: ✓ | S8: ✓ | T8: ✓ | U8: ✓ | X8: ✓ | Y8: ✓ | Z8: ✓ | AB8: ✓ | AE8: ✓ | AF8: ✓ | AG8: ✓
A9: 7 | B9: 謝秉宏 | C9: ✓ | D9: ✓ | E9: ◎ | F9: ✓ | G9: 請假 | J9: ✓ | K9: △ | L9: ✓ | M9: 請假 | N9: ◎ | O9: 出差 | P9: 出差 | Q9: 出差 | R9: 出差 | S9: 出差 | T9: 出差 | U9: 出差 | X9: 出差 | Y9: 出差 | Z9: 出差 | AB9: 出差 | AE9: 出差 | AF9: 出差 | AG9: 出差
A10: 8 | B10: 林建宏 | C10: ✓ | D10: ✓ | E10: ✓ | F10: ✓ | G10: ✓ | J10: 請假 | K10: ✓ | L10: ✓ | M10: ✓ | N10: ✓ | Q10: ✓ | R10: ✓ | S10: ✓ | T10: ✓ | U10: ✓ | X10: ✓ | Y10: ✓ | Z10: ✓ | AB10: ✓ | AE10: ✓ | AF10: ✓ | AG10: ✓
A11: 9 | B11: 蘇景郁 | C11: 出差 | D11: 出差 | E11: 出差 | F11: 出差 | G11: 出差 | J11: 出差 | K11: 出差 | L11: 出差 | M11: 出差 | N11: 出差 | Q11: 出差 | R11: 出差 | S11: 出差 | T11: 出差 | U11: 出差 | X11: 出差 | Y11: 出差 | Z11: 出差 | AB11: 出差 | AE11: 出差 | AF11: 出差 | AG11: 出差
A12: 10 | B12: 潘其昌 | C12: 出差 | D12: ✓ | E12: ✓ | F12: ✓ | G12: ✓ | J12: ✓ | K12: ◎ | L12: ✓ | M12: ✓ | N12: 出差 | Q12: 出差 | R12: 出差 | S12: 出差 | T12: 出差 | U12: 出差 | X12: 出差 | Y12: 出差 | Z12: 出差 | AB12: 出差 | AE12: 出差 | AF12: 出差 | AG12: 出差
A13: 11 | B13: 陳俊男 | C13: 出差 | D13: 出差 | E13: 出差 | F13: 出差 | G13: 出差 | J13: 出差 | K13: 出差 | L13: 出差 | M13: 出差 | N13: 出差 | Q13: 出差 | R13: 出差 | S13: 出差 | T13: 出差 | U13: 出差 | X13: 出差 | Y13: 出差 | Z13: 出差 | AB13: 出差 | AE13: 出差 | AF13: 出差 | AG13: 出差
A14: 12 | B14: 林政宏 | C14: ✓ | D14: ◎ | E14: 出差 | F14: 出差 | G14: 出差 | J14: 出差 | K14: 出差 | L14: 出差 | M14: 出差 | N14: 出差 | Q14: 出差 | R14: 出差 | S14: 出差 | T14: 出差 | U14: 出差 | X14: 出差 | Y14: 出差 | Z14: 出差 | AB14: 出差 | AE14: 出差 | AF14: 出差 | AG14: 出差
A15: 13 | B15: 劉益豪 | C15: 出差 | D15: 出差 | E15: 出差 | F15: 出差 | G15: 出差 | J15: 出差 | K15: 出差 | L15: 出差 | M15: 出差 | N15: 出差 | Q15: 出差 | R15: 出差 | S15: 出差 | T15: 出差 | U15: 出差 | X15: 出差 | Y15: ◎ | Z15: ✓ | AB15: ✓ | AE15: ✓ | AF15: △ | AG15: ✓
A16: 14 | B16: 李威漢 | C16: 出差 | D16: 出差 | E16: 出差 | F16: 出差 | G16: 出差 | J16: 出差 | K16: 出差 | L16: 出差 | M16: 出差 | N16: 出差 | Q16: 出差 | R16: 出差 | S16: 出差 | T16: 出差 | U16: 出差 | X16: 出差 | Y16: 出差 | Z16: 出差 | AB16: 出差 | AE16: 出差 | AF16: 出差 | AG16: 出差
A17: 15 | B17: 王挺翰 | C17: ✓ | D17: ✓ | E17: ✓ | F17: ✓ | G17: ✓ | J17: ✓ | K17: ✓ | L17: ✓ | M17: ✓ | N17: ✓ | Q17: ✓ | R17: ✓ | S17: ✓ | T17: ✓ | U17: ✓ | X17: ✓ | Y17: ◎ | Z17: ✓ | AB17: 體檢假 | AE17: ✓ | AF17: ✓ | AG17: ◎
A18: 16 | B18: 李又誠 | C18: ✓ | D18: ✓ | E18: ✓ | F18: ✓ | G18: ✓ | J18: ✓ | K18: ✓ | L18: ✓ | M18: ✓ | N18: ✓ | Q18: ✓ | R18: ✓ | S18: ✓ | T18: ✓ | U18: ✓ | X18: ✓ | Y18: ◎ | Z18: ✓ | AB18: 體檢假 | AE18: ✓ | AF18: ✓ | AG18: ◎
A19: 17 | B19: 徐亞維 | C19: ✓ | D19: ✓ | E19: ✓ | F19: ✓ | G19: ✓ | J19: ✓ | K19: ✓ | L19: ✓ | M19: ✓ | N19: ✓ | Q19: ✓ | R19: ✓ | S19: ✓ | T19: ✓ | U19: ✓ | X19: ✓ | Y19: ✓ | Z19: ✓ | AB19: ✓ | AE19: ✓ | AF19: ✓ | AG19: ✓
A20: 18 | B20: 陳明生 | C20: / | D20: / | E20: / | F20: / | G20: / | J20: / | K20: / | L20: / | M20: / | N20: / | Q20: / | R20: / | S20: / | T20: / | U20: / | X20: / | Y20: / | Z20: / | AB20: / | AE20: / | AF20: / | AG20: /
A21: 19 | B21: 黃嘉尉 | C21: ✓
A22: ✓ | B22: 正常
A23: ◎ | B23: 補休
A24: △ | B24: 遲到
A26: 1.當年度6月後累計天數超過96單位(6天)之人員，定期通知提醒該員按時休假。
A27: 2.當年度年底(12/31)未休完之單位時數可累計至下年度前3個月使用，最高累計單位時數為112單位(7天)，超過則不採計。
A28: 3.第2項之天數未依規定休完則直接歸零計。
A29: 4.第2項之天數如因任務/出差等因素未休完則由主管依個案處理。
A30: 5.提報加班時數超過3單位請填寫上加班原因(例: 3單位，XXX專案DOE)。
A31: 6.請補休(填出勤確認單)最長連續時數以16單位(1天)為上限(填出勤單不要超過1天以上)。
A32: 7.此補休辦法(填出勤確認單)請大家一起維護，被人資發現告發後此單位時數一但被歸零則無法補發。

Sheet TP12月份請假
A1: TP請假 | C1: 12月累計 (0.5小時/單位) | D1: 45627 | E1: 45628 | F1: 45629 | G1: 45630 | H1: 45631 | I1: 45632 | J1: 45633 | K1: 45634 | L1: 45635 | M1: 45636 | N1: 45637 | O1: 45638 | P1: 45639 | Q1: 45640 | R1: 45641 | S1: 45642 | T1: 45643 | U1: 45644 | V1: 45645 | W1: 45646 | X1: 45647 | Y1: 45648 | Z1: 45649 | AA1: 45650 | AB1: 45651 | AC1: 45652 | AD1: 45653 | AE1: 45654 | AF1: 45655 | AG1: 45656 | AH1: 45657
A2: NO. | B2: 姓名
A3: 1 | B3: 郭先弘 | C3: =SUM(D3:AH3) -> 0 | D3: 0 | E3: 0 | F3: 0 | G3: 0 | H3: 0 | K3: 0 | L3: 0 | M3: 0 | N3: 0 | O3: 0 | R3: 0 | S3: 0 | T3: 0 | U3: 0 | V3: 0 | Y3: 0 | Z3: 0 | AA3: 0 | AC3: 0 | AF3: 0 | AG3: 0 | AH3: 0
A4: 2 | B4: 陳淑芬 | C4: =SUM(D4:AH4) -> 4 | D4: 0 | E4: 0 | F4: 0 | G4: 0 | H4: 0 | K4: 0 | L4: 4 | M4: 0 | N4: 0 | O4: 0 | R4: 0 | S4: 0 | T4: 0 | U4: 0 | V4: 0 | Y4: 0 | Z4: 0 | AA4: 0 | AC4: 0 | AF4: 0 | AG4: 0 | AH4: 0
A5: 3 | B5: 林世彬 | C5: =SUM(D5:AH5) -> 8 | D5: 0 | E5: 0 | F5: 0 | G5: 0 | H5: 0 | K5: 8 | L5: 0 | M5: 0 | N5: 0 | O5: 0 | R5: 0 | S5: 0 | T5: 0 | U5: 0 | V5: 0 | Y5: 0 | Z5: 0 | AA5: 0 | AC5: 0 | AF5: 0 | AG5: 0 | AH5: 0
A6: 4 | B6: 何彥璋 | C6: =SUM(D6:AH6) -> 16 | D6: 0 | E6: 0 | F6: 0 | G6: 0 | H6: 0 | K6: 0 | L6: 0 | M6: 0 | N6: 0 | O6: 0 | R6: 0 | S6: 0 | T6: 0 | U6: 0 | V6: 16 | Y6: 0 | Z6: 0 | AA6: 0 | AC6: 0 | AF6: 0 | AG6: 0 | AH6: 0
A7: 5 | B7: 吳嘉銘 | C7: =SUM(D7:AH7) -> 0 | D7: 0 | E7: 0 | F7: 0 | G7: 0 | H7: 0 | K7: 0 | L7: 0 | M7: 0 | N7: 0 | O7: 0 | R7: 0 | S7: 0 | T7: 0 | U7: 0 | V7: 0 | Y7: 0 | Z7: 0 | AA7: 0 | AC7: 0 | AF7: 0 | AG7: 0 | AH7: 0
A8: 6 | B8: 林詠書 | C8: =SUM(D8:AH8) -> 4 | D8: 0 | E8: 0 | F8: 0 | G8: 0 | H8: 0 | K8: 0 | L8: 0 | M8: 0 | N8: 0 | O8: 0 | R8: 0 | S8: 0 | T8: 0 | U8: 0 | V8: 4 | Y8: 0 | Z8: 0 | AA8: 0 | AC8: 0 | AF8: 0 | AG8: 0 | AH8: 0
A9: 7 | B9: 謝秉宏 | C9: =SUM(D9:AH9) -> 28 | D9: 0 | E9: 0 | F9: 16 | G9: 0 | H9: 0 | K9: 0 | L9: 8 | M9: 0 | N9: 0 | O9: 4 | R9: 0 | S9: 0 | T9: 0 | U9: 0 | V9: 0 | Y9: 0 | Z9: 0 | AA9: 0 | AC9: 0 | AF9: 0 | AG9: 0 | AH9: 0
A10: 8 | B10: 林建宏 | C10: =SUM(D10:AH10) -> 0 | D10: 0 | E10: 0 | F10: 0 | G10: 0 | H10: 0 | K10: 0 | L10: 0 | M10: 0 | N10: 0 | O10: 0 | R10: 0 | S10: 0 | T10: 0 | U10: 0 | V10: 0 | Y10: 0 | Z10: 0 | AA10: 0 | AC10: 0 | AF10: 0 | AG10: 0 | AH10: 0
A11: 9 | B11: 蘇景郁 | C11: =SUM(D11:AH11) -> 0 | D11: 0 | E11: 0 | F11: 0 | G11: 0 | H11: 0 | K11: 0 | L11: 0 | M11: 0 | N11: 0 | O11: 0 | R11: 0 | S11: 0 | T11: 0 | U11: 0 | V11: 0 | Y11: 0 | Z11: 0 | AA11: 0 | AC11: 0 | AF11: 0 | AG11: 0 | AH11: 0
A12: 10 | B12: 潘其昌 | C12: =SUM(D12:AH12) -> 16 | D12: 0 | E12: 0 | F12: 0 | G12: 0 | H12: 0 | K12: 0 | L12: 16 | M12: 0 | N12: 0 | O12: 0 | R12: 0 | S12: 0 | T12: 0 | U12: 0 | V12: 0 | Y12: 0 | Z12: 0 | AA12: 0 | AC12: 0 | AF12: 0 | AG12: 0 | AH12: 0
A13: 11 | B13: 陳俊男 | C13: =SUM(D13:AH13) -> 0 | D13: 0 | E13: 0 | F13: 0 | G13: 0 | H13: 0 | K13: 0 | L13: 0 | M13: 0 | N13: 0 | O13: 0 | R13: 0 | S13: 0 | T13: 0 | U13: 0 | V13: 0 | Y13: 0 | Z13: 0 | AA13: 0 | AC13: 0 | AF13: 0 | AG13: 0 | AH13: 0
A14: 12 | B14: 林政宏 | C14: =SUM(D14:AH14) -> 16 | D14: 0 | E14: 16 | F14: 0 | G14: 0 | H14: 0 | K14: 0 | L14: 0 | M14: 0 | N14: 0 | O14: 0 | R14: 0 | S14: 0 | T14: 0 | U14: 0 | V14: 0 | Y14: 0 | Z14: 0 | AA14: 0 | AC14: 0 | AF14: 0 | AG14: 0 | AH14: 0
... A20: 18 | B20: 陳明生 | C20: =SUM(D20:AH20) -> 3 | D20: 0 | E20: 0 | F20: 0 | G20: 0 | H20: 0 | K20: 0 | L20: 0 | M20: 0 | N20: 0 | O20: 0 | R20: 0 | S20: 0 | T20: 0 | U20: 0 | V20: 0 | Y20: 0 | Z20: 0 | AA20: 0 | AC20: 0 | AF20: 0 | AG20: 0 | AH20: 3

Sheet TP12月份加班
A1: TP加班 | C1: 12月累計 (0.5小時/單位) | D1: 45627 | E1: 45628 | F1: 45629 | G1: 45630 | H1: 45631 | I1: 45632 | J1: 45633 | K1: 45634 | L1: 45635 | M1: 45636 | N1: 45637 | O1: 45638 | P1: 45639 | Q1: 45640 | R1: 45641 | S1: 45642 | T1: 45643 | U1: 45644 | V1: 45645 | W1: 45646 | X1: 45647 | Y1: 45648 | Z1: 45649 | AA1: 45650 | AB1: 45651 | AC1: 45652 | AD1: 45653 | AE1: 45654 | AF1: 45655 | AG1: 45656 | AH1: 45657
A2: NO. | B2: 姓名
A3: 1 | B3: 郭先弘 | C3: =SUM(D3:AH3) -> 0 | D3: 0 | E3: 0 | F3: 0 | G3: 0 | H3: 0 | K3: 0 | L3: 0 | M3: 0 | N3: 0 | O3: 0 | R3: 0 | S3: 0 | T3: 0 | U3: 0 | V3: 0 | Y3: 0 | Z3: 0 | AA3: 0 | AC3: 0 | AF3: 0 | AG3: 0 | AH3: 0
A4: 2 | B4: 陳淑芬 | C4: =SUM(D4:AH4) -> 0 | D4: 0 | E4: 0 | F4: 0 | G4: 0 | H4: 0 | K4: 0 | L4: 0 | M4: 0 | N4: 0 | O4: 0 | R4: 0 | S4: 0 | T4: 0 | U4: 0 | V4: 0 | Y4: 0 | Z4: 0 | AA4: 0 | AC4: 0 | AF4: 0 | AG4: 0 | AH4: 0
A5: 3 | B5: 林世彬 | C5: =SUM(D5:AH5) -> 8 | D5: 0 | E5: 0 | F5: 0 | G5: 0 | H5: 0 | K5: 0 | L5: 0 | M5: 0 | N5: 0 | O5: 0 | R5: 0 | S5: 0 | T5: 0 | U5: 0 | V5: 2 | X5: 6 | Y5: 0 | Z5: 0 | AA5: 0 | AC5: 0 | AF5: 0 | AG5: 0 | AH5: 0
A6: 4 | B6: 何彥璋 | C6: =SUM(D6:AH6) -> 12 | D6: 1 | E6: 1 | F6: 1 | G6: 1 | H6: 1 | K6: 1 | L6: 1 | M6: 1 | N6: 1 | O6: 0 | R6: 0 | S6: 0 | T6: 0 | U6: 0 | V6: 0 | Y6: 0 | Z6: 0 | AA6: 3 | AC6: 0 | AF6: 0 | AG6: 0 | AH6: 0
A7: 5 | B7: 吳嘉銘 | C7: =SUM(D7:AH7) -> 96 | D7: 4 | E7: 4 | F7: 0 | G7: 4 | H7: 4 | I7: 2 | J7: 2 | K7: 4 | L7: 4 | M7: 4 | N7: 4 | O7: 4 | P7: 2 | R7: 4 | S7: 4 | T7: 4 | U7: 0 | V7: 4 | W7: 16 | X7: 2 | Y7: 4 | Z7: 4 | AA7: 4 | AC7: 4 | AF7: 4 | AG7: 0 | AH7: 0
A8: 6 | B8: 林詠書 | C8: =SUM(D8:AH8) -> 16 | D8: 1 | E8: 1 | F8: 1 | G8: 1 | H8: 1 | K8: 1 | L8: 1 | M8: 1 | N8: 0 | O8: 0 | R8: 1 | S8: 0 | T8: 0 | U8: 2 | V8: 0 | Y8: 0 | Z8: 2 | AA8: 0 | AC8: 0 | AF8: 1 | AG8: 2 | AH8: 0
A9: 0 | B9: 謝秉宏 | C9: =SUM(D9:AH9) -> 7 | D9: 0 | E9: 1 | F9: 0 | G9: 1 | H9: 0 | K9: 1 | L9: 0 | M9: 0 | N9: 0 | O9: 0 | R9: 0 | S9: 0 | T9: 0 | U9: 2 | V9: 0 | Y9: 0 | Z9: 0 | AA9: 2 | AC9: 0 | AF9: 0 | AG9: 0 | AH9: 0
A10: 8 | B10: 林建宏 | C10: =SUM(D10:AH10) -> 0 | D10: 0 | E10: 0 | F10: 0 | G10: 0 | H10: 0 | K10: 0 | L10: 0 | M10: 0 | N10: 0 | O10: 0 | R10: 0 | S10: 0 | T10: 0 | U10: 0 | V10: 0 | Y10: 0 | Z10: 0 | AA10: 0 | AC10: 0 | AF10: 0 | AG10: 0 | AH10: 0
A11: 9 | B11: 蘇景郁 | C11: =SUM(D11:AH11) -> 74 | D11: 4 | E11: 4 | F11: 0 | G11: 4 | H11: 4 | I11: 2 | J11: 2 | K11: 4 | L11: 4 | M11: 0 | N11: 4 | O11: 4 | P11: 2 | R11: 4 | S11: 0 | T11: 4 | U11: 4 | V11: 4 | Y11: 4 | Z11: 4 | AA11: 0 | AC11: 4 | AF11: 8 | AG11: 0 | AH11: 0
A12: 10 | B12: 潘其昌 | C12: =SUM(D12:AH12) -> 17 | D12: 0 | E12: 0 | F12: 0 | G12: 0 | H12: 1 | K12: 0 | L12: 0 | M12: 0 | N12: 0 | O12: 0 | R12: 0 | S12: 0 | T12: 0 | U12: 0 | V12: 0 | Y12: 0 | Z12: 0 | AA12: 0 | AB12: 16 | AC12: 0 | AF12: 0 | AG12: 0 | AH12: 0
A13: 11 | B13: 陳俊男 | C13: =SUM(D13:AH13) -> 98 | D13: 0 | E13: 4 | F13: 4 | G13: 4 | H13: 4 | I13: 2 | J13: 2 | K13: 8 | L13: 4 | M13: 4 | N13: 4 | O13: 4 | P13: 2 | R13: 4 | S13: 4 | T13: 4 | U13: 4 | V13: 4 | X13: 2 | Y13: 4 | Z13: 4 | AA13: 4 | AC13: 4 | AF13: 4 | AG13: 5 | AH13: 5
A14: 12 | B14: 林政宏 | C14: =SUM(D14:AH14) -> 111 | D14: 0 | E14: 2 | F14: 0 | G14: 4 | H14: 4 | K14: 4 | L14: 4 | M14: 7 | N14: 4 | O14: 7 | P14: 2 | R14: 4 | S14: 4 | T14: 4 | U14: 4 | V14: 4 | X14: 2 | Y14: 4 | Z14: 4 | AA14: 4 | AB14: 21 | AC14: 4 | AF14: 4 | AG14: 5 | AH14: 5
A15: 13 | B15: 劉益豪 | C15: =SUM(D15:AH15) -> 30 | D15: 3 | E15: 4 | F15: 4 | G15: 2 | H15: 4 | K15: 2 | L15: 0 | M15: 0 | N15: 1 | O15: 0 | R15: 0 | S15: 2 | T15: 1 | U15: 0 | V15: 4 | Y15: 0 | Z15: 2 | AA15: 0 | AC15: 0 | AF15: 0 | AG15: 1 | AH15: 0
A16: 14 | B16: 李威漢 | C16: =SUM(D16:AH16) -> 144 | D16: 0 | E16: 4 | F16: 8 | G16: 4 | H16: 0 | I16: 2 | J16: 2 | K16: 8 | L16: 8 | M16: 8 | N16: 4 | O16: 0 | P16: 2 | R16: 4 | S16: 8 | T16: 8 | U16: 8 | V16: 6 | X16: 2 | Y16: 8 | Z16: 8 | AA16: 4 | AB16: 20 | AC16: 8 | AF16: 10 | AG16: 0 | AH16: 0
A17: 15 | B17: 王挺翰 | C17: =SUM(D17:AH17) -> 21 | D17: 0 | E17: 10 | F17: 0 | G17: 11 | H17: 0 | K17: 0 | L17: 0 | M17: 0 | N17: 0 | O17: 0 | R17: 0 | S17: 0 | T17: 0 | U17: 0 | V17: 0 | Y17: 0 | Z17: 0 | AA17: 0 | AC17: 0 | AF17: 0 | AG17: 0 | AH17: 0
A18: 16 | B18: 李又誠 | C18: =SUM(D18:AH18) -> 21 | D18: 0 | E18: 10 | F18: 0 | G18: 11 | H18: 0 | K18: 0 | L18: 0 | M18: 0 | N18: 0 | O18: 0 | R18: 0 | S18: 0 | T18: 0 | U18: 0 | V18: 0 | Y18: 0 | Z18: 0 | AA18: 0 | AC18: 0 | AF18: 0 | AG18: 0 | AH18: 0
A19: 17 | B19: 徐亞維 | C19: =SUM(D19:AH19) -> 19 | D19: 0 | E19: 8 | F19: 0 | G19: 11 | H19: 0 | K19: 0 | L19: 0 | M19: 0 | N19: 0 | O19: 0 | R19: 0 | S19: 0 | T19: 0 | U19: 0 | V19: 0 | Y19: 0 | Z19: 0 | AA19: 0 | AC19: 0 | AF19: 0 | AG19: 0 | AH19: 0
A20: 18 | B20: 陳明生 | C20: =SUM(D20:AH20) -> 84 | D20: 5 | E20: 5 | F20: 6 | G20: 6 | H20: 6 | K20: 5 | L20: 5 | M20: 5 | N20: 10 | O20: 0 | R20: 5 | S20: 5 | T20: 5 | U20: 0 | V20: 0 | Y20: 0 | Z20: 0 | AA20: 0 | AB20: 16 | AC20: 0 | AF20: 0 | AG20: 0 | AH20: 0
B22: 有標註（GTK刷臉）
A23: 12/6 四筆(紅字)為 12/2 (非GTK刷臉)時數
A24: 12/13 三筆(紅字)為 12/916 (非GTK刷臉)時數
A25: 12/13五筆(紅字)為 12/16 (非GTK刷臉)時數
A26: 12/21四筆(紅字)為 12/23 (非GTK刷臉)時數

Sheet TP出勤1月份
A1: TP出勤 | C1: 45292 | D1: 45293 | E1: 45294 | F1: 45295 | G1: 45296 | H1: 45297 | I1: 45298 | J1: 45299 | K1: 45300 | L1: 45301 | M1: 45302 | N1: 45303 | O1: 45304 | P1: 45305 | Q1: 45306 | R1: 45307 | S1: 45308 | T1: 45309 | U1: 45310 | V1: 45311 | W1: 45312 | X1: 45313 | Y1: 45314 | Z1: 45315 | AA1: 45316 | AB1: 45317 | AC1: 45318 | AD1: 45319 | AE1: 45320 | AF1: 45321 | AG1: 45322
A2: NO. | B2: 姓名
A3: 1 | B3: 郭先弘 | D3: ✓ | E3: ✓ | H3: ✓ | I3: ✓ | J3: ✓ | K3: ✓ | L3: ✓ | O3: ◎ | P3: ✓ | Q3: ✓ | R3: ✓ | S3: ✓ | V3: ✓ | W3: ✓ | X3: ✓ | Y3: ✓
A4: 2 | B4: 陳淑芬 | D4: ✓ | E4: ✓ | H4: ✓ | I4: ✓ | J4: ✓ | K4: ✓ | L4: ✓ | O4: ✓ | P4: ✓ | Q4: ✓ | R4: ✓ | S4: ✓ | V4: ✓ | W4: ✓ | X4: ✓ | Y4: ✓
A5: 3 | B5: 林世彬 | D5: ✓ | E5: ✓ | H5: ✓ | I5: ✓ | J5: ✓ | K5: ✓ | L5: ✓ | O5: ✓ | P5: ✓ | Q5: ✓ | R5: ✓ | S5: ✓ | V5: ✓ | W5: ✓ | X5: ✓ | Y5: ✓
A6: 4 | B6: 何彥璋 | D6: ✓ | E6: ✓ | H6: ✓ | I6: 出差 | J6: 出差 | K6: 出差 | L6: 出差 | O6: 出差 | P6: 出差 | Q6: 出差 | R6: 出差 | S6: 出差 | V6: ✓ | W6: ✓ | X6: 請假 | Y6: ✓
A7: 5 | B7: 吳嘉銘 | D7: ◎ | E7: ✓ | H7: ✓ | I7: ✓ | J7: ✓ | K7: ✓ | L7: ✓ | O7: ✓ | P7: ✓ | Q7: ✓ | R7: ✓ | S7: ✓ | V7: ✓ | W7: ✓ | X7: ✓ | Y7: ✓
A8: 6 | B8: 林詠書 | D8: ✓ | E8: ✓ | H8: ✓ | I8: ✓ | J8: ✓ | K8: ✓ | L8: ✓ | O8: ✓ | P8: ◎ | Q8: ✓ | R8: ✓ | S8: ✓ | V8: ✓ | W8: ✓ | X8: ✓ | Y8: 請假
A9: 7 | B9: 謝秉宏 | D9: ✓ | E9: ✓ | H9: ✓ | I9: ✓ | J9: ✓ | K9: ✓ | L9: ✓ | O9: ✓ | P9: ✓ | Q9: ◎ | R9: 休假 | S9: ✓ | V9: ✓ | W9: ✓ | X9: ✓ | Y9: ✓
A10: 8 | B10: 林建宏 | D10: ✓ | E10: ✓ | H10: ✓ | I10: ✓ | J10: ✓ | K10: ✓ | L10: ✓ | O10: ✓ | P10: ✓ | Q10: ✓ | R10: ✓ | S10: ✓ | V10: ✓ | W10: ✓ | X10: ✓ | Y10: ✓
A11: 9 | B11: 蘇景郁 | D11: ✓ | E11: ✓ | H11: ✓ | I11: ✓ | J11: ✓ | K11: ✓ | L11: 出差 | O11: 出差 | P11: 出差 | Q11: 出差 | R11: 出差 | S11: 出差 | V11: 出差 | W11: 出差 | X11: 出差 | Y11: 出差 | Z11: 出差
A12: 10 | B12: 潘其昌 | D12: ✓ | E12: ✓ | H12: ✓ | I12: ✓ | J12: ✓ | K12: ✓ | L12: 出差 | O12: 出差 | P12: 出差 | Q12: 出差 | R12: 出差 | S12: 出差 | V12: 出差 | W12: 出差 | X12: 出差 | Y12: 出差 | Z12: 出差
A13: 11 | B13: 陳俊男 | D13: ✓ | E13: ✓ | H13: ✓ | I13: ✓ | J13: ✓ | K13: ✓ | L13: 請假 | O13: ◎ | P13: ✓ | Q13: ✓ | R13: ✓ | S13: ✓ | V13: ✓ | W13: ✓ | X13: ✓ | Y13: ✓
A14: 12 | B14: 林政宏 | D14: ✓ | E14: ✓ | H14: ✓ | I14: ✓ | J14: ✓ | K14: ✓ | L14: ✓ | O14: ◎ | P14: ✓ | Q14: ✓ | R14: ✓ | S14: ✓ | V14: ✓ | W14: ✓ | X14: ✓ | Y14: ✓
A15: 13 | B15: 劉益豪 | D15: 請假 | E15: ◎ | H15: ✓ | I15: ✓ | J15: △ | K15: ✓ | L15: ✓ | O15: ✓ | P15: ✓ | Q15: ✓ | R15: ✓ | S15: ✓ | V15: ✓ | W15: 請假 | X15: ✓ | Y15: ✓
A16: 14 | B16: 李威漢 | D16: ✓ | E16: ✓ | H16: ✓ | I16: ✓ | J16: ✓ | K16: ✓ | L16: ✓ | O16: ✓ | P16: ✓ | Q16: ✓ | R16: ✓ | S16: ✓ | V16: ✓ | W16: ✓ | X16: ✓ | Y16: ✓
A17: 15 | B17: 王挺翰 | D17: ✓ | E17: ✓ | H17: ✓ | I17: ✓ | J17: ✓ | K17: ✓ | L17: ✓ | O17: ✓ | P17: ✓ | Q17: ✓ | R17: ✓ | S17: ◎ | V17: ✓ | W17: ✓ | X17: ✓ | Y17: ✓
A18: 16 | B18: 李又誠 | D18: ✓ | E18: ✓ | H18: ✓ | I18: ✓ | J18: ✓ | K18: ✓ | L18: ✓ | O18: ✓ | P18: ✓ | Q18: ✓ | R18: ✓ | S18: ◎ | V18: ✓ | W18: ✓ | X18: ✓ | Y18: ✓
A19: ✓ | B19: 正常
A20: ◎ | B20: 補休
A21: △ | B21: 遲到

Sheet TP1月份請假
A1: TP請假 | C1: 一月累計 (0.5小時/單位) | D1: 45292 | E1: 45293 | F1: 45294 | G1: 45295 | H1: 45296 | I1: 45297 | J1: 45298 | K1: 45299 | L1: 45300 | M1: 45301 | N1: 45302 | O1: 45303 | P1: 45304 | Q1: 45305 | R1: 45306 | S1: 45307 | T1: 45308 | U1: 45309 | V1: 45310 | W1: 45311 | X1: 45312 | Y1: 45313 | Z1: 45314 | AA1: 45315 | AB1: 45316 | AC1: 45317 | AD1: 45318 | AE1: 45319 | AF1: 45320 | AG1: 45321 | AH1: 45322
A2: NO. | B2: 姓名
A3: 1 | B3: 郭先弘 | C3: =SUM(D3:AH3) -> 0 | E3: 0 | F3: 0 | I3: 0 | J3: 0 | K3: 0 | L3: 0 | M3: 0 | P3: 0 | Q3: 0 | R3: 0 | S3: 0 | T3: 0 | W3: 0 | X3: 0 | Y3: 0 | Z3: 0
A4: 2 | B4: 陳淑芬 | C4: =SUM(D4:AH4) -> 10 | E4: 0 | F4: 10 | I4: 0 | J4: 0 | K4: 0 | L4: 0 | M4: 0 | P4: 0 | Q4: 0 | R4: 0 | S4: 0 | T4: 0 | W4: 0 | X4: 0 | Y4: 0 | Z4: 0
A5: 3 | B5: 林世彬 | C5: =SUM(D5:AH5) -> 0 | E5: 0 | F5: 0 | I5: 0 | J5: 0 | K5: 0 | L5: 0 | M5: 0 | P5: 0 | Q5: 0 | R5: 0 | S5: 0 | T5: 0 | W5: 0 | X5: 0 | Y5: 0 | Z5: 0
A6: 4 | B6: 何彥璋 | C6: =SUM(D6:AH6) -> 0 | E6: 0 | F6: 0 | I6: 0 | J6: 0 | K6: 0 | L6: 0 | M6: 0 | P6: 0 | Q6: 0 | R6: 0 | S6: 0 | T6: 0 | W6: 0 | X6: 0 | Y6: 0 | Z6: 0
A7: 5 | B7: 吳嘉銘 | C7: =SUM(D7:AH7) -> 16 | E7: 16 | F7: 0 | I7: 0 | J7: 0 | K7: 0 | L7: 0 | M7: 0 | P7: 0 | Q7: 0 | R7: 0 | S7: 0 | T7: 0 | W7: 0 | X7: 0 | Y7: 0 | Z7: 0
A8: 6 | B8: 林詠書 | C8: =SUM(D8:AH8) -> 32 | E8: 0 | F8: 0 | I8: 0 | J8: 0 | K8: 0 | L8: 0 | M8: 0 | P8: 0 | Q8: 16 | R8: 0 | S8: 0 | T8: 0 | W8: 0 | X8: 0 | Y8: 0 | Z8: 16
A9: 7 | B9: 謝秉宏 | C9: =SUM(D9:AH9) -> 24 | E9: 0 | F9: 8 | I9: 0 | J9: 0 | K9: 0 | L9: 0 | M9: 0 | P9: 0 | Q9: 0 | R9: 16 | S9: 0 | T9: 0 | W9: 0 | X9: 0 | Y9: 0 | Z9: 0
A10: 8 | B10: 林建宏 | C10: =SUM(D10:AH10) -> 0 | E10: 0 | F10: 0 | I10: 0 | J10: 0 | K10: 0 | L10: 0 | M10: 0 | P10: 0 | Q10: 0 | R10: 0 | S10: 0 | T10: 0 | W10: 0 | X10: 0 | Y10: 0 | Z10: 0
A11: 9 | B11: 蘇景郁 | C11: =SUM(D11:AH11) -> 0 | E11: 0 | F11: 0 | I11: 0 | J11: 0 | K11: 0 | L11: 0 | M11: 0 | P11: 0 | Q11: 0 | R11: 0 | S11: 0 | T11: 0 | W11: 0 | X11: 0 | Y11: 0 | Z11: 0
A12: 10 | B12: 潘其昌 | C12: =SUM(D12:AH12) -> 0 | E12: 0 | F12: 0 | I12: 0 | J12: 0 | K12: 0 | L12: 0 | M12: 0 | P12: 0 | Q12: 0 | R12: 0 | S12: 0 | T12: 0 | W12: 0 | X12: 0 | Y12: 0 | Z12: 0
A13: 11 | B13: 陳俊男 | C13: =SUM(D13:AH13) -> 2 | E13: 0 | F13: 0 | I13: 0 | J13: 0 | K13: 0 | L13: 0 | M13: 0 | P13: 0 | Q13: 0 | R13: 0 | S13: 0 | T13: 0 | W13: 0 | X13: 0 | Y13: 0 | Z13: 2
A14: 12 | B14: 林政宏 | C14: =SUM(D14:AH14) -> 0 | E14: 0 | F14: 0 | I14: 0 | J14: 0 | K14: 0 | L14: 0 | M14: 0 | P14: 0 | Q14: 0 | R14: 0 | S14: 0 | T14: 0 | W14: 0 | X14: 0 | Y14: 0 | Z14: 0
... A18: 16 | B18: 李又誠 | C18: =SUM(D18:AH18) -> 16 | E18: 0 | F18: 0 | I18: 0 | J18: 0 | K18: 0 | L18: 0 | M18: 0 | P18: 0 | Q18: 0 | R18: 0 | S18: 0 | T18: 16 | W18: 0 | X18: 0 | Y18: 0 | Z18: 0

Sheet TP1月份加班
A1: TP加班 | C1: 一月累計 (0.5小時/單位) | D1: 45292 | E1: 45293 | F1: 45294 | G1: 45295 | H1: 45296 | I1: 45297 | J1: 45298 | K1: 45299 | L1: 45300 | M1: 45301 | N1: 45302 | O1: 45303 | P1: 45304 | Q1: 45305 | R1: 45306 | S1: 45307 | T1: 45308 | U1: 45309 | V1: 45310 | W1: 45311 | X1: 45312 | Y1: 45313 | Z1: 45314 | AA1: 45315 | AB1: 45316 | AC1: 45317 | AD1: 45318 | AE1: 45319 | AF1: 45320 | AG1: 45321 | AH1: 45322
A2: NO. | B2: 姓名
A3: 1 | B3: 郭先弘 | C3: =SUM(D3:AH3) -> 0 | E3: 0 | F3: 0 | I3: 0 | J3: 0 | K3: 0 | L3: 0 | M3: 0 | P3: 0 | Q3: 0 | R3: 0 | S3: 0 | T3: 0 | W3: 0 | X3: 0 | Y3: 0 | Z3: 0
A4: 2 | B4: 陳淑芬 | C4: =SUM(D4:AH4) -> 0 | E4: 0 | F4: 0 | I4: 0 | J4: 0 | K4: 0 | L4: 0 | M4: 0 | P4: 0 | Q4: 0 | R4: 0 | S4: 0 | T4: 0 | W4: 0 | X4: 0 | Y4: 0 | Z4: 0
A5: 3 | B5: 林世彬 | C5: =SUM(D5:AH5) -> 0 | E5: 0 | F5: 0 | I5: 0 | J5: 0 | K5: 0 | L5: 0 | M5: 0 | P5: 0 | Q5: 0 | R5: 0 | S5: 0 | T5: 0 | W5: 0 | X5: 0 | Y5: 0 | Z5: 0
A6: 4 | B6: 何彥璋 | C6: =SUM(D6:AH6) -> 4 | E6: 4 | F6: 0 | I6: 0 | J6: 0 | K6: 0 | L6: 0 | M6: 0 | P6: 0 | Q6: 0 | R6: 0 | S6: 0 | T6: 0 | W6: 0 | X6: 0 | Y6: 0 | Z6: 0
A7: 5 | B7: 吳嘉銘 | C7: =SUM(D7:AH7) -> 18 | E7: 0 | F7: 0 | I7: 0 | J7: 0 | K7: 8 | L7: 10 | M7: 0 | P7: 0 | Q7: 0 | R7: 0 | S7: 0 | T7: 0 | W7: 0 | X7: 0 | Y7: 0 | Z7: 0
A8: 6 | B8: 林詠書 | C8: =SUM(D8:AH8) -> 7 | E8: 1 | F8: 0 | I8: 0 | J8: 1 | K8: 1 | L8: 1 | M8: 0 | P8: 0 | Q8: 0 | R8: 0 | S8: 1 | T8: 0 | W8: 0 | X8: 1 | Y8: 1 | Z8: 0
A9: 7 | B9: 謝秉宏 | C9: =SUM(D9:AH9) -> 6 | E9: 0 | F9: 0 | I9: 0 | J9: 0 | K9: 0 | L9: 6 | M9: 0 | P9: 0 | Q9: 0 | R9: 0 | S9: 0 | T9: 0 | W9: 0 | X9: 0 | Y9: 0 | Z9: 0
A10: 8 | B10: 林建宏 | C10: =SUM(D10:AH10) -> 0 | E10: 0 | F10: 0 | I10: 0 | J10: 0 | K10: 0 | L10: 0 | M10: 0 | P10: 0 | Q10: 0 | R10: 0 | S10: 0 | T10: 0 | W10: 0 | X10: 0 | Y10: 0 | Z10: 0
A11: 9 | B11: 蘇景郁 | C11: =SUM(D11:AH11) -> 0 | E11: 0 | F11: 0 | I11: 0 | J11: 0 | K11: 0 | L11: 0 | M11: 0 | P11: 0 | Q11: 0 | R11: 0 | S11: 0 | T11: 0 | W11: 0 | X11: 0 | Y11: 0 | Z11: 0
A12: 10 | B12: 潘其昌 | C12: =SUM(D12:AH12) -> 0 | E12: 0 | F12: 0 | I12: 0 | J12: 0 | K12: 0 | L12: 0 | M12: 0 | P12: 0 | Q12: 0 | R12: 0 | S12: 0 | T12: 0 | W12: 0 | X12: 0 | Y12: 0 | Z12: 0
A13: 11 | B13: 陳俊男 | C13: =SUM(D13:AH13) -> 0 | E13: 0 | F13: 0 | I13: 0 | J13: 0 | K13: 0 | L13: 0 | M13: 0 | P13: 0 | Q13: 0 | R13: 0 | S13: 0 | T13: 0 | W13: 0 | X13: 0 | Y13: 0 | Z13: 0
A14: 12 | B14: 林政宏 | C14: =SUM(D14:AH14) -> 0 | E14: 0 | F14: 0 | I14: 0 | J14: 0 | K14: 0 | L14: 0 | M14: 0 | P14: 0 | Q14: 0 | R14: 0 | S14: 0 | T14: 0 | W14: 0 | X14: 0 | Y14: 0 | Z14: 0
... A18: 16 | B18: 李又誠 | C18: =SUM(D18:AH18) -> 18 | E18: 0 | F18: 0 | I18: 0 | J18: 0 | K18: 8 | L18: 10 | M18: 0 | P18: 0 | Q18: 0 | R18: 0 | S18: 0 | T18: 0 | W18: 0 | X18: 0 | Y18: 0 | Z18: 0

Sheet TP出勤2月份
A1: TP出勤 | C1: 45323 | D1: 45324 | E1: 45325 | F1: 45326 | G1: 45327 | H1: 45328 | I1: 45329 | J1: 45330 | K1: 45331 | L1: 45332 | M1: 45333 | N1: 45334 | O1: 45335 | P1: 45336 | Q1: 45337 | R1: 45338 | S1: 45339 | T1: 45340 | U1: 45341 | V1: 45342 | W1: 45343 | X1: 45344 | Y1: 45345 | Z1: 45346 | AA1: 45347 | AB1: 45348 | AC1: 45349 | AD1: 45350
A2: NO. | B2: 姓名
A3: 1 | B3: 郭先弘 | E3: ✓ | F3: ✓ | G3: ✓ | H3: ✓ | I3: ✓ | J3: ✓ | L3: ✓ | M3: ✓ | N3: ✓ | O3: ✓ | P3: ✓ | S3: ✓ | T3: ✓ | U3: ✓ | V3: ✓ | W3: ✓ | Z3: ✓ | AA3: ✓ | AB3: ✓ | AC3: ✓
A4: 2 | B4: 陳淑芬 | E4: ✓ | F4: ✓ | G4: ✓ | H4: ✓ | I4: ✓ | J4: ✓ | L4: ✓ | M4: ✓ | N4: ✓ | O4: ✓ | P4: ✓ | S4: ✓ | T4: ✓ | U4: ✓ | V4: ✓ | W4: ✓ | Z4: 出差 | AA4: 出差 | AB4: 出差 | AC4: 出差
A5: 3 | B5: 林世彬 | E5: ✓ | F5: ✓ | G5: ✓ | H5: ✓ | I5: ✓ | J5: ✓ | L5: ✓ | M5: ✓ | N5: ✓ | O5: ✓ | P5: ✓ | S5: ✓ | T5: ✓ | U5: ✓ | V5: ✓ | W5: ✓ | Z5: ✓ | AA5: ✓ | AB5: ✓ | AC5: ✓
A6: 4 | B6: 何彥璋 | E6: ✓ | F6: ✓ | G6: ✓ | H6: ✓ | I6: ✓ | J6: ✓ | L6: ✓ | M6: ✓ | N6: ✓ | O6: ◎ | P6: 出差 | S6: 出差 | T6: 出差 | U6: 出差 | V6: 出差 | W6: 出差 | Z6: 出差 | AA6: 出差 | AB6: 出差 | AC6: 出差
A7: 5 | B7: 吳嘉銘 | E7: ✓ | F7: ✓ | G7: ✓ | H7: ✓ | I7: ✓ | J7: ✓ | L7: ✓ | M7: ✓ | N7: ✓ | O7: ✓ | P7: ✓ | S7: ◎ | T7: ✓ | U7: ✓ | V7: ✓ | W7: ✓ | Z7: ✓ | AA7: ✓ | AB7: ✓ | AC7: ✓
A8: 6 | B8: 林詠書 | E8: ✓ | F8: ✓ | G8: ✓ | H8: ✓ | I8: ✓ | J8: ✓ | L8: ✓ | M8: ✓ | N8: ◎ | O8: ✓ | P8: ✓ | S8: ✓ | T8: ✓ | U8: ✓ | V8: ✓ | W8: 請假 | Z8: ✓ | AA8: ✓ | AB8: ✓ | AC8: ✓
A9: 7 | B9: 謝秉宏 | E9: ✓ | F9: ✓ | G9: ✓ | H9: ✓ | I9: ◎ | J9: 請假 | L9: ✓ | M9: ✓ | N9: ✓ | O9: ✓ | P9: 出差 | S9: 出差 | T9: 出差 | U9: 出差 | V9: 出差 | W9: 出差 | Z9: 出差 | AA9: 出差 | AB9: 出差 | AC9: 出差
A10: 8 | B10: 林建宏 | E10: ✓ | F10: ✓ | G10: ✓ | H10: ✓ | I10: ✓ | J10: ✓ | L10: ✓ | M10: ✓ | N10: ✓ | O10: ✓ | P10: ✓ | S10: ✓ | T10: ✓ | U10: ✓ | V10: ✓ | W10: ✓ | Z10: ✓ | AA10: ✓ | AB10: ✓ | AC10: ✓
A11: 9 | B11: 蘇景郁 | E11: ✓ | F11: ✓ | G11: ✓ | H11: ✓ | I11: ✓ | J11: ✓ | L11: ✓ | M11: ✓ | N11: ✓ | O11: ✓ | P11: ✓ | S11: ✓ | T11: ◎ | U11: ✓ | V11: ✓ | W11: ✓ | Z11: ◎ | AA11: △ | AB11: ✓ | AC11: ✓
A12: 10 | B12: 潘其昌 | E12: ✓ | F12: ✓ | G12: ✓ | H12: ✓ | I12: ✓ | J12: ✓ | L12: ✓ | M12: ◎ | N12: ✓ | O12: ✓ | P12: 出差 | S12: 出差 | T12: 出差 | U12: 出差 | V12: 出差 | W12: 出差 | Z12: 出差 | AA12: 出差 | AB12: 出差 | AC12: 出差
A13: 11 | B13: 陳俊男 | E13: ✓ | F13: ✓ | G13: ✓ | H13: ✓ | I13: ✓ | J13: ◎ | L13: 請假 | M13: ✓ | N13: 請假 | O13: ✓ | P13: 出差 | S13: 出差 | T13: 出差 | U13: 出差 | V13: 出差 | W13: 出差 | Z13: 出差 | AA13: 出差 | AB13: 出差 | AC13: 出差
A14: 12 | B14: 林政宏 | E14: ✓ | F14: ✓ | G14: ✓ | H14: ✓ | I14: ✓ | J14: ◎ | L14: ✓ | M14: ✓ | N14: ✓ | O14: ◎ | P14: ✓ | S14: ◎ | T14: ✓ | U14: ✓ | V14: ◎ | W14: 出差 | Z14: 出差 | AA14: 出差 | AB14: 出差 | AC14: 出差
... A18: 16 | B18: 李又誠 | E18: ✓ | F18: ✓ | G18: ✓ | H18: ✓ | I18: ✓ | J18: ✓ | L18: ✓ | M18: ✓ | N18: ✓ | O18: ✓ | P18: ✓ | S18: ✓ | T18: ✓ | U18: ✓ | V18: ✓ | W18: ✓ | Z18: ✓ | AA18: ✓ | AB18: ✓ | AC18: ✓
A19: ✓ | B19: 正常
A20: ◎ | B20: 補休
A21: △ | B21: 遲到

Sheet TP2月份請假
A1: TP請假 | C1: 二月累計 (0.5小時/單位) | D1: 45323 | E1: 45324 | F1: 45325 | G1: 45326 | H1: 45327 | I1: 45328 | J1: 45329 | K1: 45330 | L1: 45331 | M1: 45332 | N1: 45333 | O1: 45334 | P1: 45335 | Q1: 45336 | R1: 45337 | S1: 45338 | T1: 45339 | U1: 45340 | V1: 45341 | W1: 45342 | X1: 45343 | Y1: 45344 | Z1: 45345 | AA1: 45346 | AB1: 45347 | AC1: 45348 | AD1: 45349 | AE1: 45350 | AF1: 45351
A2: NO. | B2: 姓名
A3: 1 | B3: 郭先弘 | C3: =SUM(D3:AF3) -> 0 | F3: 0 | G3: 0 | H3: 0 | I3: 0 | J3: 0 | K3: 0 | M3: 0 | N3: 0 | O3: 0 | P3: 0 | Q3: 0 | T3: 0 | U3: 0 | V3: 0 | W3: 0 | X3: 0 | AA3: 0 | AB3: 0 | AC3: 0 | AD3: 0
A4: 2 | B4: 陳淑芬 | C4: =SUM(D4:AF4) -> 0 | F4: 0 | G4: 0 | H4: 0 | I4: 0 | J4: 0 | K4: 0 | M4: 0 | N4: 0 | O4: 0 | P4: 0 | Q4: 0 | T4: 0 | U4: 0 | V4: 0 | W4: 0 | X4: 0 | AA4: 0 | AB4: 0 | AC4: 0 | AD4: 0
A5: 3 | B5: 林世彬 | C5: =SUM(D5:AF5) -> 4 | F5: 0 | G5: 0 | H5: 0 | I5: 0 | J5: 0 | K5: 0 | M5: 4 | N5: 0 | O5: 0 | P5: 0 | Q5: 0 | T5: 0 | U5: 0 | V5: 0 | W5: 0 | X5: 0 | AA5: 0 | AB5: 0 | AC5: 0 | AD5: 0
A6: 4 | B6: 何彥璋 | C6: =SUM(D6:AF6) -> 24 | F6: 0 | G6: 0 | H6: 0 | I6: 0 | J6: 0 | K6: 0 | M6: 8 | N6: 0 | O6: 0 | P6: 16 | Q6: 0 | T6: 0 | U6: 0 | V6: 0 | W6: 0 | X6: 0 | AA6: 0 | AB6: 0 | AC6: 0 | AD6: 0
A7: 5 | B7: 吳嘉銘 | C7: =SUM(D7:AF7) -> 16 | F7: 0 | G7: 0 | H7: 0 | I7: 0 | J7: 0 | K7: 0 | M7: 0 | N7: 0 | O7: 0 | P7: 0 | Q7: 0 | T7: 16 | U7: 0 | V7: 0 | W7: 0 | X7: 0 | AA7: 0 | AB7: 0 | AC7: 0 | AD7: 0
A8: 6 | B8: 林詠書 | C8: =SUM(D8:AF8) -> 24 | F8: 0 | G8: 0 | H8: 0 | I8: 0 | J8: 0 | K8: 0 | M8: 0 | N8: 0 | O8: 16 | P8: 0 | Q8: 0 | T8: 0 | U8: 0 | V8: 0 | W8: 8 | X8: 0 | AA8: 0 | AB8: 0 | AC8: 0 | AD8: 0
A9: 7 | B9: 謝秉宏 | C9: =SUM(D9:AF9) -> 24 | F9: 0 | G9: 0 | H9: 0 | I9: 0 | J9: 16 | K9: 0 | M9: 0 | N9: 0 | O9: 0 | P9: 8 | Q9: 0 | T9: 0 | U9: 0 | V9: 0 | W9: 0 | X9: 0 | AA9: 0 | AB9: 0 | AC9: 0 | AD9: 0
A10: 8 | B10: 林建宏 | C10: =SUM(D10:AF10) -> 0 | F10: 0 | G10: 0 | H10: 0 | I10: 0 | J10: 0 | K10: 0 | M10: 0 | N10: 0 | O10: 0 | P10: 0 | Q10: 0 | T10: 0 | U10: 0 | V10: 0 | W10: 0 | X10: 0 | AA10: 0 | AB10: 0 | AC10: 0 | AD10: 0
A11: 9 | B11: 蘇景郁 | C11: =SUM(D11:AF11) -> 24 | F11: 0 | G11: 0 | H11: 0 | I11: 0 | J11: 0 | K11: 0 | M11: 0 | N11: 0 | O11: 0 | P11: 0 | Q11: 0 | T11: 0 | U11: 16 | V11: 0 | W11: 0 | X11: 0 | AA11: 8 | AB11: 0 | AC11: 0 | AD11: 0
A12: 10 | B12: 潘其昌 | C12: =SUM(D12:AF12) -> 16 | F12: 0 | G12: 0 | H12: 0 | I12: 0 | J12: 0 | K12: 0 | M12: 0 | N12: 16 | O12: 0 | P12: 0 | Q12: 0 | T12: 0 | U12: 0 | V12: 0 | W12: 0 | X12: 0 | AA12: 0 | AB12: 0 | AC12: 0 | AD12: 0
A13: 11 | B13: 陳俊男 | C13: =SUM(D13:AF13) -> 16 | F13: 0 | G13: 0 | H13: 0 | I13: 0 | J13: 0 | K13: 16 | M13: 0 | N13: 0 | O13: 0 | P13: 0 | Q13: 0 | T13: 0 | U13: 0 | V13: 0 | W13: 0 | X13: 0 | AA13: 0 | AB13: 0 | AC13: 0 | AD13: 0
A14: 12 | B14: 林政宏 | C14: =SUM(D14:AF14) -> 64 | F14: 0 | G14: 0 | H14: 0 | I14: 0 | J14: 0 | K14: 16 | M14: 0 | N14: 0 | O14: 0 | P14: 16 | Q14: 0 | T14: 16 | U14: 0 | V14: 0 | W14: 16 | X14: 0 | AA14: 0 | AB14: 0 | AC14: 0 | AD14: 0
... A18: 16 | B18: 李又誠 | C18: =SUM(D18:AF18) -> 16 | F18: 0 | G18: 0 | H18: 0 | I18: 0 | J18: 0 | K18: 0 | M18: 0 | N18: 0 | O18: 0 | P18: 0 | Q18: 16 | T18: 0 | U18: 0 | V18: 0 | W18: 0 | X18: 0 | AA18: 0 | AB18: 0 | AC18: 0 | AD18: 0

Sheet TP2月份加班
A1: TP加班 | C1: 二月累計 (0.5小時/單位) | D1: 45323 | E1: 45324 | F1: 45325 | G1: 45326 | H1: 45327 | I1: 45328 | J1: 45329 | K1: 45330 | L1: 45331 | M1: 45332 | N1: 45333 | O1: 45334 | P1: 45335 | Q1: 45336 | R1: 45337 | S1: 45338 | T1: 45339 | U1: 45340 | V1: 45341 | W1: 45342 | X1: 45343 | Y1: 45344 | Z1: 45345 | AA1: 45346 | AB1: 45347 | AC1: 45348 | AD1: 45349 | AE1: 45350
A2: NO. | B2: 姓名
A3: 1 | B3: 郭先弘 | C3: =SUM(D3:AF3) -> 0 | F3: 0 | G3: 0 | H3: 0 | I3: 0 | J3: 0 | K3: 0 | M3: 0 | N3: 0 | O3: 0 | P3: 0 | Q3: 0 | T3: 0 | U3: 0 | V3: 0 | W3: 0 | X3: 0 | AA3: 0 | AB3: 0 | AC3: 0 | AD3: 0
A4: 2 | B4: 陳淑芬 | C4: =SUM(D4:AF4) -> 0 | F4: 0 | G4: 0 | H4: 0 | I4: 0 | J4: 0 | K4: 0 | M4: 0 | N4: 0 | O4: 0 | P4: 0 | Q4: 0 | T4: 0 | U4: 0 | V4: 0 | W4: 0 | X4: 0 | AA4: 0 | AB4: 0 | AC4: 0 | AD4: 0
A5: 3 | B5: 林世彬 | C5: =SUM(D5:AF5) -> 8 | F5: 0 | G5: 0 | H5: 0 | I5: 0 | J5: 0 | K5: 0 | M5: 0 | N5: 0 | O5: 0 | P5: 0 | Q5: 0 | T5: 0 | U5: 0 | V5: 0 | W5: 0 | X5: 0 | Z5: 8 | AA5: 0 | AB5: 0 | AC5: 0 | AD5: 0
A6: 4 | B6: 何彥璋 | C6: =SUM(D6:AF6) -> 10 | F6: 0 | G6: 0 | H6: 0 | I6: 0 | J6: 5 | K6: 0 | M6: 0 | N6: 5 | O6: 0 | P6: 0 | Q6: 0 | T6: 0 | U6: 0 | V6: 0 | W6: 0 | X6: 0 | AA6: 0 | AB6: 0 | AC6: 0 | AD6: 0
A7: 5 | B7: 吳嘉銘 | C7: =SUM(D7:AF7) -> 16 | F7: 0 | G7: 0 | H7: 0 | I7: 0 | J7: 0 | K7: 0 | M7: 0 | N7: 8 | O7: 0 | P7: 8 | Q7: 0 | T7: 0 | U7: 0 | V7: 0 | W7: 0 | X7: 0 | AA7: 0 | AB7: 0 | AC7: 0 | AD7: 0
A8: 6 | B8: 林詠書 | C8: =SUM(D8:AF8) -> 12 | F8: 1 | G8: 1 | H8: 0 | I8: 0 | J8: 0 | K8: 0 | M8: 1 | N8: 1 | O8: 0 | P8: 1 | Q8: 1 | T8: 1 | U8: 1 | V8: 1 | W8: 0 | X8: 0 | AA8: 1 | AB8: 0 | AC8: 1 | AD8: 1
A9: 7 | B9: 謝秉宏 | C9: =SUM(D9:AF9) -> 0 | F9: 0 | G9: 0 | H9: 0 | I9: 0 | J9: 0 | K9: 0 | M9: 0 | N9: 0 | O9: 0 | P9: 0 | Q9: 0 | T9: 0 | U9: 0 | V9: 0 | W9: 0 | X9: 0 | AA9: 0 | AB9: 0 | AC9: 0 | AD9: 0
A10: 8 | B10: 林建宏 | C10: =SUM(D10:AF10) -> 0 | F10: 0 | G10: 0 | H10: 0 | I10: 0 | J10: 0 | K10: 0 | M10: 0 | N10: 0 | O10: 0 | P10: 0 | Q10: 0 | T10: 0 | U10: 0 | V10: 0 | W10: 0 | X10: 0 | AA10: 0 | AB10: 0 | AC10: 0 | AD10: 0
A11: 9 | B11: 蘇景郁 | C11: =SUM(D11:AF11) -> 0 | F11: 0 | G11: 0 | H11: 0 | I11: 0 | J11: 0 | K11: 0 | M11: 0 | N11: 0 | O11: 0 | P11: 0 | Q11: 0 | T11: 0 | U11: 0 | V11: 0 | W11: 0 | X11: 0 | AA11: 0 | AB11: 0 | AC11: 0 | AD11: 0
A12: 10 | B12: 潘其昌 | C12: =SUM(D12:AF12) -> 0 | F12: 0 | G12: 0 | H12: 0 | I12: 0 | J12: 0 | K12: 0 | M12: 0 | N12: 0 | O12: 0 | P12: 0 | Q12: 0 | T12: 0 | U12: 0 | V12: 0 | W12: 0 | X12: 0 | AA12: 0 | AB12: 0 | AC12: 0 | AD12: 0
A13: 11 | B13: 陳俊男 | C13: =SUM(D13:AF13) -> 0 | F13: 0 | G13: 0 | H13: 0 | I13: 0 | J13: 0 | K13: 0 | M13: 0 | N13: 0 | O13: 0 | P13: 0 | Q13: 0 | T13: 0 | U13: 0 | V13: 0 | W13: 0 | X13: 0 | AA13: 0 | AB13: 0 | AC13: 0 | AD13: 0
A14: 12 | B14: 林政宏 | C14: =SUM(D14:AF14) -> 18 | F14: 0 | G14: 0 | H14: 0 | I14: 0 | J14: 0 | K14: 0 | M14: 0 | N14: 0 | O14: 0 | P14: 0 | Q14: 0 | T14: 0 | U14: 0 | V14: 0 | W14: 0 | X14: 0 | AA14: 0 | AB14: 0 | AC14: 0 | AD14: 0 | AE14: 18
A15: 13 | B15: 劉益豪 | C15: =SUM(D15:AF15) -> 8 | F15: 4 | G15: 4 | H15: 0 | I15: 0 | J15: 0 | K15: 0 | M15: 0 | N15: 0 | O15: 0 | P15: 0 | Q15: 0 | T15: 0 | U15: 0 | V15: 0 | W15: 0 | X15: 0 | AA15: 0 | AB15: 0 | AC15: 0 | AD15: 0
A16: 14 | B16: 李威漢 | C16: =SUM(D16:AF16) -> 16 | F16: 0 | G16: 0 | H16: 0 | I16: 0 | J16: 0 | K16: 0 | M16: 0 | N16: 8 | O16: 0 | P16: 8 | Q16: 0 | T16: 0 | U16: 0 | V16: 0 | W16: 0 | X16: 0 | AA16: 0 | AB16: 0 | AC16: 0 | AD16: 0
A17: 15 | B17: 王挺翰 | C17: =SUM(D17:AF17) -> 25 | F17: 0 | G17: 0 | H17: 0 | I17: 0 | J17: 0 | K17: 0 | M17: 9 | N17: 8 | O17: 0 | P17: 8 | Q17: 0 | T17: 0 | U17: 0 | V17: 0 | W17: 0 | X17: 0 | AA17: 0 | AB17: 0 | AC17: 0 | AD17: 0
A18: 16 | B18: 李又誠 | C18: =SUM(D18:AF18) -> 25 | F18: 0 | G18: 0 | H18: 0 | I18: 0 | J18: 0 | K18: 0 | M18: 9 | N18: 8 | O18: 0 | P18: 8 | Q18: 0 | T18: 0 | U18: 0 | V18: 0 | W18: 0 | X18: 0 | AA18: 0 | AB18: 0 | AC18: 0 | AD18: 0

Sheet TP出勤3月份
A1: TP出勤 | C1: 45352 | D1: 45353 | E1: 45354 | F1: 45355 | G1: 45356 | H1: 45357 | I1: 45358 | J1: 45359 | K1: 45360 | L1: 45361 | M1: 45362 | N1: 45363 | O1: 45364 | P1: 45365 | Q1: 45366 | R1: 45367 | S1: 45368 | T1: 45369 | U1: 45370 | V1: 45371 | W1: 45372 | X1: 45373 | Y1: 45374 | Z1: 45375 | AA1: 45376 | AB1: 45377 | AC1: 45378 | AD1: 45379 | AE1: 45380 | AF1: 45381 | AG1: 45382
A2: NO. | B2: 姓名
