Workbook

Sheet 2024分析表
A1: TP出勤-請假 | C1: 總累計 (0.5小時/單位) | D1: 1月累計 (0.5小時/單位) | E1: 2月累計 (0.5小時/單位) | F1: 3月累計 (0.5小時/單位) | G1: 4月累計 (0.5小時/單位) | H1: 5月累計 (0.5小時/單位) | I1: 6月累計 (0.5小時/單位) | J1: 7月累計 (0.5小時/單位) | K1: 8月累計 (0.5小時/單位) | L1: 9月累計 (0.5小時/單位) | M1: 10月累計 (0.5小時/單位) | N1: 11月累計 (0.5小時/單位) | O1: 12月累計 (0.5小時/單位) | P1: 2024月份請假直條圖(1~10月)
A2: NO. | B2: 姓名
A3: 1 | B3: 郭先弘 | C3: =SUM(D3:O3) -> 0 | D3: =TP1月份請假!C3 -> 0 | E3: =TP2月份請假!C3 -> 0 | F3: =TP3月份請假!C3 -> 0 | G3: =TP4月份請假!C3 -> 0 | H3: =TP5月份請假!C3 -> 0 | I3: =TP6月份請假!C3 -> 0 | J3: =TP7月份請假!C3 -> 0 | K3: =TP8月份請假!C3 -> 0 | L3: =TP9月份請假!C3 -> 0 | M3: =TP10月份請假!C3 -> 0
A4: 2 | B4: 陳淑芬 | C4: =SUM(D4:O4) -> 151 | D4: =TP1月份請假!C4 -> 0 | E4: =TP2月份請假!C4 -> 23 | F4: =TP3月份請假!C4 -> 17 | G4: =TP4月份請假!C4 -> 8 | H4: =TP5月份請假!C4 -> 0 | I4: =TP6月份請假!C4 -> 16 | J4: =TP7月份請假!C4 -> 16 | K4: =TP8月份請假!C4 -> 7 | L4: =TP9月份請假!C4 -> 35 | M4: =TP10月份請假!C4 -> 29
A5: 3 | B5: 林世彬 | C5: =SUM(D5:O5) -> 156 | D5: =TP1月份請假!C5 -> 20 | E5: =TP2月份請假!C5 -> 9 | F5: =TP3月份請假!C5 -> 38 | G5: =TP4月份請假!C5 -> 32 | H5: =TP5月份請假!C5 -> 5 | I5: =TP6月份請假!C5 -> 0 | J5: =TP7月份請假!C5 -> 21 | K5: =TP8月份請假!C5 -> 9 | L5: =TP9月份請假!C5 -> 10 | M5: =TP10月份請假!C5 -> 12
A6: 4 | B6: 何彥璋 | C6: =SUM(D6:O6) -> 206 | D6: =TP1月份請假!C6 -> 16 | E6: =TP2月份請假!C6 -> 40 | F6: =TP3月份請假!C6 -> 32 | G6: =TP4月份請假!C6 -> 0 | H6: =TP5月份請假!C6 -> 16 | I6: =TP6月份請假!C6 -> 32 | J6: =TP7月份請假!C6 -> 16 | K6: =TP8月份請假!C6 -> 0 | L6: =TP9月份請假!C6 -> 22 | M6: =TP10月份請假!C6 -> 32
A7: 5 | B7: 吳嘉銘 | C7: =SUM(D7:O7) -> 157 | D7: =TP1月份請假!C7 -> 16 | E7: =TP2月份請假!C7 -> 21 | F7: =TP3月份請假!C7 -> 0 | G7: =TP4月份請假!C7 -> 32 | H7: =TP5月份請假!C7 -> 16 | I7: =TP6月份請假!C7 -> 16 | J7: =TP7月份請假!C7 -> 8 | K7: =TP8月份請假!C7 -> 16 | L7: =TP9月份請假!C7 -> 16 | M7: =TP10月份請假!C7 -> 16
A8: 6 | B8: 林詠書 | C8: =SUM(D8:O8) -> 219 | D8: =TP1月份請假!C8 -> 16 | E8: =TP2月份請假!C8 -> 8 | F8: =TP3月份請假!C8 -> 4 | G8: =TP4月份請假!C8 -> 0 | H8: =TP5月份請假!C8 -> 24 | I8: =TP6月份請假!C8 -> 39 | J8: =TP7月份請假!C8 -> 20 | K8: =TP8月份請假!C8 -> 24 | L8: =TP9月份請假!C8 -> 36 | M8: =TP10月份請假!C8 -> 48
A9: 7 | B9: 謝秉宏 | C9: =SUM(D9:O9) -> 292 | D9: =TP1月份請假!C9 -> 40 | E9: =TP2月份請假!C9 -> 46 | F9: =TP3月份請假!C9 -> 58 | G9: =TP4月份請假!C9 -> 5 | H9: =TP5月份請假!C9 -> 4 | I9: =TP6月份請假!C9 -> 33 | J9: =TP7月份請假!C9 -> 26 | K9: =TP8月份請假!C9 -> 48 | L9: =TP9月份請假!C9 -> 16 | M9: =TP10月份請假!C9 -> 16
A10: 8 | B10: 林建宏 | C10: =SUM(D10:O10) -> 100 | D10: =TP1月份請假!C10 -> 0 | E10: =TP2月份請假!C10 -> 56 | F10: =TP3月份請假!C10 -> 0 | G10: =TP4月份請假!C10 -> 0 | H10: =TP5月份請假!C10 -> 0 | I10: =TP6月份請假!C10 -> 16 | J10: =TP7月份請假!C10 -> 0 | K10: =TP8月份請假!C10 -> 24 | L10: =TP9月份請假!C10 -> 4 | M10: =TP10月份請假!C10 -> 0
A11: 9 | B11: 蘇景郁 | C11: =SUM(D11:O11) -> 199 | D11: =TP1月份請假!C11 -> 0 | E11: =TP2月份請假!C11 -> 32 | F11: =TP3月份請假!C11 -> 0 | G11: =TP4月份請假!C11 -> 39 | H11: =TP5月份請假!C11 -> 16 | I11: =TP6月份請假!C11 -> 32 | J11: =TP7月份請假!C11 -> 24 | K11: =TP8月份請假!C11 -> 0 | L11: =TP9月份請假!C11 -> 24 | M11: =TP10月份請假!C11 -> 32
A12: 10 | B12: 潘其昌 | C12: =SUM(D12:O12) -> 96 | D12: =TP1月份請假!C12 -> 16 | E12: =TP2月份請假!C12 -> 0 | F12: =TP3月份請假!C12 -> 32 | G12: =TP4月份請假!C12 -> 0 | H12: =TP5月份請假!C12 -> 16 | I12: =TP6月份請假!C12 -> 16 | J12: =TP7月份請假!C12 -> 0 | K12: =TP8月份請假!C12 -> 0 | L12: =TP9月份請假!C12 -> 0 | M12: =TP10月份請假!C12 -> 16
A13: 11 | B13: 陳俊男 | C13: =SUM(D13:O13) -> 282 | D13: =TP1月份請假!C13 -> 8 | E13: =TP2月份請假!C13 -> 93 | F13: =TP3月份請假!C13 -> 16 | G13: =TP4月份請假!C13 -> 22 | H13: =TP5月份請假!C13 -> 16 | I13: =TP6月份請假!C13 -> 0 | J13: =TP7月份請假!C13 -> 49 | K13: =TP8月份請假!C13 -> 32 | L13: =TP9月份請假!C13 -> 24 | M13: =TP10月份請假!C13 -> 22
A14: 12 | B14: 林政宏 | C14: =SUM(D14:O14) -> 166 | D14: =TP1月份請假!C14 -> 0 | E14: =TP2月份請假!C14 -> 32 | F14: =TP3月份請假!C14 -> 22 | G14: =TP4月份請假!C14 -> 16 | H14: =TP5月份請假!C14 -> 0 | I14: =TP6月份請假!C14 -> 48 | J14: =TP7月份請假!C14 -> 16 | K14: =TP8月份請假!C14 -> 16 | L14: =TP9月份請假!C14 -> 16 | M14: =TP10月份請假!C14 -> 0
A15: 13 | B15: 陸長遠 | C15: =SUM(D15:O15) -> 138 | D15: =TP1月份請假!C15 -> 8 | E15: =TP2月份請假!C15 -> 56 | F15: =TP3月份請假!C15 -> 8 | G15: =TP4月份請假!C15 -> 12 | H15: =TP5月份請假!C15 -> 22 | I15: =TP6月份請假!C15 -> 16 | J15: =TP7月份請假!C15 -> 16 | K15: =TP8月份請假!C15 -> 0 | L15: =TP9月份請假!C15 -> 0 | M15: =TP10月份請假!C15 -> 0
A16: 13 | B16: 劉益豪 | C16: =SUM(D16:O16) -> 182 | D16: =TP1月份請假!C16 -> 0 | E16: =TP2月份請假!C16 -> 40 | F16: =TP3月份請假!C16 -> 0 | G16: =TP4月份請假!C16 -> 33 | H16: =TP5月份請假!C16 -> 11 | I16: =TP6月份請假!C16 -> 21 | J16: =TP7月份請假!C16 -> 48 | K16: =TP8月份請假!C16 -> 0 | L16: =TP9月份請假!C16 -> 18 | M16: =TP10月份請假!C16 -> 11
A17: 14 | B17: 李威漢 | C17: =SUM(D17:O17) -> 0 | D17: =TP1月份請假!C17 -> 0 | E17: =TP2月份請假!C17 -> 0 | F17: =TP3月份請假!C17 -> 0 | G17: =TP4月份請假!C17 -> 0 | H17: =TP5月份請假!C17 -> 0 | I17: =TP6月份請假!C17 -> 0 | J17: =TP7月份請假!C17 -> 0 | K17: =TP8月份請假!C17 -> 0 | L17: =TP9月份請假!C17 -> 0 | M17: =TP10月份請假!C17 -> 0
A18: 15 | B18: 王挺翰 | C18: =SUM(D18:O18) -> 0 | D18: =TP1月份請假!C18 -> 0 | E18: =TP2月份請假!C18 -> 0 | F18: =TP3月份請假!C18 -> 0 | G18: =TP4月份請假!C18 -> 0 | H18: =TP5月份請假!C18 -> 0 | I18: =TP6月份請假!C18 -> 0 | J18: =TP7月份請假!C18 -> 0 | K18: =TP8月份請假!C18 -> 0 | L18: =TP9月份請假!C18 -> 0 | M18: =TP10月份請假!C18 -> 0
A20: TP出勤-加班 | C20: 總累計 (0.5小時/單位) | D20: 1月累計 (0.5小時/單位) | E20: 2月累計 (0.5小時/單位) | F20: 3月累計 (0.5小時/單位) | G20: 4月累計 (0.5小時/單位) | H20: 5月累計 (0.5小時/單位) | I20: 6月累計 (0.5小時/單位) | J20: 7月累計 (0.5小時/單位) | K20: 8月累計 (0.5小時/單位) | L20: 9月累計 (0.5小時/單位) | M20: 10月累計 (0.5小時/單位) | N20: 11月累計 (0.5小時/單位) | O20: 12月累計 (0.5小時/單位) | P20: 2024月份加班直條圖(1~10月)
A21: NO. | B21: 姓名
A22: 1 | B22: 郭先弘 | C22: =SUM(D22:O22) -> 0 | D22: =TP1月份加班!C3 -> 0 | E22: =TP2月份加班!C3 -> 0 | F22: =TP3月份加班!C3 -> 0 | G22: =TP4月份加班!C3 -> 0 | H22: =TP5月份加班!C3 -> 0 | I22: =TP6月份加班!C3 -> 0 | J22: =TP7月份加班!C3 -> 0 | K22: =TP8月份加班!C3 -> 0 | L22: =TP9月份加班!C3 -> 0 | M22: =TP10月份加班!C3 -> 0
A23: 2 | B23: 陳淑芬 | C23: =SUM(D23:O23) -> 50 | D23: =TP1月份加班!C4 -> 0 | E23: =TP2月份加班!C4 -> 0 | F23: =TP3月份加班!C4 -> 8 | G23: =TP4月份加班!C4 -> 5 | H23: =TP5月份加班!C4 -> 0 | I23: =TP6月份加班!C4 -> 8 | J23: =TP7月份加班!C4 -> 0 | K23: =TP8月份加班!C4 -> 29 | L23: =TP9月份加班!C4 -> 0 | M23: =TP10月份加班!C4 -> 0
A24: 3 | B24: 林世彬 | C24: =SUM(D24:O24) -> 62 | D24: =TP1月份加班!C5 -> 18 | E24: =TP2月份加班!C5 -> 0 | F24: =TP3月份加班!C5 -> 13 | G24: =TP4月份加班!C5 -> 0 | H24: =TP5月份加班!C5 -> 24 | I24: =TP6月份加班!C5 -> 1 | J24: =TP7月份加班!C5 -> 0 | K24: =TP8月份加班!C5 -> 6 | L24: =TP9月份加班!C5 -> 0 | M24: =TP10月份加班!C5 -> 0
A25: 4 | B25: 何彥璋 | C25: =SUM(D25:O25) -> 93 | D25: =TP1月份加班!C6 -> 6 | E25: =TP2月份加班!C6 -> 0 | F25: =TP3月份加班!C6 -> 23 | G25: =TP4月份加班!C6 -> 11 | H25: =TP5月份加班!C6 -> 0 | I25: =TP6月份加班!C6 -> 11 | J25: =TP7月份加班!C6 -> 1 | K25: =TP8月份加班!C6 -> 20 | L25: =TP9月份加班!C6 -> 11 | M25: =TP10月份加班!C6 -> 10
A26: 5 | B26: 吳嘉銘 | C26: =SUM(D26:O26) -> 47 | D26: =TP1月份加班!C7 -> 9 | E26: =TP2月份加班!C7 -> 0 | F26: =TP3月份加班!C7 -> 16 | G26: =TP4月份加班!C7 -> 5 | H26: =TP5月份加班!C7 -> 0 | I26: =TP6月份加班!C7 -> 0 | J26: =TP7月份加班!C7 -> 1 | K26: =TP8月份加班!C7 -> 6 | L26: =TP9月份加班!C7 -> 2 | M26: =TP10月份加班!C7 -> 8
A27: 6 | B27: 林詠書 | C27: =SUM(D27:O27) -> 205 | D27: =TP1月份加班!C8 -> 33 | E27: =TP2月份加班!C8 -> 12 | F27: =TP3月份加班!C8 -> 38 | G27: =TP4月份加班!C8 -> 19 | H27: =TP5月份加班!C8 -> 24 | I27: =TP6月份加班!C8 -> 21 | J27: =TP7月份加班!C8 -> 17 | K27: =TP8月份加班!C8 -> 15 | L27: =TP9月份加班!C8 -> 6 | M27: =TP10月份加班!C8 -> 20
A28: 7 | B28: 謝秉宏 | C28: =SUM(D28:O28) -> 241 | D28: =TP1月份加班!C9 -> 34 | E28: =TP2月份加班!C9 -> 37 | F28: =TP3月份加班!C9 -> 47 | G28: =TP4月份加班!C9 -> 23 | H28: =TP5月份加班!C9 -> 8 | I28: =TP6月份加班!C9 -> 21 | J28: =TP7月份加班!C9 -> 15 | K28: =TP8月份加班!C9 -> 28 | L28: =TP9月份加班!C9 -> 17 | M28: =TP10月份加班!C9 -> 11
A29: 8 | B29: 林建宏 | C29: =SUM(D29:O29) -> 23 | D29: =TP1月份加班!C10 -> 6 | E29: =TP2月份加班!C10 -> 0 | F29: =TP3月份加班!C10 -> 0 | G29: =TP4月份加班!C10 -> 11 | H29: =TP5月份加班!C10 -> 0 | I29: =TP6月份加班!C10 -> 6 | J29: =TP7月份加班!C10 -> 0 | K29: =TP8月份加班!C10 -> 0 | L29: =TP9月份加班!C10 -> 0 | M29: =TP10月份加班!C10 -> 0
A30: 9 | B30: 蘇景郁 | C30: =SUM(D30:O30) -> 155 | D30: =TP1月份加班!C11 -> 6 | E30: =TP2月份加班!C11 -> 1 | F30: =TP3月份加班!C11 -> 16 | G30: =TP4月份加班!C11 -> 8 | H30: =TP5月份加班!C11 -> 12 | I30: =TP6月份加班!C11 -> 14 | J30: =TP7月份加班!C11 -> 0 | K30: =TP8月份加班!C11 -> 93 | L30: =TP9月份加班!C11 -> 3 | M30: =TP10月份加班!C11 -> 2
A31: 10 | B31: 潘其昌 | C31: =SUM(D31:O31) -> 50 | D31: =TP1月份加班!C12 -> 6 | E31: =TP2月份加班!C12 -> 0 | F31: =TP3月份加班!C12 -> 16 | G31: =TP4月份加班!C12 -> 22 | H31: =TP5月份加班!C12 -> 0 | I31: =TP6月份加班!C12 -> 0 | J31: =TP7月份加班!C12 -> 0 | K31: =TP8月份加班!C12 -> 2 | L31: =TP9月份加班!C12 -> 4 | M31: =TP10月份加班!C12 -> 0
A32: 11 | B32: 陳俊男 | C32: =SUM(D32:O32) -> 227 | D32: =TP1月份加班!C13 -> 25 | E32: =TP2月份加班!C13 -> 0 | F32: =TP3月份加班!C13 -> 0 | G32: =TP4月份加班!C13 -> 60 | H32: =TP5月份加班!C13 -> 55 | I32: =TP6月份加班!C13 -> 71 | J32: =TP7月份加班!C13 -> 16 | K32: =TP8月份加班!C13 -> 0 | L32: =TP9月份加班!C13 -> 0 | M32: =TP10月份加班!C13 -> 0
A33: 12 | B33: 林政宏 | C33: =SUM(D33:O33) -> 268 | D33: =TP1月份加班!C14 -> 44 | E33: =TP2月份加班!C14 -> 32 | F33: =TP3月份加班!C14 -> 33 | G33: =TP4月份加班!C14 -> 18 | H33: =TP5月份加班!C14 -> 43 | I33: =TP6月份加班!C14 -> 66 | J33: =TP7月份加班!C14 -> 32 | K33: =TP8月份加班!C14 -> 0 | L33: =TP9月份加班!C14 -> 0 | M33: =TP10月份加班!C14 -> 0
A34: 13 | B34: 劉益豪 | C34: =SUM(D34:O34) -> 227 | D34: =TP1月份加班!C16 -> 30 | E34: =TP2月份加班!C16 -> 12 | F34: =TP3月份加班!C16 -> 34 | G34: =TP4月份加班!C16 -> 22 | H34: =TP5月份加班!C16 -> 4 | I34: =TP6月份加班!C16 -> 7 | J34: =TP7月份加班!C16 -> 0 | K34: =TP8月份加班!C16 -> 85 | L34: =TP9月份加班!C16 -> 33 | M34: =TP10月份加班!C16 -> 0
A35: 14 | B35: 李威漢 | C35: =SUM(D35:O35) -> 10 | D35: =TP1月份加班!C17 -> 0 | E35: =TP2月份加班!C17 -> 0 | F35: =TP3月份加班!C17 -> 0 | G35: =TP4月份加班!C17 -> 0 | H35: =TP5月份加班!C17 -> 0 | I35: =TP6月份加班!C17 -> 0 | J35: =TP7月份加班!C17 -> 0 | K35: =TP8月份加班!C17 -> 0 | L35: =TP9月份加班!C17 -> 0 | M35: =TP10月份加班!C17 -> 10
A36: 15 | B36: 王挺翰 | C36: =SUM(D36:O36) -> 6 | D36: =TP1月份加班!C18 -> 0 | E36: =TP2月份加班!C18 -> 0 | F36: =TP3月份加班!C18 -> 0 | G36: =TP4月份加班!C18 -> 0 | H36: =TP5月份加班!C18 -> 0 | I36: =TP6月份加班!C18 -> 0 | J36: =TP7月份加班!C18 -> 0 | K36: =TP8月份加班!C18 -> 0 | L36: =TP9月份加班!C18 -> 0 | M36: =TP10月份加班!C18 -> 6
A38: TP出勤-加班減請假 | C38: 總累計 (0.5小時/單位) | D38: 1月累計 (0.5小時/單位) | E38: 2月累計 (0.5小時/單位) | F38: 3月累計 (0.5小時/單位) | G38: 4月累計 (0.5小時/單位) | H38: 5月累計 (0.5小時/單位) | I38: 6月累計 (0.5小時/單位) | J38: 7月累計 (0.5小時/單位) | K38: 8月累計 (0.5小時/單位) | L38: 9月累計 (0.5小時/單位) | M38: 10月累計 (0.5小時/單位) | N38: 11月累計 (0.5小時/單位) | O38: 12月累計 (0.5小時/單位) | P38: 2024月份加班減請假直條圖(1~10月)
A39: NO. | B39: 姓名
A40: 1 | B40: 郭先弘 | C40: =SUM(D40:O40) -> 0 | D40: ='TP加班累計-請假總合_2024'!C3 -> 0 | E40: ='TP加班累計-請假總合_2024'!D3 -> 0 | F40: ='TP加班累計-請假總合_2024'!E3 -> 0 | G40: ='TP加班累計-請假總合_2024'!F3 -> 0 | H40: ='TP加班累計-請假總合_2024'!G3 -> 0 | I40: ='TP加班累計-請假總合_2024'!H3 -> 0 | J40: ='TP加班累計-請假總合_2024'!I3 -> 0 | K40: ='TP加班累計-請假總合_2024'!J3 -> 0 | ... M40: ='TP加班累計-請假總合_2024'!L3 -> 0
A41: 2 | B41: 陳淑芬 | C41: =SUM(D41:O41) -> -101 | D41: ='TP加班累計-請假總合_2024'!C4 -> 0 | E41: ='TP加班累計-請假總合_2024'!D4 -> -23 | F41: ='TP加班累計-請假總合_2024'!E4 -> -9 | G41: ='TP加班累計-請假總合_2024'!F4 -> -3 | H41: ='TP加班累計-請假總合_2024'!G4 -> 0 | I41: ='TP加班累計-請假總合_2024'!H4 -> -8 | J41: ='TP加班累計-請假總合_2024'!I4 -> -16 | K41: ='TP加班累計-請假總合_2024'!J4 -> 22 | ... M41: ='TP加班累計-請假總合_2024'!L4 -> -29
A42: 3 | B42: 林世彬 | C42: =SUM(D42:O42) -> -94 | D42: ='TP加班累計-請假總合_2024'!C5 -> -2 | E42: ='TP加班累計-請假總合_2024'!D5 -> -9 | F42: ='TP加班累計-請假總合_2024'!E5 -> -25 | G42: ='TP加班累計-請假總合_2024'!F5 -> -32 | H42: ='TP加班累計-請假總合_2024'!G5 -> 19 | I42: ='TP加班累計-請假總合_2024'!H5 -> 1 | J42: ='TP加班累計-請假總合_2024'!I5 -> -21 | K42: ='TP加班累計-請假總合_2024'!J5 -> -3 | ... M42: ='TP加班累計-請假總合_2024'!L5 -> -12
...

Sheet TP加班累計-請假總合_2024
A1: TP(加班-請假) | C1: 2024一月累計單位 (0.5小時/單位) | D1: 2024二月累計單位 (0.5小時/單位) | E1: 2024三月累計單位 (0.5小時/單位) | F1: 四月累計單位 (0.5小時/單位) | G1: 五月累計單位 (0.5小時/單位) | H1: 六月累計單位 (0.5小時/單位) | I1: 七月累計單位 (0.5小時/單位) | J1: 八月累計單位 (0.5小時/單位) | K1: 九月累計單位 (0.5小時/單位) | L1: 十月累計單位 (0.5小時/單位) | M1: 十一月累計單位 (0.5小時/單位) | N1: 十二月累計單位 (0.5小時/單位) | O1: 2024總累計單位 (0.5小時/單位)
A2: NO. | B2: 姓名
A3: 1 | B3: 郭先弘 | C3: =TP1月份加班!C3-TP1月份請假!C3 -> 0 | D3: =TP2月份加班!C3-TP2月份請假!C3 -> 0 | E3: =TP3月份加班!C3-TP3月份請假!C3 -> 0 | F3: =TP4月份加班!C3-TP4月份請假!C3 -> 0 | G3: =TP5月份加班!C3-TP5月份請假!C3 -> 0 | H3: =TP6月份加班!C3-TP6月份請假!C3 -> 0 | I3: =TP7月份加班!C3-TP7月份請假!C3 -> 0 | J3: =TP8月份加班!C3-TP8月份請假!C3 -> 0 | K3: =TP9月份加班!C3-TP9月份請假!C3 -> 0 | L3: =TP10月份加班!C3-TP10月份請假!C3 -> 0 | M3: =TP11月份加班!C3-TP11月份請假!C3 -> 0 | N3: =TP12月份加班!C3-TP12月份請假!C3 -> 0 | O3: =SUM(C3:N3) -> 0
A4: 2 | B4: 陳淑芬 | C4: =TP1月份加班!C4-TP1月份請假!C4 -> 0 | D4: =TP2月份加班!C4-TP2月份請假!C4 -> -23 | E4: =TP3月份加班!C4-TP3月份請假!C4 -> -9 | F4: =TP4月份加班!C4-TP4月份請假!C4 -> -3 | G4: =TP5月份加班!C4-TP5月份請假!C4 -> 0 | H4: =TP6月份加班!C4-TP6月份請假!C4 -> -8 | I4: =TP7月份加班!C4-TP7月份請假!C4 -> -16 | J4: =TP8月份加班!C4-TP8月份請假!C4 -> 22 | K4: =TP9月份加班!C4-TP9月份請假!C4 -> -35 | L4: =TP10月份加班!C4-TP10月份請假!C4 -> -29 | M4: =TP11月份加班!C4-TP11月份請假!C4 -> -11 | N4: =TP12月份加班!C4-TP12月份請假!C4 -> -26 | O4: =SUM(C4:N4) -> -138
A5: 3 | B5: 林世彬 | C5: =TP1月份加班!C5-TP1月份請假!C5 -> -2 | D5: =TP2月份加班!C5-TP2月份請假!C5 -> -9 | E5: =TP3月份加班!C5-TP3月份請假!C5 -> -25 | F5: =TP4月份加班!C5-TP4月份請假!C5 -> -32 | G5: =TP5月份加班!C5-TP5月份請假!C5 -> 19 | H5: =TP6月份加班!C5-TP6月份請假!C5 -> 1 | I5: =TP7月份加班!C5-TP7月份請假!C5 -> -21 | J5: =TP8月份加班!C5-TP8月份請假!C5 -> -3 | K5: =TP9月份加班!C5-TP9月份請假!C5 -> -10 | L5: =TP10月份加班!C5-TP10月份請假!C5 -> -12 | M5: =TP11月份加班!C5-TP11月份請假!C5 -> 0 | N5: =TP12月份加班!C5-TP12月份請假!C5 -> -6 | O5: =SUM(C5:N5) -> -100
A6: 4 | B6: 何彥璋 | C6: =TP1月份加班!C6-TP1月份請假!C6 -> -10 | D6: =TP2月份加班!C6-TP2月份請假!C6 -> -40 | E6: =TP3月份加班!C6-TP3月份請假!C6 -> -9 | F6: =TP4月份加班!C6-TP4月份請假!C6 -> 11 | G6: =TP5月份加班!C6-TP5月份請假!C6 -> -16 | H6: =TP6月份加班!C6-TP6月份請假!C6 -> -21 | I6: =TP7月份加班!C6-TP7月份請假!C6 -> -15 | J6: =TP8月份加班!C6-TP8月份請假!C6 -> 20 | K6: =TP9月份加班!C6-TP9月份請假!C6 -> -11 | L6: =TP10月份加班!C6-TP10月份請假!C6 -> -22 | M6: =TP11月份加班!C6-TP11月份請假!C6 -> 18 | N6: =TP12月份加班!C6-TP12月份請假!C6 -> 18 | O6: =SUM(C6:N6) -> -77
A7: 5 | B7: 吳嘉銘 | C7: =TP1月份加班!C7-TP1月份請假!C7 -> -7 | D7: =TP2月份加班!C7-TP2月份請假!C7 -> -21 | E7: =TP3月份加班!C7-TP3月份請假!C7 -> 16 | F7: =TP4月份加班!C7-TP4月份請假!C7 -> -27 | G7: =TP5月份加班!C7-TP5月份請假!C7 -> -16 | H7: =TP6月份加班!C7-TP6月份請假!C7 -> -16 | I7: =TP7月份加班!C7-TP7月份請假!C7 -> -7 | J7: =TP8月份加班!C7-TP8月份請假!C7 -> -10 | K7: =TP9月份加班!C7-TP9月份請假!C7 -> -14 | L7: =TP10月份加班!C7-TP10月份請假!C7 -> -8 | M7: =TP11月份加班!C7-TP11月份請假!C7 -> 8 | N7: =TP12月份加班!C7-TP12月份請假!C7 -> -15 | O7: =SUM(C7:N7) -> -117 | S7: `
A8: 6 | B8: 林詠書 | C8: =TP1月份加班!C8-TP1月份請假!C8 -> 17 | D8: =TP2月份加班!C8-TP2月份請假!C8 -> 4 | E8: =TP3月份加班!C8-TP3月份請假!C8 -> 34 | F8: =TP4月份加班!C8-TP4月份請假!C8 -> 19 | G8: =TP5月份加班!C8-TP5月份請假!C8 -> 0 | H8: =TP6月份加班!C8-TP6月份請假!C8 -> -18 | I8: =TP7月份加班!C8-TP7月份請假!C8 -> -3 | J8: =TP8月份加班!C8-TP8月份請假!C8 -> -9 | K8: =TP9月份加班!C8-TP9月份請假!C8 -> -30 | L8: =TP10月份加班!C8-TP10月份請假!C8 -> -28 | M8: =TP11月份加班!C8-TP11月份請假!C8 -> -14 | N8: =TP12月份加班!C8-TP12月份請假!C8 -> -34 | O8: =SUM(C8:N8) -> -62
A9: 7 | B9: 謝秉宏 | C9: =TP1月份加班!C9-TP1月份請假!C9 -> -6 | D9: =TP2月份加班!C9-TP2月份請假!C9 -> -9 | E9: =TP3月份加班!C9-TP3月份請假!C9 -> -11 | F9: =TP4月份加班!C9-TP4月份請假!C9 -> 18 | G9: =TP5月份加班!C9-TP5月份請假!C9 -> 4 | H9: =TP6月份加班!C9-TP6月份請假!C9 -> -12 | I9: =TP7月份加班!C9-TP7月份請假!C9 -> -11 | J9: =TP8月份加班!C9-TP8月份請假!C9 -> -20 | K9: =TP9月份加班!C9-TP9月份請假!C9 -> 1 | L9: =TP10月份加班!C9-TP10月份請假!C9 -> -5 | M9: =TP11月份加班!C9-TP11月份請假!C9 -> 25 | N9: =TP12月份加班!C9-TP12月份請假!C9 -> -7 | O9: =SUM(C9:N9) -> -33
A10: 8 | B10: 林建宏 | C10: =TP1月份加班!C10-TP1月份請假!C10 -> 6 | D10: =TP2月份加班!C10-TP2月份請假!C10 -> -56 | E10: =TP3月份加班!C10-TP3月份請假!C10 -> 0 | F10: =TP4月份加班!C10-TP4月份請假!C10 -> 11 | G10: =TP5月份加班!C10-TP5月份請假!C10 -> 0 | H10: =TP6月份加班!C10-TP6月份請假!C10 -> -10 | I10: =TP7月份加班!C10-TP7月份請假!C10 -> 0 | J10: =TP8月份加班!C10-TP8月份請假!C10 -> -24 | K10: =TP9月份加班!C10-TP9月份請假!C10 -> -4 | L10: =TP10月份加班!C10-TP10月份請假!C10 -> 0 | M10: =TP11月份加班!C10-TP11月份請假!C10 -> -8 | N10: =TP12月份加班!C10-TP12月份請假!C10 -> -16 | O10: =SUM(C10:N10) -> -101
A11: 9 | B11: 蘇景郁 | C11: =TP1月份加班!C11-TP1月份請假!C11 -> 6 | D11: =TP2月份加班!C11-TP2月份請假!C11 -> -31 | E11: =TP3月份加班!C11-TP3月份請假!C11 -> 16 | F11: =TP4月份加班!C11-TP4月份請假!C11 -> -31 | G11: =TP5月份加班!C11-TP5月份請假!C11 -> -4 | H11: =TP6月份加班!C11-TP6月份請假!C11 -> -18 | I11: =TP7月份加班!C11-TP7月份請假!C11 -> -24 | J11: =TP8月份加班!C11-TP8月份請假!C11 -> 93 | K11: =TP9月份加班!C11-TP9月份請假!C11 -> -21 | L11: =TP10月份加班!C11-TP10月份請假!C11 -> -30 | M11: =TP11月份加班!C11-TP11月份請假!C11 -> -16 | N11: =TP12月份加班!C11-TP12月份請假!C11 -> -33 | O11: =SUM(C11:N11) -> -93
A12: 10 | B12: 潘其昌 | C12: =TP1月份加班!C12-TP1月份請假!C12 -> -10 | D12: =TP2月份加班!C12-TP2月份請假!C12 -> 0 | E12: =TP3月份加班!C12-TP3月份請假!C12 -> -16 | F12: =TP4月份加班!C12-TP4月份請假!C12 -> 22 | G12: =TP5月份加班!C12-TP5月份請假!C12 -> -16 | H12: =TP6月份加班!C12-TP6月份請假!C12 -> -16 | I12: =TP7月份加班!C12-TP7月份請假!C12 -> 0 | J12: =TP8月份加班!C12-TP8月份請假!C12 -> 2 | K12: =TP9月份加班!C12-TP9月份請假!C12 -> 4 | L12: =TP10月份加班!C12-TP10月份請假!C12 -> -16 | M12: =TP11月份加班!C12-TP11月份請假!C12 -> 15 | N12: =TP12月份加班!C12-TP12月份請假!C12 -> -29 | O12: =SUM(C12:N12) -> -60
A13: 11 | B13: 陳俊男 | C13: =TP1月份加班!C13-TP1月份請假!C13 -> 17 | D13: =TP2月份加班!C13-TP2月份請假!C13 -> -93 | E13: =TP3月份加班!C13-TP3月份請假!C13 -> -16 | F13: =TP4月份加班!C13-TP4月份請假!C13 -> 38 | G13: =TP5月份加班!C13-TP5月份請假!C13 -> 39 | H13: =TP6月份加班!C13-TP6月份請假!C13 -> 71 | I13: =TP7月份加班!C13-TP7月份請假!C13 -> -33 | J13: =TP8月份加班!C13-TP8月份請假!C13 -> -32 | K13: =TP9月份加班!C13-TP9月份請假!C13 -> -24 | L13: =TP10月份加班!C13-TP10月份請假!C13 -> -22 | M13: =TP11月份加班!C13-TP11月份請假!C13 -> -18 | N13: =TP12月份加班!C13-TP12月份請假!C13 -> -16 | O13: =SUM(C13:N13) -> -89
A14: 12 | B14: 林政宏 | C14: =TP1月份加班!C14-TP1月份請假!C14 -> 44 | D14: =TP2月份加班!C14-TP2月份請假!C14 -> 0 | E14: =TP3月份加班!C14-TP3月份請假!C14 -> 11 | F14: =TP4月份加班!C14-TP4月份請假!C14 -> 2 | G14: =TP5月份加班!C14-TP5月份請假!C14 -> 43 | H14: =TP6月份加班!C14-TP6月份請假!C14 -> 18 | I14: =TP7月份加班!C14-TP7月份請假!C14 -> 16 | J14: =TP8月份加班!C14-TP8月份請假!C14 -> -16 | K14: =TP9月份加班!C14-TP9月份請假!C14 -> -16 | L14: =TP10月份加班!C14-TP10月份請假!C14 -> 0 | M14: =TP11月份加班!C14-TP11月份請假!C14 -> 15 | N14: =TP12月份加班!C14-TP12月份請假!C14 -> -128 | O14: =SUM(C14:N14) -> -11
A15: 13 | B15: 陸長遠 | C15: =TP1月份加班!C15-TP1月份請假!C15 -> 5 | D15: =TP2月份加班!C15-TP2月份請假!C15 -> -48 | E15: =TP3月份加班!C15-TP3月份請假!C15 -> 23 | F15: =TP4月份加班!C15-TP4月份請假!C15 -> -9 | G15: =TP5月份加班!C15-TP5月份請假!C15 -> -22 | H15: =TP6月份加班!C15-TP6月份請假!C15 -> -16 | I15: =TP7月份加班!C15-TP7月份請假!C15 -> -16 | J15: =TP8月份加班!C15-TP8月份請假!C15 -> 0 | K15: =TP9月份加班!C15-TP9月份請假!C15 -> 0 | L15: =TP10月份加班!C15-TP10月份請假!C15 -> 0 | M15: =TP11月份加班!C15-TP11月份請假!C15 -> 0 | N15: =TP12月份加班!C15-TP12月份請假!C15 -> 0 | O15: =SUM(C15:N15) -> -83
A16: 13 | B16: 劉益豪 | C16: =TP1月份加班!C16-TP1月份請假!C16 -> 30 | D16: =TP2月份加班!C16-TP2月份請假!C16 -> -28 | E16: =TP3月份加班!C16-TP3月份請假!C16 -> 34 | F16: =TP4月份加班!C16-TP4月份請假!C16 -> -11 | G16: =TP5月份加班!C16-TP5月份請假!C16 -> -7 | H16: =TP6月份加班!C16-TP6月份請假!C16 -> -14 | I16: =TP7月份加班!C16-TP7月份請假!C16 -> -48 | J16: =TP8月份加班!C16-TP8月份請假!C16 -> 85 | K16: =TP9月份加班!C16-TP9月份請假!C16 -> 15 | L16: =TP10月份加班!C16-TP10月份請假!C16 -> -11 | M16: =TP11月份加班!C16-TP11月份請假!C16 -> 0 | N16: =TP12月份加班!C16-TP12月份請假!C16 -> -42 | O16: =SUM(C16:N16) -> 3
A17: 14 | B17: 李威漢 | K17: =TP9月份加班!C17-TP9月份請假!C17 -> 0 | L17: =TP10月份加班!C17-TP10月份請假!C17 -> 10 | M17: =TP11月份加班!C17-TP11月份請假!C17 -> -8 | N17: =TP12月份加班!C17-TP12月份請假!C17 -> -15 | O17: =SUM(C17:N17) -> -13
A18: 15 | B18: 王挺翰 | L18: =TP10月份加班!C17-TP10月份請假!C17 -> 10 | M18: =TP11月份加班!C18-TP11月份請假!C18 -> 6 | N18: =TP12月份加班!C18-TP12月份請假!C18 -> -7 | O18: =SUM(C18:N18) -> 9
A19: 16 | B19: 李又誠 | M19: =TP11月份加班!C19-TP11月份請假!C19 -> 0 | N19: =TP12月份加班!C19-TP12月份請假!C19 -> 17 | O19: =SUM(C19:N19) -> 17
A20: 1.紅字代表請假單位大於加班單位

Sheet TP加班-請假總合累計_2023+2024
A1: TP(加班-請假) | C1: 2023+2024總累計單位 (0.5小時/單位)
A2: NO. | B2: 姓名
A3: 1 | B3: 郭先弘 | C3: ='TP加班累計-請假總合_2023'!C3+'TP加班累計-請假總合_2024'!O3 -> 2
A4: 2 | B4: 陳淑芬 | C4: ='TP加班累計-請假總合_2023'!C4+'TP加班累計-請假總合_2024'!O4 -> 17 | D4: 17
A5: 3 | B5: 林世彬 | C5: ='TP加班累計-請假總合_2023'!C5+'TP加班累計-請假總合_2024'!O5 -> -53 | D5: -53
A6: 4 | B6: 何彥璋 | C6: ='TP加班累計-請假總合_2023'!C6+'TP加班累計-請假總合_2024'!O6 -> -3 | D6: -3
A7: 5 | B7: 吳嘉銘 | C7: ='TP加班累計-請假總合_2023'!C7+'TP加班累計-請假總合_2024'!O7 -> -24 | D7: -24 | G7: `
A8: 6 | B8: 林詠書 | C8: ='TP加班累計-請假總合_2023'!C8+'TP加班累計-請假總合_2024'!O8 -> 100 | D8: 100
A9: 7 | B9: 謝秉宏 | C9: ='TP加班累計-請假總合_2023'!C9+'TP加班累計-請假總合_2024'!O9 -> 6 | D9: 6
A10: 8 | B10: 林建宏 | C10: ='TP加班累計-請假總合_2023'!C10+'TP加班累計-請假總合_2024'!O10 -> 10 | D10: 10
A11: 9 | B11: 蘇景郁 | C11: ='TP加班累計-請假總合_2023'!C11+'TP加班累計-請假總合_2024'!O11 -> -46 | D11: -46
A12: 10 | B12: 潘其昌 | C12: ='TP加班累計-請假總合_2023'!C12+'TP加班累計-請假總合_2024'!O12 -> 18 | D12: 18
A13: 11 | B13: 陳俊男 | C13: ='TP加班累計-請假總合_2023'!C13+'TP加班累計-請假總合_2024'!O13 -> 24 | D13: 24
A14: 12 | B14: 林政宏 | C14: ='TP加班累計-請假總合_2023'!C14+'TP加班累計-請假總合_2024'!O14 -> 329 | D14: 112
A15: 13 | B15: 陸長遠 | C15: ='TP加班累計-請假總合_2023'!C15+'TP加班累計-請假總合_2024'!O15 -> -21
A16: 13 | B16: 劉益豪 | C16: ='TP加班累計-請假總合_2023'!C16+'TP加班累計-請假總合_2024'!O16 -> 67 | D16: 67
A17: 14 | B17: 李威漢 | C17: ='TP加班累計-請假總合_2023'!C17+'TP加班累計-請假總合_2024'!O17 -> -13 | D17: -13
A18: 15 | B18: 王挺翰 | C18: ='TP加班累計-請假總合_2023'!C18+'TP加班累計-請假總合_2024'!O18 -> 9 | D18: 9
A19: 16 | B19: 李又誠 | C19: ='TP加班累計-請假總合_2023'!C19+'TP加班累計-請假總合_2024'!O19 -> 17 | D19: 17
A20: 1.紅字代表請假單位大於加班單位

Sheet TP加班累計-請假總合_2023
A1: TP(加班-請假) | C1: 2023總累計單位 (0.5小時/單位)
A2: NO. | B2: 姓名
A3: 1 | B3: 郭先弘 | C3: 2
A4: 2 | B4: 陳淑芬 | C4: 155
A5: 3 | B5: 林世彬 | C5: 47
A6: 4 | B6: 何彥璋 | C6: 74
A7: 5 | B7: 吳嘉銘 | C7: 93 | G7: `
A8: 6 | B8: 林詠書 | C8: 162
A9: 7 | B9: 謝秉宏 | C9: 39
A10: 8 | B10: 林建宏 | C10: 111
A11: 9 | B11: 蘇景郁 | C11: 47
A12: 10 | B12: 潘其昌 | C12: 78
A13: 11 | B13: 陳俊男 | C13: 113
A14: 12 | B14: 林政宏 | C14: 340
A15: 13 | B15: 陸長遠 | C15: 62
A16: 14 | B16: 劉益豪 | C16: 64
A17: 1.紅字代表請假單位大於加班單位

Sheet TP1月份請假
A1: TP請假 | C1: 一月累計 (0.5小時/單位) | D1: 45292 | E1: 45293 | F1: 45294 | G1: 45295 | H1: 45296 | I1: 45297 | J1: 45298 | K1: 45299 | L1: 45300 | M1: 45301 | N1: 45302 | O1: 45303 | P1: 45304 | Q1: 45305 | R1: 45306 | S1: 45307 | T1: 45308 | U1: 45309 | V1: 45310 | W1: 45311 | X1: 45312 | Y1: 45313 | Z1: 45314 | AA1: 45315 | AB1: 45316 | AC1: 45317 | AD1: 45318 | AE1: 45319 | AF1: 45320 | AG1: 45321 | AH1: 45322
A2: NO. | B2: 姓名
A3: 1 | B3: 郭先弘 | C3: =SUM(D3:AH3) -> 0 | D3: 0 | E3: 0 | F3: 0 | G3: 0 | H3: 0 | K3: 0 | L3: 0 | M3: 0 | N3: 0 | O3: 0 | R3: 0 | S3: 0 | T3: 0 | U3: 0 | V3: 0 | Y3: 0 | Z3: 0 | AA3: 0 | AB3: 0 | AC3: 0 | AF3: 0 | AG3: 0 | AH3: 0
A4: 2 | B4: 陳淑芬 | C4: =SUM(D4:AH4) -> 0 | D4: 0 | E4: 0 | F4: 0 | G4: 0 | H4: 0 | K4: 0 | L4: 0 | M4: 0 | N4: 0 | O4: 0 | R4: 0 | S4: 0 | T4: 0 | U4: 0 | V4: 0 | Y4: 0 | Z4: 0 | AA4: 0 | AB4: 0 | AC4: 0 | AF4: 0 | AG4: 0 | AH4: 0
A5: 3 | B5: 林世彬 | C5: =SUM(D5:AH5) -> 20 | D5: 0 | E5: 0 | F5: 0 | G5: 0 | H5: 0 | K5: 6 | L5: 0 | M5: 0 | N5: 0 | O5: 0 | R5: 0 | S5: 8 | T5: 0 | U5: 0 | V5: 0 | Y5: 0 | Z5: 0 | AA5: 0 | AB5: 6 | AC5: 0 | AF5: 0 | AG5: 0 | AH5: 0
A6: 4 | B6: 何彥璋 | C6: =SUM(D6:AH6) -> 16 | D6: 0 | E6: 16 | F6: 0 | G6: 0 | H6: 0 | K6: 0 | L6: 0 | M6: 0 | N6: 0 | O6: 0 | R6: 0 | S6: 0 | T6: 0 | U6: 0 | V6: 0 | Y6: 0 | Z6: 0 | AA6: 0 | AB6: 0 | AC6: 0 | AF6: 0 | AG6: 0 | AH6: 0
A7: 5 | B7: 吳嘉銘 | C7: =SUM(D7:AH7) -> 16 | D7: 0 | E7: 0 | F7: 0 | G7: 0 | H7: 0 | K7: 0 | L7: 0 | M7: 0 | N7: 16 | O7: 0 | R7: 0 | S7: 0 | T7: 0 | U7: 0 | V7: 0 | Y7: 0 | Z7: 0 | AA7: 0 | AB7: 0 | AC7: 0 | AF7: 0 | AG7: 0 | AH7: 0
A8: 6 | B8: 林詠書 | C8: =SUM(D8:AH8) -> 16 | D8: 0 | E8: 0 | F8: 0 | G8: 0 | H8: 0 | K8: 0 | L8: 0 | M8: 0 | N8: 0 | O8: 0 | R8: 0 | S8: 0 | T8: 0 | U8: 0 | V8: 0 | Y8: 0 | Z8: 0 | AA8: 0 | AB8: 0 | AC8: 0 | AF8: 0 | AG8: 16 | AH8: 0
A9: 7 | B9: 謝秉宏 | C9: =SUM(D9:AH9) -> 40 | D9: 0 | E9: 0 | F9: 0 | G9: 0 | H9: 0 | K9: 0 | L9: 0 | M9: 0 | N9: 0 | O9: 0 | R9: 0 | S9: 0 | T9: 0 | U9: 0 | V9: 0 | Y9: 0 | Z9: 0 | AA9: 16 | AB9: 8 | AC9: 0 | AF9: 16 | AG9: 0 | AH9: 0
A10: 8 | B10: 林建宏 | C10: =SUM(D10:AH10) -> 0 | D10: 0 | E10: 0 | F10: 0 | G10: 0 | H10: 0 | K10: 0 | L10: 0 | M10: 0 | N10: 0 | O10: 0 | R10: 0 | S10: 0 | T10: 0 | U10: 0 | V10: 0 | Y10: 0 | Z10: 0 | AA10: 0 | AB10: 0 | AC10: 0 | AF10: 0 | AG10: 0 | AH10: 0
A11: 9 | B11: 蘇景郁 | C11: =SUM(D11:AH11) -> 0 | D11: 0 | E11: 0 | F11: 0 | G11: 0 | H11: 0 | K11: 0 | L11: 0 | M11: 0 | N11: 0 | O11: 0 | R11: 0 | S11: 0 | T11: 0 | U11: 0 | V11: 0 | Y11: 0 | Z11: 0 | AA11: 0 | AB11: 0 | AC11: 0 | AF11: 0 | AG11: 0 | AH11: 0
A12: 10 | B12: 潘其昌 | C12: =SUM(D12:AH12) -> 16 | D12: 0 | E12: 16 | F12: 0 | G12: 0 | H12: 0 | K12: 0 | L12: 0 | M12: 0 | N12: 0 | O12: 0 | R12: 0 | S12: 0 | T12: 0 | U12: 0 | V12: 0 | Y12: 0 | Z12: 0 | AA12: 0 | AB12: 0 | AC12: 0 | AF12: 0 | AG12: 0 | AH12: 0
A13: 11 | B13: 陳俊男 | C13: =SUM(D13:AH13) -> 8 | D13: 0 | E13: 0 | F13: 0 | G13: 0 | H13: 0 | K13: 0 | L13: 8 | M13: 0 | N13: 0 | O13: 0 | R13: 0 | S13: 0 | T13: 0 | U13: 0 | V13: 0 | Y13: 0 | Z13: 0 | AA13: 0 | AB13: 0 | AC13: 0 | AF13: 0 | AG13: 0 | AH13: 0
A14: 12 | B14: 林政宏 | C14: =SUM(D14:AH14) -> 0 | D14: 0 | E14: 0 | F14: 0 | G14: 0 | H14: 0 | K14: 0 | L14: 0 | M14: 0 | N14: 0 | O14: 0 | R14: 0 | S14: 0 | T14: 0 | U14: 0 | V14: 0 | Y14: 0 | Z14: 0 | AA14: 0 | AB14: 0 | AC14: 0 | AF14: 0 | AG14: 0 | AH14: 0
... A16: 14 | B16: 劉益豪 | C16: =SUM(D16:AH16) -> 0 | D16: 0 | E16: 0 | F16: 0 | G16: 0 | H16: 0 | K16: 0 | L16: 0 | M16: 0 | N16: 0 | O16: 0 | R16: 0 | S16: 0 | T16: 0 | U16: 0 | V16: 0 | Y16: 0 | Z16: 0 | AA16: 0 | AB16: 0 | AC16: 0 | AF16: 0 | AG16: 0 | AH16: 0

Sheet TP出勤1月份
A1: TP出勤 | C1: 45292 | D1: 45293 | E1: 45294 | F1: 45295 | G1: 45296 | H1: 45297 | I1: 45298 | J1: 45299 | K1: 45300 | L1: 45301 | M1: 45302 | N1: 45303 | O1: 45304 | P1: 45305 | Q1: 45306 | R1: 45307 | S1: 45308 | T1: 45309 | U1: 45310 | V1: 45311 | W1: 45312 | X1: 45313 | Y1: 45314 | Z1: 45315 | AA1: 45316 | AB1: 45317 | AC1: 45318 | AD1: 45319 | AE1: 45320 | AF1: 45321 | AG1: 45322
A2: NO. | B2: 姓名
A3: 1 | B3: 郭先弘 | D3: ✓ | E3: 出差 | F3: 出差 | G3: 出差 | J3: 出差 | K3: 出差 | L3: 出差 | M3: 出差 | N3: 出差 | Q3: 出差 | R3: 出差 | S3: 出差 | T3: 出差 | U3: 出差 | X3: 出差 | Y3: 出差 | Z3: 出差 | AA3: 出差 | AB3: 出差 | AE3: 出差 | AF3: 出差 | AG3: 出差
A4: 2 | B4: 陳淑芬 | D4: ✓ | E4: 出差 | F4: 出差 | G4: 出差 | J4: 出差 | K4: 出差 | L4: 出差 | M4: 出差 | N4: 出差 | Q4: 出差 | R4: 出差 | S4: 出差 | T4: 出差 | U4: 出差 | X4: 出差 | Y4: 出差 | Z4: 出差 | AA4: 出差 | AB4: 出差 | AE4: 出差 | AF4: 出差 | AG4: 出差
A5: 3 | B5: 林世彬 | D5: ✓ | E5: ✓ | F5: ✓ | G5: ✓ | J5: ✓ | K5: ✓ | L5: ✓ | M5: ✓ | N5: ✓ | Q5: ✓ | R5: ◎ | S5: ✓ | T5: ✓ | U5: ✓ | X5: ✓ | Y5: ✓ | Z5: ✓ | AA5: ✓ | AB5: ✓ | AE5: ✓ | AF5: ✓ | AG5: ✓
A6: 4 | B6: 何彥璋 | D6: ◎ | E6: 出差 | F6: 出差 | G6: 出差 | J6: 出差 | K6: 出差 | L6: 出差 | M6: 出差 | N6: 出差 | Q6: 出差 | R6: 出差 | S6: 出差 | T6: 出差 | U6: 出差 | X6: 出差 | Y6: 出差 | Z6: 出差 | AA6: 出差 | AB6: 出差 | AE6: 出差 | AF6: 出差 | AG6: 出差
A7: 5 | B7: 吳嘉銘 | D7: 出差 | E7: 出差 | F7: 出差 | G7: 出差 | J7: ✓ | K7: ✓ | L7: ✓ | M7: ◎ | N7: 出差 | Q7: 出差 | R7: 出差 | S7: 出差 | T7: 出差 | U7: 出差 | X7: 出差 | Y7: 出差 | Z7: 出差 | AA7: 出差 | AB7: 出差 | AE7: 出差 | AF7: 出差 | AG7: 出差
A8: 6 | B8: 林詠書 | D8: ✓ | E8: ✓ | F8: ✓ | G8: ✓ | J8: 出差 | K8: 出差 | L8: 出差 | M8: 出差 | N8: 出差 | Q8: 出差 | R8: 出差 | S8: 出差 | T8: 出差 | U8: 出差 | X8: 出差 | Y8: 出差 | Z8: 出差 | AA8: 出差 | AB8: 出差 | AE8: 出差 | AF8: ◎ | AG8: ✓
A9: 7 | B9: 謝秉宏 | D9: ✓ | E9: ✓ | F9: ✓ | G9: ✓ | J9: ✓ | K9: ✓ | L9: ✓ | M9: ✓ | N9: ✓ | Q9: ✓ | R9: ✓ | S9: ✓ | T9: ✓ | U9: ✓ | X9: ✓ | Y9: ✓ | Z9: ◎ | AA9: ✓ | AB9: ✓ | AE9: ◎ | AF9: ✓ | AG9: ✓
A10: 8 | B10: 林建宏 | D10: ✓ | E10: 出差 | F10: 出差 | G10: 出差 | J10: 出差 | K10: 出差 | L10: 出差 | M10: 出差 | N10: 出差 | Q10: 出差 | R10: 出差 | S10: 出差 | T10: 出差 | U10: 出差 | X10: 出差 | Y10: 出差 | Z10: 出差 | AA10: 出差 | AB10: 出差 | AE10: 出差 | AF10: 出差 | AG10: 出差
A11: 9 | B11: 蘇景郁 | D11: ✓ | E11: 出差 | F11: 出差 | G11: 出差 | J11: 出差 | K11: 出差 | L11: 出差 | M11: 出差 | N11: 出差 | Q11: 出差 | R11: 出差 | S11: 出差 | T11: 出差 | U11: 出差 | X11: 出差 | Y11: 出差 | Z11: 出差 | AA11: 出差 | AB11: 出差 | AE11: 出差 | AF11: 出差 | AG11: 出差
A12: 10 | B12: 潘其昌 | D12: ◎ | E12: 出差 | F12: 出差 | G12: 出差 | J12: 出差 | K12: 出差 | L12: 出差 | M12: 出差 | N12: 出差 | Q12: 出差 | R12: 出差 | S12: 出差 | T12: 出差 | U12: 出差 | X12: 出差 | Y12: 出差 | Z12: 出差 | AA12: 出差 | AB12: 出差 | AE12: 出差 | AF12: 出差 | AG12: 出差
A13: 11 | B13: 陳俊男 | D13: ✓ | E13: ✓ | F13: ✓ | G13: ✓ | J13: ✓ | K13: ✓ | L13: 出差 | M13: 出差 | N13: 出差 | Q13: 出差 | R13: 出差 | S13: 出差 | T13: 出差 | U13: 出差 | X13: 出差 | Y13: 出差 | Z13: 出差 | AA13: 出差 | AB13: 出差 | AE13: 出差 | AF13: 出差 | AG13: 出差
A14: 12 | B14: 林政宏 | D14: 出差 | E14: 出差 | F14: 出差 | G14: 出差 | J14: 出差 | K14: 出差 | L14: 出差 | M14: 出差 | N14: 出差 | Q14: 出差 | R14: 出差 | S14: 出差 | T14: 出差 | U14: 出差 | X14: 出差 | Y14: 出差 | Z14: 出差 | AA14: 出差 | AB14: 出差 | AE14: 出差 | AF14: 出差 | AG14: 出差
... A16: 14 | B16: 劉益豪 | D16: 出差 | E16: 出差 | F16: 出差 | G16: 出差 | J16: 出差 | K16: 出差 | L16: 出差 | M16: 出差 | N16: 出差 | Q16: 出差 | R16: 出差 | S16: 出差 | T16: 出差 | U16: 出差 | X16: 出差 | Y16: 出差 | Z16: 出差 | AA16: 出差 | AB16: 出差 | AE16: 出差 | AF16: 出差 | AG16: 出差
A17: ✓ | B17: 正常
A18: ◎ | B18: 補休
A19: △ | B19: 遲到

Sheet TP1月份加班
A1: TP加班 | C1: 一月累計 (0.5小時/單位) | D1: 45292 | E1: 45293 | F1: 45294 | G1: 45295 | H1: 45296 | I1: 45297 | J1: 45298 | K1: 45299 | L1: 45300 | M1: 45301 | N1: 45302 | O1: 45303 | P1: 45304 | Q1: 45305 | R1: 45306 | S1: 45307 | T1: 45308 | U1: 45309 | V1: 45310 | W1: 45311 | X1: 45312 | Y1: 45313 | Z1: 45314 | AA1: 45315 | AB1: 45316 | AC1: 45317 | AD1: 45318 | AE1: 45319 | AF1: 45320 | AG1: 45321 | AH1: 45322
A2: NO. | B2: 姓名
A3: 1 | B3: 郭先弘 | C3: =SUM(D3:AH3) -> 0 | D3: 0 | E3: 0 | F3: 0 | G3: 0 | H3: 0 | K3: 0 | L3: 0 | M3: 0 | N3: 0 | O3: 0 | R3: 0 | S3: 0 | T3: 0 | U3: 0 | V3: 0 | Y3: 0 | Z3: 0 | AA3: 0 | AB3: 0 | AC3: 0 | AF3: 0 | AG3: 0 | AH3: 0
A4: 2 | B4: 陳淑芬 | C4: =SUM(D4:AH4) -> 0 | D4: 0 | E4: 0 | F4: 0 | G4: 0 | H4: 0 | K4: 0 | L4: 0 | M4: 0 | N4: 0 | O4: 0 | R4: 0 | S4: 0 | T4: 0 | U4: 0 | V4: 0 | Y4: 0 | Z4: 0 | AA4: 0 | AB4: 0 | AC4: 0 | AF4: 0 | AG4: 0 | AH4: 0
A5: 3 | B5: 林世彬 | C5: =SUM(D5:AH5) -> 18 | D5: 0 | E5: 12 | F5: 2 | G5: 0 | H5: 0 | K5: 0 | L5: 0 | M5: 0 | N5: 0 | O5: 0 | R5: 0 | S5: 0 | T5: 0 | U5: 0 | V5: 0 | Y5: 0 | Z5: 0 | AA5: 0 | AB5: 0 | AC5: 0 | AF5: 4 | AG5: 0 | AH5: 0
A6: 4 | B6: 何彥璋 | C6: =SUM(D6:AH6) -> 6 | D6: 0 | E6: 0 | F6: 0 | G6: 0 | H6: 0 | K6: 0 | L6: 0 | M6: 0 | N6: 6 | O6: 0 | R6: 0 | S6: 0 | T6: 0 | U6: 0 | V6: 0 | Y6: 0 | Z6: 0 | AA6: 0 | AB6: 0 | AC6: 0 | AF6: 0 | AG6: 0 | AH6: 0
A7: 5 | B7: 吳嘉銘 | C7: =SUM(D7:AH7) -> 9 | D7: 0 | E7: 6 | F7: 0 | G7: 0 | H7: 0 | K7: 1 | L7: 1 | M7: 1 | N7: 0 | O7: 0 | R7: 0 | S7: 0 | T7: 0 | U7: 0 | V7: 0 | Y7: 0 | Z7: 0 | AA7: 0 | AB7: 0 | AC7: 0 | AF7: 0 | AG7: 0 | AH7: 0
A8: 6 | B8: 林詠書 | C8: =SUM(D8:AH8) -> 33 | D8: 0 | E8: 2 | F8: 1 | G8: 1 | H8: 1 | K8: 0 | L8: 4 | M8: 1 | N8: 4 | O8: 3 | R8: 4 | S8: 1 | T8: 1 | U8: 1 | V8: 1 | Y8: 1 | Z8: 4 | AA8: 1 | AB8: 1 | AC8: 0 | AF8: 0 | AG8: 0 | AH8: 1
A9: 7 | B9: 謝秉宏 | C9: =SUM(D9:AH9) -> 34 | D9: 0 | E9: 0 | F9: 0 | G9: 0 | H9: 2 | K9: 2 | L9: 6 | M9: 1 | N9: 0 | O9: 0 | R9: 0 | S9: 7 | T9: 6 | U9: 0 | V9: 0 | Y9: 0 | Z9: 0 | AA9: 0 | AB9: 0 | AC9: 0 | AF9: 0 | AG9: 6 | AH9: 4
A10: 8 | B10: 林建宏 | C10: =SUM(D10:AH10) -> 6 | D10: 0 | E10: 0 | F10: 0 | G10: 0 | H10: 0 | K10: 0 | L10: 0 | M10: 0 | N10: 6 | O10: 0 | R10: 0 | S10: 0 | T10: 0 | U10: 0 | V10: 0 | Y10: 0 | Z10: 0 | AA10: 0 | AB10: 0 | AC10: 0 | AF10: 0 | AG10: 0 | AH10: 0
A11: 9 | B11: 蘇景郁 | C11: =SUM(D11:AH11) -> 6 | D11: 0 | E11: 0 | F11: 0 | G11: 0 | H11: 0 | K11: 0 | L11: 0 | M11: 0 | N11: 6 | O11: 0 | R11: 0 | S11: 0 | T11: 0 | U11: 0 | V11: 0 | Y11: 0 | Z11: 0 | AA11: 0 | AB11: 0 | AC11: 0 | AF11: 0 | AG11: 0 | AH11: 0
A12: 10 | B12: 潘其昌 | C12: =SUM(D12:AH12) -> 6 | D12: 0 | E12: 0 | F12: 0 | G12: 0 | H12: 0 | K12: 0 | L12: 0 | M12: 0 | N12: 6 | O12: 0 | R12: 0 | S12: 0 | T12: 0 | U12: 0 | V12: 0 | Y12: 0 | Z12: 0 | AA12: 0 | AB12: 0 | AC12: 0 | AF12: 0 | AG12: 0 | AH12: 0
A13: 11 | B13: 陳俊男 | C13: =SUM(D13:AH13) -> 25 | D13: 0 | E13: 0 | F13: 0 | G13: 0 | H13: 0 | K13: 0 | L13: 0 | M13: 0 | N13: 5 | O13: 0 | R13: 8 | S13: 4 | T13: 0 | U13: 0 | V13: 0 | Y13: 0 | Z13: 8 | AA13: 0 | AB13: 0 | AC13: 0 | AF13: 0 | AG13: 0 | AH13: 0
A14: 12 | B14: 林政宏 | C14: =SUM(D14:AH14) -> 44 | D14: 0 | E14: 6 | F14: 0 | G14: 6 | H14: 0 | K14: 0 | L14: 6 | M14: 0 | N14: 6 | O14: 0 | R14: 6 | S14: 0 | T14: 0 | U14: 0 | V14: 0 | Y14: 0 | Z14: 8 | AA14: 6 | AB14: 0 | AC14: 0 | AF14: 0 | AG14: 0 | AH14: 0
... A16: 14 | B16: 劉益豪 | C16: =SUM(D16:AH16) -> 30 | D16: 0 | E16: 6 | F16: 0 | G16: 6 | H16: 0 | K16: 0 | L16: 0 | M16: 0 | N16: 6 | O16: 0 | R16: 0 | S16: 4 | T16: 0 | U16: 0 | V16: 0 | Y16: 0 | Z16: 8 | AA16: 0 | AB16: 0 | AC16: 0 | AF16: 0 | AG16: 0 | AH16: 0

Sheet TP出勤2月份
A1: TP出勤 | C1: 45323 | D1: 45324 | E1: 45325 | F1: 45326 | G1: 45327 | H1: 45328 | I1: 45329 | J1: 45330 | K1: 45331 | L1: 45332 | M1: 45333 | N1: 45334 | O1: 45335 | P1: 45336 | Q1: 45337 | R1: 45338 | S1: 45339 | T1: 45340 | U1: 45341 | V1: 45342 | W1: 45343 | X1: 45344 | Y1: 45345 | Z1: 45346 | AA1: 45347 | AB1: 45348 | AC1: 45349 | AD1: 45350 | AE1: 45351
A2: NO. | B2: 姓名
A3: 1 | B3: 郭先弘 | C3: 出差 | D3: 出差 | G3: ◎ | H3: ◎ | I3: ◎ | Q3: ✓ | R3: ✓ | S3: ◎ | U3: ✓ | V3: ✓ | W3: ◎ | X3: ✓ | Y3: ✓ | AB3: ✓ | AC3: ✓ | AE3: ◎
A4: 2 | B4: 陳淑芬 | C4: 出差 | D4: 出差 | G4: 出差 | H4: ✓ | I4: ✓ | Q4: ✓ | R4: ✓ | S4: ◎ | U4: 出差 | V4: 出差 | W4: 出差 | X4: 出差 | Y4: 出差 | AB4: 出差 | AC4: 出差 | AE4: 出差
A5: 3 | B5: 林世彬 | C5: ✓ | D5: ✓ | G5: ✓ | H5: ✓ | I5: ✓ | Q5: ✓ | R5: ✓ | S5: ✓ | U5: ✓ | V5: ✓ | W5: ✓ | X5: ✓ | AB5: ✓ | AC5: ✓ | AE5: ✓
A6: 4 | B6: 何彥璋 | C6: 出差 | D6: 出差 | G6: 出差 | H6: ✓ | I6: ◎ | Q6: ◎ | R6: 出差 | S6: 出差 | U6: 出差 | V6: 出差 | W6: 出差 | X6: 出差 | Y6: 出差 | AB6: 出差 | AC6: 出差 | AE6: 出差
A7: 5 | B7: 吳嘉銘 | C7: 出差 | D7: 出差 | G7: 出差 | H7: ✓ | I7: ◎ | Q7: ✓ | R7: 出差 | S7: 出差 | U7: 出差 | V7: 出差 | W7: 出差 | X7: 出差 | Y7: 出差 | AB7: 出差 | AC7: 出差 | AE7: 出差
A8: 6 | B8: 林詠書 | C8: ✓ | D8: ✓ | G8: ✓ | H8: ✓ | I8: ✓ | Q8: ✓ | R8: ✓ | S8: ✓ | U8: ✓ | V8: ◎ | W8: ✓ | X8: ✓ | Y8: ✓ | AB8: ✓ | AC8: ✓ | AE8: ✓
A9: 7 | B9: 謝秉宏 | C9: ✓ | D9: ✓ | G9: ◎ | H9: ✓ | I9: ✓ | Q9: ✓ | R9: ✓ | S9: ✓ | U9: ◎ | V9: ✓ | W9: ✓ | X9: ✓ | Y9: ✓ | AB9: ✓ | AC9: △ | AE9: ✓
A10: 8 | B10: 林建宏 | C10: 出差 | D10: 出差 | G10: 出差 | H10: ◎ | I10: ✓ | Q10: ✓ | R10: ◎ | S10: ◎ | U10: 出差 | V10: 出差 | W10: 出差 | X10: 出差 | Y10: 出差 | AB10: 出差 | AC10: 出差 | AE10: 出差
A11: 9 | B11: 蘇景郁 | C11: 出差 | D11: 出差 | G11: 出差 | H11: ✓ | I11: ◎ | Q11: ✓ | R11: ✓ | S11: ◎ | U11: 出差 | V11: 出差 | W11: 出差 | X11: 出差 | Y11: 出差 | AB11: 出差 | AC11: 出差 | AE11: 出差
A12: 10 | B12: 潘其昌 | C12: 出差 | D12: 出差 | G12: 出差 | H12: ✓ | I12: ✓ | Q12: ✓ | R12: 出差 | S12: 出差 | U12: 出差 | V12: 出差 | W12: 出差 | X12: 出差 | Y12: 出差 | AB12: 出差 | AC12: 出差 | AE12: 出差
A13: 11 | B13: 陳俊男 | C13: 出差 | D13: 出差 | G13: ✓ | H13: ✓ | I13: ◎ | Q13: ✓ | R13: ◎ | S13: ◎ | U13: ◎ | V13: ✓ | W13: ✓ | X13: ✓ | Y13: ◎ | AB13: ✓ | AC13: ✓ | AE13: ✓
A14: 12 | B14: 林政宏 | C14: 出差 | D14: 出差 | G14: 出差 | H14: 出差 | I14: 出差 | Q14: ✓ | R14: ✓ | S14: ◎ | U14: ✓ | V14: ◎ | W14: 出差 | X14: 出差 | Y14: 出差 | AB14: 出差 | AC14: 出差 | AE14: 出差
A15: 13 | B15: 陸長遠 | C15: 出差 | D15: 出差 | G15: 出差 | H15: ◎ | I15: ◎ | Q15: ✓ | R15: ✓ | S15: ◎ | U15: 出差 | V15: 出差 | W15: 出差 | X15: 出差 | Y15: 出差 | AB15: 出差 | AC15: 出差 | AE15: 出差
A16: 14 | B16: 劉益豪 | C16: 出差 | D16: 出差 | G16: ✓ | H16: ✓ | I16: ◎ | Q16: ✓ | R16: ◎ | S16: 出差 | U16: 出差 | V16: 出差 | W16: 出差 | X16: 出差 | Y16: 出差 | AB16: 出差 | AC16: 出差 | AE16: 出差
A17: ✓ | B17: 正常
A18: ◎ | B18: 補休
A19: △ | B19: 遲到

Sheet TP2月份請假
A1: TP請假 | C1: 二月累計 (0.5小時/單位) | D1: 45323 | E1: 45324 | F1: 45325 | G1: 45326 | H1: 45327 | I1: 45328 | J1: 45329 | K1: 45330 | L1: 45331 | M1: 45332 | N1: 45333 | O1: 45334 | P1: 45335 | Q1: 45336 | R1: 45337 | S1: 45338 | T1: 45339 | U1: 45340 | V1: 45341 | W1: 45342 | X1: 45343 | Y1: 45344 | Z1: 45345 | AA1: 45346 | AB1: 45347 | AC1: 45348 | AD1: 45349 | AE1: 45350 | AF1: 45351
A2: NO. | B2: 姓名
A3: 1 | B3: 郭先弘 | C3: =SUM(D3:AF3) -> 0 | D3: 0 | E3: 0 | H3: 0 | I3: 0 | J3: 0 | R3: 0 | S3: 0 | T3: 0 | V3: 0 | W3: 0 | X3: 0 | Y3: 0 | Z3: 0 | AC3: 0 | AD3: 0 | AF3: 0
A4: 2 | B4: 陳淑芬 | C4: =SUM(D4:AF4) -> 23 | D4: 0 | E4: 0 | H4: 0 | I4: 7 | J4: 0 | R4: 0 | S4: 0 | T4: 16 | V4: 0 | W4: 0 | X4: 0 | Y4: 0 | Z4: 0 | AC4: 0 | AD4: 0 | AF4: 0
A5: 3 | B5: 林世彬 | C5: =SUM(D5:AF5) -> 9 | D5: 0 | E5: 0 | H5: 0 | I5: 5 | J5: 0 | R5: 4 | S5: 0 | T5: 0 | V5: 0 | W5: 0 | X5: 0 | Y5: 0 | Z5: 0 | AC5: 0 | AD5: 0 | AF5: 0
A6: 4 | B6: 何彥璋 | C6: =SUM(D6:AF6) -> 40 | D6: 0 | E6: 0 | H6: 0 | I6: 8 | J6: 16 | R6: 16 | S6: 0 | T6: 0 | V6: 0 | W6: 0 | X6: 0 | Y6: 0 | Z6: 0 | AC6: 0 | AD6: 0 | AF6: 0
A7: 5 | B7: 吳嘉銘 | C7: =SUM(D7:AF7) -> 21 | D7: 0 | E7: 0 | H7: 0 | I7: 5 | J7: 16 | R7: 0 | S7: 0 | T7: 0 | V7: 0 | W7: 0 | X7: 0 | Y7: 0 | Z7: 0 | AC7: 0 | AD7: 0 | AF7: 0
A8: 6 | B8: 林詠書 | C8: =SUM(D8:AF8) -> 8 | D8: 0 | E8: 0 | H8: 0 | I8: 8 | J8: 0 | R8: 0 | S8: 0 | T8: 0 | V8: 0 | W8: 0 | X8: 0 | Y8: 0 | Z8: 0 | AC8: 0 | AD8: 0 | AF8: 0
A9: 7 | B9: 謝秉宏 | C9: =SUM(D9:AF9) -> 46 | D9: 0 | E9: 0 | H9: 16 | I9: 0 | J9: 14 | R9: 0 | S9: 0 | T9: 0 | V9: 16 | W9: 0 | X9: 0 | Y9: 0 | Z9: 0 | AC9: 0 | AD9: 0 | AF9: 0
A10: 8 | B10: 林建宏 | C10: =SUM(D10:AF10) -> 56 | D10: 0 | E10: 0 | H10: 0 | I10: 16 | J10: 8 | R10: 0 | S10: 16 | T10: 16 | V10: 0 | W10: 0 | X10: 0 | Y10: 0 | Z10: 0 | AC10: 0 | AD10: 0 | AF10: 0
A11: 9 | B11: 蘇景郁 | C11: =SUM(D11:AF11) -> 32 | D11: 0 | E11: 0 | H11: 0 | I11: 0 | J11: 16 | R11: 0 | S11: 0 | T11: 16 | V11: 0 | W11: 0 | X11: 0 | Y11: 0 | Z11: 0 | AC11: 0 | AD11: 0 | AF11: 0
A12: 10 | B12: 潘其昌 | C12: =SUM(D12:AF12) -> 0 | D12: 0 | E12: 0 | H12: 0 | I12: 0 | J12: 0 | R12: 0 | S12: 0 | T12: 0 | V12: 0 | W12: 0 | X12: 0 | Y12: 0 | Z12: 0 | AC12: 0 | AD12: 0 | AF12: 0
A13: 11 | B13: 陳俊男 | C13: =SUM(D13:AF13) -> 93 | D13: 0 | E13: 0 | H13: 0 | I13: 0 | J13: 16 | R13: 8 | S13: 16 | T13: 16 | V13: 16 | W13: 0 | X13: 0 | Y13: 5 | Z13: 16 | AC13: 0 | AD13: 0 | AF13: 0
A14: 12 | B14: 林政宏 | C14: =SUM(D14:AF14) -> 32 | D14: 0 | E14: 0 | H14: 0 | I14: 0 | J14: 0 | R14: 0 | S14: 0 | T14: 16 | V14: 0 | W14: 16 | X14: 0 | Y14: 0 | Z14: 0 | AC14: 0 | AD14: 0 | AF14: 0
... A16: 14 | B16: 劉益豪 | C16: =SUM(D16:AF16) -> 40 | D16: 0 | E16: 0 | H16: 0 | I16: 8 | J16: 16 | R16: 0 | S16: 16 | T16: 0 | V16: 0 | W16: 0 | X16: 0 | Y16: 0 | Z16: 0 | AC16: 0 | AD16: 0 | AF16: 0

Sheet TP2月份加班
A1: TP加班 | C1: 二月累計 (0.5小時/單位) | D1: 45323 | E1: 45324 | F1: 45325 | G1: 45326 | H1: 45327 | I1: 45328 | J1: 45329 | K1: 45330 | L1: 45331 | M1: 45332 | N1: 45333 | O1: 45334 | P1: 45335 | Q1: 45336 | R1: 45337 | S1: 45338 | T1: 45339 | U1: 45340 | V1: 45341 | W1: 45342 | X1: 45343 | Y1: 45344 | Z1: 45345 | AA1: 45346 | AB1: 45347 | AC1: 45348 | AD1: 45349 | AE1: 45350 | AF1: 45351
A2: NO. | B2: 姓名
A3: 1 | B3: 郭先弘 | C3: =SUM(D3:AF3) -> 0 | D3: 0 | E3: 0 | H3: 0 | I3: 0 | J3: 0 | R3: 0 | S3: 0 | T3: 0 | V3: 0 | W3: 0 | X3: 0 | Y3: 0 | Z3: 0 | AC3: 0 | AD3: 0 | AF3: 0
A4: 2 | B4: 陳淑芬 | C4: =SUM(D4:AF4) -> 0 | D4: 0 | E4: 0 | H4: 0 | I4: 0 | J4: 0 | R4: 0 | S4: 0 | T4: 0 | V4: 0 | W4: 0 | X4: 0 | Y4: 0 | Z4: 0 | AC4: 0 | AD4: 0 | AF4: 0
A5: 3 | B5: 林世彬 | C5: =SUM(D5:AF5) -> 0 | D5: 0 | E5: 0 | H5: 0 | I5: 0 | J5: 0 | R5: 0 | S5: 0 | T5: 0 | V5: 0 | W5: 0 | X5: 0 | Y5: 0 | Z5: 0 | AC5: 0 | AD5: 0 | AF5: 0
A6: 4 | B6: 何彥璋 | C6: =SUM(D6:AF6) -> 0 | D6: 0 | E6: 0 | H6: 0 | I6: 0 | J6: 0 | R6: 0 | S6: 0 | T6: 0 | V6: 0 | W6: 0 | X6: 0 | Y6: 0 | Z6: 0 | AC6: 0 | AD6: 0 | AF6: 0
A7: 5 | B7: 吳嘉銘 | C7: =SUM(D7:AF7) -> 0 | D7: 0 | E7: 0 | H7: 0 | I7: 0 | J7: 0 | R7: 0 | S7: 0 | T7: 0 | V7: 0 | W7: 0 | X7: 0 | Y7: 0 | Z7: 0 | AC7: 0 | AD7: 0 | AF7: 0
A8: 6 | B8: 林詠書 | C8: =SUM(D8:AF8) -> 12 | D8: 1 | E8: 0 | H8: 1 | I8: 0 | J8: 0 | R8: 1 | S8: 1 | T8: 0 | V8: 1 | W8: 0 | X8: 2 | Y8: 1 | Z8: 0 | AC8: 2 | AD8: 1 | AF8: 1
A9: 7 | B9: 謝秉宏 | C9: =SUM(D9:AF9) -> 37 | D9: 6 | E9: 0 | H9: 0 | I9: 0 | J9: 0 | R9: 1 | S9: 6 | T9: 0 | V9: 0 | W9: 6 | X9: 7 | Y9: 1 | Z9: 1 | AC9: 1 | AD9: 1 | AF9: 7
A10: 8 | B10: 林建宏 | C10: =SUM(D10:AF10) -> 0 | D10: 0 | E10: 0 | H10: 0 | I10: 0 | J10: 0 | R10: 0 | S10: 0 | T10: 0 | V10: 0 | W10: 0 | X10: 0 | Y10: 0 | Z10: 0 | AC10: 0 | AD10: 0 | AF10: 0
A11: 9 | B11: 蘇景郁 | C11: =SUM(D11:AF11) -> 1 | D11: 0 | E11: 0 | H11: 0 | I11: 0 | J11: 0 | R11: 1 | S11: 0 | T11: 0 | V11: 0 | W11: 0 | X11: 0 | Y11: 0 | Z11: 0 | AC11: 0 | AD11: 0 | AF11: 0
A12: 10 | B12: 潘其昌 | C12: =SUM(D12:AF12) -> 0 | D12: 0 | E12: 0 | H12: 0 | I12: 0 | J12: 0 | R12: 0 | S12: 0 | T12: 0 | V12: 0 | W12: 0 | X12: 0 | Y12: 0 | Z12: 0 | AC12: 0 | AD12: 0 | AF12: 0
A13: 11 | B13: 陳俊男 | C13: =SUM(D13:AF13) -> 0 | D13: 0 | E13: 0 | H13: 0 | I13: 0 | J13: 0 | R13: 0 | S13: 0 | T13: 0 | V13: 0 | W13: 0 | X13: 0 | Y13: 0 | Z13: 0 | AC13: 0 | AD13: 0 | AF13: 0
A14: 12 | B14: 林政宏 | C14: =SUM(D14:AF14) -> 32 | D14: 0 | E14: 0 | H14: 6 | I14: 0 | J14: 0 | R14: 4 | S14: 6 | T14: 0 | V14: 16 | W14: 0 | X14: 0 | Y14: 0 | Z14: 0 | AC14: 0 | AD14: 0 | AF14: 0
... A16: 14 | B16: 劉益豪 | C16: =SUM(D16:AF16) -> 12 | D16: 0 | E16: 0 | H16: 0 | I16: 0 | J16: 0 | R16: 0 | S16: 0 | T16: 0 | V16: 0 | W16: 0 | X16: 6 | Y16: 0 | Z16: 0 | AC16: 0 | AD16: 6 | AF16: 0

Sheet TP出勤3月份
A1: TP出勤 | C1: 45352 | D1: 45353 | E1: 45354 | F1: 45355 | G1: 45356 | H1: 45357 | I1: 45358 | J1: 45359 | K1: 45360 | L1: 45361 | M1: 45362 | N1: 45363 | O1: 45364 | P1: 45365 | Q1: 45366 | R1: 45367 | S1: 45368 | T1: 45369 | U1: 45370 | V1: 45371 | W1: 45372 | X1: 45373 | Y1: 45374 | Z1: 45375 | AA1: 45376 | AB1: 45377 | AC1: 45378 | AD1: 45379 | AE1: 45380 | AF1: 45381 | AG1: 45382
A2: NO. | B2: 姓名
A3: 1 | B3: 郭先弘 | C3: 出差 | F3: 出差 | G3: 出差 | H3: 出差 | I3: 出差 | J3: 出差 | M3: 出差 | N3: 出差 | O3: 出差 | P3: 出差 | Q3: 出差 | T3: 出差 | U3: 出差 | V3: 出差 | W3: 出差 | X3: 出差 | AA3: 出差 | AB3: 出差 | AC3: 出差 | AD3: 出差 | AE3: 出差
A4: 2 | B4: 陳淑芬 | C4: 出差 | F4: 出差 | G4: 出差 | H4: 出差 | I4: 出差 | J4: 出差 | M4: 出差 | N4: 出差 | O4: ◎ | P4: 出差 | Q4: 出差 | T4: ✓ | U4: ✓ | V4: ✓ | W4: ✓ | AA4: ✓ | AB4: ✓ | AC4: △ | AD4: ✓ | AE4: ✓
A5: 3 | B5: 林世彬 | C5: ✓ | F5: ✓ | G5: ✓ | H5: ✓ | I5: ✓ | J5: ✓ | M5: ✓ | N5: ✓ | O5: ✓ | P5: ✓ | Q5: ✓ | T5: ✓ | U5: ✓ | V5: ✓ | W5: ✓ | X5: ◎ | AA5: ✓ | AB5: ✓ | AC5: ✓ | AD5: ✓ | AE5: ✓
A6: 4 | B6: 何彥璋 | C6: 出差 | F6: 出差 | G6: 出差 | H6: 出差 | I6: 出差 | J6: 出差 | M6: 出差 | N6: 出差 | O6: 出差 | P6: 出差 | Q6: 出差 | T6: 出差 | U6: ✓ | V6: ✓ | W6: ✓ | X6: ◎ | AA6: ✓ | AB6: ✓ | AC6: ✓ | AD6: ◎ | AE6: 出差
A7: 5 | B7: 吳嘉銘 | C7: 出差 | F7: 出差 | G7: 出差 | H7: 出差 | I7: 出差 | J7: 出差 | M7: 出差 | N7: 出差 | O7: 出差 | P7: 出差 | Q7: 出差 | T7: 出差 | U7: 出差 | V7: 出差 | W7: 出差 | X7: 出差 | AA7: 出差 | AB7: 出差 | AC7: 出差 | AD7: 出差 | AE7: 出差
A8: 6 | B8: 林詠書 | C8: ✓ | F8: ✓ | G8: ✓ | H8: ✓ | I8: ✓ | J8: ✓ | M8: ✓ | N8: ✓ | O8: ✓ | P8: ✓ | Q8: ✓ | T8: ✓ | U8: ✓ | V8: ✓ | W8: ✓ | X8: ✓ | AA8: ✓ | AB8: ✓ | AC8: ✓ | AD8: ✓ | AE8: ✓
A9: 7 | B9: 謝秉宏 | C9: ✓ | F9: ◎ | G9: ✓ | H9: ✓ | I9: ✓ | J9: ✓ | M9: ✓ | N9: ✓ | O9: ✓ | P9: ✓ | Q9: ✓ | T9: ✓ | U9: ✓ | V9: ◎ | W9: ✓ | X9: ✓ | AA9: ✓ | AB9: ✓ | AC9: ◎ | AD9: ✓ | AE9: ✓
A10: 8 | B10: 林建宏 | C10: 出差 | F10: 出差 | G10: 出差 | H10: 出差 | I10: 出差 | J10: 出差 | M10: 出差 | N10: 出差 | O10: 出差 | P10: 出差 | Q10: 出差 | T10: 出差 | U10: 出差 | V10: 出差 | W10: 出差 | X10: 出差 | AA10: 出差 | AB10: 出差 | AC10: 出差 | AD10: 出差 | AE10: 出差
A11: 9 | B11: 蘇景郁 | C11: 出差 | F11: 出差 | G11: 出差 | H11: 出差 | I11: 出差 | J11: 出差 | M11: 出差 | N11: 出差 | O11: 出差 | P11: 出差 | Q11: 出差 | T11: 出差 | U11: 出差 | V11: 出差 | W11: 出差 | X11: 出差 | AA11: 出差 | AB11: 出差 | AC11: 出差 | AD11: 出差 | AE11: 出差
A12: 10 | B12: 潘其昌 | C12: 出差 | F12: 出差 | G12: 出差 | H12: 出差 | I12: 出差 | J12: 出差 | M12: 出差 | N12: 出差 | O12: 出差 | P12: 出差 | Q12: 出差 | T12: 出差 | U12: ✓ | V12: ◎ | W12: ✓ | X12: ◎ | AA12: ✓ | AB12: ✓ | AC12: ✓ | AD12: ✓ | AE12: 出差
A13: 11 | B13: 陳俊男 | C13: ✓ | F13: ✓ | G13: ◎ | H13: 出差 | I13: 出差 | J13: 出差 | M13: 出差 | N13: 出差 | O13: 出差 | P13: 出差 | Q13: 出差 | T13: 出差 | U13: 出差 | V13: 出差 | W13: 出差 | X13: 出差 | AA13: 出差 | AB13: 出差 | AC13: 出差 | AD13: 出差 | AE13: 出差
A14: 12 | B14: 林政宏 | C14: 出差 | F14: 出差 | G14: 出差 | H14: 出差 | I14: 出差 | J14: 出差 | M14: ◎ | N14: ◎ | O14: ✓ | P14: ✓ | Q14: ✓ | T14: ✓ | U14: ✓ | V14: 出差 | W14: ✓ | X14: ✓ | AA14: 出差 | AB14: 出差 | AC14: 出差 | AD14: 出差 | AE14: 出差
A15: 13 | B15: 陸長遠 | C15: 出差 | F15: 出差 | G15: 出差 | H15: 出差 | I15: 出差 | J15: 出差 | M15: 出差 | N15: 出差 | O15: 出差 | P15: 出差 | Q15: 出差 | T15: 出差 | U15: ✓ | V15: ✓ | W15: ✓ | X15: ✓ | AA15: ✓ | AB15: ✓ | AC15: ✓ | AD15: ✓ | AE15: ✓
A16: 14 | B16: 劉益豪 | C16: 出差 | F16: 出差 | G16: 出差 | H16: 出差 | I16: 出差 | J16: 出差 | M16: 出差 | N16: 出差 | O16: 出差 | P16: 出差 | Q16: 出差 | T16: 出差 | U16: 出差 | V16: 出差 | W16: 出差 | X16: 出差 | AA16: 出差 | AB16: 出差 | AC16: 出差 | AD16: 出差 | AE16: 出差
A17: ✓ | B17: 正常
A18: ◎ | B18: 補休
A19: △ | B19: 遲到

Sheet TP3月份請假
A1: TP請假 | C1: 三月累計 (0.5小時/單位) | D1: 45352 | E1: 45353 | F1: 45354 | G1: 45355 | H1: 45356 | I1: 45357 | J1: 45358 | K1: 45359 | L1: 45360 | M1: 45361 | N1: 45362 | O1: 45363 | P1: 45364 | Q1: 45365 | R1: 45366 | S1: 45367 | T1: 45368 | U1: 45369 | V1: 45370 | W1: 45371 | X1: 45372 | Y1: 45373 | Z1: 45374 | AA1: 45375 | AB1: 45376 | AC1: 45377 | AD1: 45378 | AE1: 45379 | AF1: 45380 | AG1: 45381 | AH1: 45382
A2: NO. | B2: 姓名
A3: 1 | B3: 郭先弘 | C3: =SUM(D3:AH3) -> 0 | D3: 0 | G3: 0 | H3: 0 | I3: 0 | J3: 0 | K3: 0 | N3: 0 | O3: 0 | P3: 0 | Q3: 0 | R3: 0 | U3: 0 | V3: 0 | W3: 0 | X3: 0 | Y3: 0 | AB3: 0 | AC3: 0 | AD3: 0 | AE3: 0 | AF3: 0
A4: 2 | B4: 陳淑芬 | C4: =SUM(D4:AH4) -> 17 | D4: 0 | G4: 0 | H4: 0 | I4: 0 | J4: 0 | K4: 0 | N4: 0 | O4: 0 | P4: 16 | Q4: 0 | R4: 0 | U4: 0 | V4: 0 | W4: 0 | X4: 0 | Y4: 0 | AB4: 0 | AC4: 0 | AD4: 1 | AE4: 0 | AF4: 0
A5: 3 | B5: 林世彬 | C5: =SUM(D5:AH5) -> 38 | D5: 0 | G5: 0 | H5: 0 | I5: 0 | J5: 0 | K5: 0 | N5: 4 | O5: 2 | P5: 0 | Q5: 4 | R5: 0 | U5: 0 | V5: 0 | W5: 3 | X5: 5 | Y5: 16 | AB5: 0 | AC5: 0 | AD5: 0 | AE5: 4 | AF5: 0
A6: 4 | B6: 何彥璋 | C6: =SUM(D6:AH6) -> 32 | D6: 0 | G6: 0 | H6: 0 | I6: 0 | J6: 0 | K6: 0 | N6: 0 | O6: 0 | P6: 0 | Q6: 0 | R6: 0 | U6: 0 | V6: 0 | W6: 0 | X6: 0 | Y6: 16 | AB6: 0 | AC6: 0 | AD6: 0 | AE6: 16 | AF6: 0
A7: 5 | B7: 吳嘉銘 | C7: =SUM(D7:AH7) -> 0 | D7: 0 | G7: 0 | H7: 0 | I7: 0 | J7: 0 | K7: 0 | N7: 0 | O7: 0 | P7: 0 | Q7: 0 | R7: 0 | U7: 0 | V7: 0 | W7: 0 | X7: 0 | Y7: 0 | AB7: 0 | AC7: 0 | AD7: 0 | AE7: 0 | AF7: 0
A8: 6 | B8: 林詠書 | C8: =SUM(D8:AH8) -> 4 | D8: 0 | G8: 0 | H8: 0 | I8: 0 | J8: 0 | K8: 0 | N8: 0 | O8: 0 | P8: 0 | Q8: 0 | R8: 0 | U8: 0 | V8: 0 | W8: 0 | X8: 0 | Y8: 0 | AB8: 0 | AC8: 0 | AD8: 0 | AE8: 4 | AF8: 0
A9: 7 | B9: 謝秉宏 | C9: =SUM(D9:AH9) -> 58 | D9: 0 | G9: 16 | H9: 0 | I9: 0 | J9: 0 | K9: 0 | N9: 0 | O9: 0 | P9: 0 | Q9: 0 | R9: 0 | U9: 8 | V9: 0 | W9: 16 | X9: 0 | Y9: 2 | AB9: 0 | AC9: 0 | AD9: 16 | AE9: 0 | AF9: 0
A10: 8 | B10: 林建宏 | C10: =SUM(D10:AH10) -> 0 | D10: 0 | G10: 0 | H10: 0 | I10: 0 | J10: 0 | K10: 0 | N10: 0 | O10: 0 | P10: 0 | Q10: 0 | R10: 0 | U10: 0 | V10: 0 | W10: 0 | X10: 0 | Y10: 0 | AB10: 0 | AC10: 0 | AD10: 0 | AE10: 0 | AF10: 0
A11: 9 | B11: 蘇景郁 | C11: =SUM(D11:AH11) -> 0 | D11: 0 | G11: 0 | H11: 0 | I11: 0 | J11: 0 | K11: 0 | N11: 0 | O11: 0 | P11: 0 | Q11: 0 | R11: 0 | U11: 0 | V11: 0 | W11: 0 | X11: 0 | Y11: 0 | AB11: 0 | AC11: 0 | AD11: 0 | AE11: 0 | AF11: 0
A12: 10 | B12: 潘其昌 | C12: =SUM(D12:AH12) -> 32 | D12: 0 | G12: 0 | H12: 0 | I12: 0 | J12: 0 | K12: 0 | N12: 0 | O12: 0 | P12: 0 | Q12: 0 | R12: 0 | U12: 0 | V12: 0 | W12: 16 | X12: 0 | Y12: 16 | AB12: 0 | AC12: 0 | AD12: 0 | AE12: 0 | AF12: 0
A13: 11 | B13: 陳俊男 | C13: =SUM(D13:AH13) -> 16 | D13: 0 | G13: 0 | H13: 16 | I13: 0 | J13: 0 | K13: 0 | N13: 0 | O13: 0 | P13: 0 | Q13: 0 | R13: 0 | U13: 0 | V13: 0 | W13: 0 | X13: 0 | Y13: 0 | AB13: 0 | AC13: 0 | AD13: 0 | AE13: 0 | AF13: 0
A14: 12 | B14: 林政宏 | C14: =SUM(D14:AH14) -> 22 | D14: 0 | G14: 0 | H14: 6 | I14: 0 | J14: 0 | K14: 0 | N14: 16 | O14: 0 | P14: 0 | Q14: 0 | R14: 0 | U14: 0 | V14: 0 | W14: 0 | X14: 0 | Y14: 0 | AB14: 0 | AC14: 0 | AD14: 0 | AE14: 0 | AF14: 0
... A16: 14 | B16: 劉益豪 | C16: =SUM(D16:AH16) -> 0 | D16: 0 | G16: 0 | H16: 0 | I16: 0 | J16: 0 | K16: 0 | N16: 0 | O16: 0 | P16: 0 | Q16: 0 | R16: 0 | U16: 0 | V16: 0 | W16: 0 | X16: 0 | Y16: 0 | AB16: 0 | AC16: 0 | AD16: 0 | AE16: 0 | AF16: 0

Sheet TP3月份加班
A1: TP加班 | C1: 三月累計 (0.5小時/單位) | D1: 45352 | E1: 45353 | F1: 45354 | G1: 45355 | H1: 45356 | I1: 45357 | J1: 45358 | K1: 45359 | L1: 45360 | M1: 45361 | N1: 45362 | O1: 45363 | P1: 45364 | Q1: 45365 | R1: 45366 | S1: 45367 | T1: 45368 | U1: 45369 | V1: 45370 | W1: 45371 | X1: 45372 | Y1: 45373 | Z1: 45374 | AA1: 45375 | AB1: 45376 | AC1: 45377 | AD1: 45378 | AE1: 45379 | AF1: 45380 | AG1: 45381 | AH1: 45382
A2: NO. | B2: 姓名
A3: 1 | B3: 郭先弘 | C3: =SUM(D3:AH3) -> 0 | D3: 0 | G3: 0 | H3: 0 | I3: 0 | J3: 0 | K3: 0 | N3: 0 | O3: 0 | P3: 0 | Q3: 0 | R3: 0 | U3: 0 | V3: 0 | W3: 0 | X3: 0 | Y3: 0 | AB3: 0 | AC3: 0 | AD3: 0 | AE3: 0 | AF3: 0
A4: 2 | B4: 陳淑芬 | C4: =SUM(D4:AH4) -> 8 | D4: 0 | G4: 0 | H4: 0 | I4: 0 | J4: 0 | K4: 0 | N4: 0 | O4: 0 | P4: 0 | Q4: 0 | R4: 0 | U4: 0 | V4: 0 | W4: 0 | X4: 0 | Y4: 0 | AB4: 0 | AC4: 0 | AD4: 0 | AE4: 8 | AF4: 0
A5: 3 | B5: 林世彬 | C5: =SUM(D5:AH5) -> 13 | D5: 0 | G5: 0 | H5: 0 | I5: 0 | J5: 0 | K5: 0 | N5: 0 | O5: 2 | P5: 2 | Q5: 2 | R5: 0 | U5: 0 | V5: 1 | W5: 0 | X5: 0 | Y5: 0 | AB5: 2 | AC5: 1 | AD5: 1 | AE5: 1 | AF5: 1
A6: 4 | B6: 何彥璋 | C6: =SUM(D6:AH6) -> 23 | D6: 0 | G6: 0 | H6: 0 | I6: 0 | J6: 0 | K6: 0 | N6: 0 | O6: 0 | P6: 0 | Q6: 0 | R6: 0 | S6: 16 | U6: 0 | V6: 2 | W6: 1 | X6: 0 | Y6: 0 | AB6: 2 | AC6: 0 | AD6: 2 | AE6: 0 | AF6: 0
A7: 5 | B7: 吳嘉銘 | C7: =SUM(D7:AH7) -> 16 | D7: 0 | G7: 0 | H7: 0 | I7: 0 | J7: 0 | K7: 0 | N7: 0 | O7: 0 | P7: 0 | Q7: 0 | R7: 0 | S7: 16 | U7: 0 | V7: 0 | W7: 0 | X7: 0 | Y7: 0 | AB7: 0 | AC7: 0 | AD7: 0 | AE7: 0 | AF7: 0
A8: 6 | B8: 林詠書 | C8: =SUM(D8:AH8) -> 38 | D8: 0 | G8: 2 | H8: 4 | I8: 3 | J8: 2 | K8: 1 | N8: 2 | O8: 2 | P8: 2 | Q8: 2 | R8: 1 | U8: 2 | V8: 3 | W8: 1 | X8: 1 | Y8: 2 | AB8: 2 | AC8: 2 | AD8: 2 | AE8: 0 | AF8: 2
A9: 7 | B9: 謝秉宏 | C9: =SUM(D9:AH9) -> 47 | D9: 1 | G9: 0 | H9: 0 | I9: 0 | J9: 6 | K9: 1 | N9: 1 | O9: 6 | P9: 4 | Q9: 7 | R9: 0 | U9: 0 | V9: 6 | W9: 0 | X9: 7 | Y9: 0 | AB9: 0 | AC9: 1 | AD9: 0 | AE9: 7 | AF9: 0
A10: 8 | B10: 林建宏 | C10: =SUM(D10:AH10) -> 0 | D10: 0 | G10: 0 | H10: 0 | I10: 0 | J10: 0 | K10: 0 | N10: 0 | O10: 0 | P10: 0 | Q10: 0 | R10: 0 | U10: 0 | V10: 0 | W10: 0 | X10: 0 | Y10: 0 | AB10: 0 | AC10: 0 | AD10: 0 | AE10: 0 | AF10: 0
A11: 9 | B11: 蘇景郁 | C11: =SUM(D11:AH11) -> 16 | D11: 0 | G11: 0 | H11: 0 | I11: 0 | J11: 0 | K11: 0 | N11: 0 | O11: 0 | P11: 0 | Q11: 0 | R11: 0 | S11: 16 | U11: 0 | V11: 0 | W11: 0 | X11: 0 | Y11: 0 | AB11: 0 | AC11: 0 | AD11: 0 | AE11: 0 | AF11: 0
A12: 10 | B12: 潘其昌 | C12: =SUM(D12:AH12) -> 16 | D12: 0 | G12: 0 | H12: 0 | I12: 0 | J12: 0 | K12: 0 | N12: 0 | O12: 0 | P12: 0 | Q12: 0 | R12: 0 | S12: 16 | U12: 0 | V12: 0 | W12: 0 | X12: 0 | Y12: 0 | AB12: 0 | AC12: 0 | AD12: 0 | AE12: 0 | AF12: 0
A13: 11 | B13: 陳俊男 | C13: =SUM(D13:AH13) -> 0 | D13: 0 | G13: 0 | H13: 0 | I13: 0 | J13: 0 | K13: 0 | N13: 0 | O13: 0 | P13: 0 | Q13: 0 | R13: 0 | U13: 0 | V13: 0 | W13: 0 | X13: 0 | Y13: 0 | AB13: 0 | AC13: 0 | AD13: 0 | AE13: 0 | AF13: 0
A14: 12 | B14: 林政宏 | C14: =SUM(D14:AH14) -> 33 | D14: 0 | G14: 0 | H14: 0 | I14: 0 | J14: 0 | K14: 0 | N14: 0 | O14: 0 | P14: 0 | Q14: 0 | R14: 0 | S14: 16 | U14: 0 | V14: 0 | W14: 0 | X14: 6 | Y14: 5 | AB14: 0 | AC14: 0 | AD14: 6 | AE14: 0 | AF14: 0
A15: 13 | B15: 陸長遠 | C15: =SUM(D15:AH15) -> 31 | D15: 2 | G15: 0 | H15: 0 | I15: 0 | J15: 0 | K15: 0 | N15: 0 | O15: 0 | P15: 0 | Q15: 0 | R15: 0 | S15: 16 | U15: 0 | V15: 0 | W15: 0 | X15: 0 | Y15: 0 | AB15: 0 | AC15: 0 | AD15: 0 | AE15: 4 | AF15: 4 | AG15: 5
A16: 14 | B16: 劉益豪 | C16: =SUM(D16:AH16) -> 34 | D16: 0 | G16: 0 | H16: 0 | I16: 0 | J16: 7 | K16: 0 | N16: 0 | O16: 0 | P16: 0 | Q16: 0 | R16: 0 | S16: 16 | U16: 0 | V16: 0 | W16: 0 | X16: 0 | Y16: 0 | AB16: 0 | AC16: 0 | AD16: 0 | AE16: 0 | AF16: 11

Sheet TP出勤4月份
A1: TP出勤 | C1: 45383 | D1: 45384 | E1: 45385 | F1: 45386 | G1: 45387 | H1: 45388 | I1: 45389 | J1: 45390 | K1: 45391 | L1: 45392 | M1: 45393 | N1: 45394 | O1: 45395 | P1: 45396 | Q1: 45397 | R1: 45398 | S1: 45399 | T1: 45400 | U1: 45401 | V1: 45402 | W1: 45403 | X1: 45404 | Y1: 45405 | Z1: 45406 | AA1: 45407 | AB1: 45408 | AC1: 45409 | AD1: 45410 | AE1: 45411 | AF1: 45412
A2: NO. | B2: 姓名
A3: 1 | B3: 郭先弘 | C3: ✓ | D3: ✓ | E3: ✓ | J3: ✓ | K3: ✓ | L3: ✓ | M3: ✓ | N3: ✓ | Q3: ✓ | R3: ✓ | S3: ✓ | T3: ✓ | U3: ✓ | X3: ✓ | Y3: ✓ | Z3: ✓ | AA3: ✓ | AB3: 出差 | AE3: 出差 | AF3: 出差
A4: 2 | B4: 陳淑芬 | C4: ✓ | D4: ✓ | E4: ✓ | J4: 出差 | K4: 出差 | L4: 出差 | M4: 出差 | N4: 出差 | Q4: 出差 | R4: 出差 | S4: 出差 | T4: 出差 | U4: 出差 | X4: 出差 | Y4: 出差 | Z4: 出差 | AA4: 出差 | AB4: 出差 | AE4: 出差 | AF4: 出差
A5: 3 | B5: 林世彬 | C5: ✓ | D5: ◎ | E5: ✓ | J5: ✓ | K5: ✓ | L5: ✓ | M5: ✓ | N5: ✓ | Q5: ✓ | R5: ✓ | S5: ✓ | T5: ✓ | U5: ✓ | X5: ✓ | Y5: ◎ | Z5: ✓ | AA5: 外出 | AB5: 外出 | AE5: ✓ | AF5: ✓
A6: 4 | B6: 何彥璋 | C6: 出差 | D6: 出差 | E6: 出差 | J6: 出差 | K6: 出差 | L6: 出差 | M6: 出差 | N6: 出差 | Q6: 出差 | R6: 出差 | S6: 出差 | T6: 出差 | U6: 出差 | X6: 出差 | Y6: 出差 | Z6: 出差 | AA6: 出差 | AB6: 出差 | AE6: 出差 | AF6: 出差
A7: 5 | B7: 吳嘉銘 | C7: 出差 | D7: ◎ | E7: ✓ | J7: ✓ | K7: ✓ | L7: ✓ | M7: 出差 | N7: 出差 | Q7: 出差 | R7: 出差 | S7: 出差 | T7: 出差 | U7: 出差 | X7: 出差 | Y7: 出差 | Z7: 出差 | AA7: 出差 | AB7: 出差 | AE7: 出差 | AF7: 出差
A8: 6 | B8: 林詠書 | C8: ✓ | D8: ✓ | E8: ✓ | J8: ✓ | K8: ✓ | L8: ✓ | M8: ✓ | N8: ✓ | Q8: ✓ | R8: ✓ | S8: ✓ | T8: ✓ | U8: ✓ | X8: ✓ | Y8: ✓ | Z8: ✓ | AA8: ✓ | AB8: ✓ | AE8: 陪產 | AF8: 陪產
A9: 7 | B9: 謝秉宏 | C9: ✓ | D9: ✓ | E9: ✓ | J9: △ | K9: ✓ | L9: ✓ | M9: ✓ | N9: ✓ | Q9: ✓ | R9: ✓ | S9: ✓ | T9: ✓ | U9: ✓ | X9: ✓ | Y9: ✓ | Z9: ✓ | AA9: ✓ | AB9: ✓ | AE9: ✓ | AF9: ✓
A10: 8 | B10: 林建宏 | C10: ✓ | D10: 補休 | E10: ✓ | J10: ✓ | K10: 特休 | L10: 出差 | M10: 出差 | N10: 出差 | Q10: 出差 | R10: 出差 | S10: 出差 | T10: 出差 | U10: 出差 | X10: 出差 | Y10: 出差 | Z10: 出差 | AA10: 出差 | AB10: 出差 | AE10: 出差 | AF10: 出差
A11: 9 | B11: 蘇景郁 | C11: 出差 | D11: ◎ | E11: ✓ | J11: ✓ | K11: ✓ | L11: ✓ | M11: 出差 | N11: 出差 | Q11: 出差 | R11: 出差 | S11: 出差 | T11: 出差 | U11: 出差 | X11: 出差 | Y11: 出差 | Z11: 出差 | AA11: 出差 | AB11: 出差 | AE11: 出差 | AF11: 出差
A12: 10 | B12: 潘其昌 | C12: 出差 | D12: 出差 | E12: 出差 | J12: 出差 | K12: 出差 | L12: 出差 | M12: 出差 | N12: 出差 | Q12: 出差 | R12: 出差 | S12: 出差 | T12: 出差 | U12: 出差 | X12: 出差 | Y12: 出差 | Z12: 出差 | AA12: 出差 | AB12: 出差 | AE12: 出差 | AF12: 出差
A13: 11 | B13: 陳俊男 | C13: 出差 | D13: 出差 | E13: 出差 | J13: ✓ | K13: ✓ | L13: ✓ | M13: ◎ | N13: 出差 | Q13: 出差 | R13: 出差 | S13: 出差 | T13: 出差 | U13: 出差 | X13: 出差 | Y13: 出差 | Z13: 出差 | AA13: 出差 | AB13: 出差 | AE13: 出差 | AF13: 出差
A14: 12 | B14: 林政宏 | C14: 出差 | D14: 出差 | E14: 出差 | J14: 出差 | K14: 出差 | L14: 出差 | M14: 出差 | N14: 出差 | Q14: 出差 | R14: ✓ | S14: ✓ | T14: ◎ | U14: 出差 | X14: 出差 | Y14: 出差 | Z14: 出差 | AA14: 出差 | AB14: 出差 | AE14: 出差 | AF14: 出差
... A16: 14 | B16: 劉益豪 | C16: 出差 | D16: 出差 | E16: 出差 | J16: 出差 | K16: 出差 | L16: 出差 | M16: 出差 | N16: 出差 | Q16: 出差 | R16: 出差 | S16: 出差 | T16: ◎ | U16: ◎ | X16: ✓ | Y16: ✓ | Z16: ✓ | AA16: ✓ | AB16: ✓ | AE16: ◎ | AF16: 補休
A17: ✓ | B17: 正常
A18: ◎ | B18: 補休
A19: △ | B19: 遲到

Sheet TP4月份請假
A1: TP請假 | C1: 四月累計 (0.5小時/單位) | D1: 45383 | E1: 45384 | F1: 45385 | G1: 45386 | H1: 45387 | I1: 45388 | J1: 45389 | K1: 45390 | L1: 45391 | M1: 45392 | N1: 45393 | O1: 45394 | P1: 45395 | Q1: 45396 | R1: 45397 | S1: 45398 | T1: 45399 | U1: 45400 | V1: 45401 | W1: 45402 | X1: 45403 | Y1: 45404 | Z1: 45405 | AA1: 45406 | AB1: 45407 | AC1: 45408 | AD1: 45409 | AE1: 45410 | AF1: 45411 | AG1: 45412
A2: NO. | B2: 姓名
A3: 1 | B3: 郭先弘 | C3: =SUM(D3:AG3) -> 0 | D3: 0 | E3: 0 | F3: 0 | K3: 0 | L3: 0 | M3: 0 | N3: 0 | O3: 0 | R3: 0 | S3: 0 | T3: 0 | U3: 0 | V3: 0 | Y3: 0 | Z3: 0 | AA3: 0 | AB3: 0 | AC3: 0 | AF3: 0 | AG3: 0
A4: 2 | B4: 陳淑芬 | C4: =SUM(D4:AG4) -> 8 | D4: 8 | E4: 0 | F4: 0 | K4: 0 | L4: 0 | M4: 0 | N4: 0 | O4: 0 | R4: 0 | S4: 0 | T4: 0 | U4: 0 | V4: 0 | Y4: 0 | Z4: 0 | AA4: 0 | AB4: 0 | AC4: 0 | AF4: 0 | AG4: 0
A5: 3 | B5: 林世彬 | C5: =SUM(D5:AG5) -> 32 | D5: 0 | E5: 16 | F5: 8 | K5: 4 | L5: 0 | M5: 0 | N5: 0 | O5: 0 | R5: 0 | S5: 0 | T5: 0 | U5: 0 | V5: 0 | Y5: 0 | Z5: 4 | AA5: 0 | AB5: 0 | AC5: 0 | AF5: 0 | AG5: 0
A6: 4 | B6: 何彥璋 | C6: =SUM(D6:AG6) -> 0 | D6: 0 | E6: 0 | F6: 0 | K6: 0 | L6: 0 | M6: 0 | N6: 0 | O6: 0 | R6: 0 | S6: 0 | T6: 0 | U6: 0 | V6: 0 | Y6: 0 | Z6: 0 | AA6: 0 | AB6: 0 | AC6: 0 | AF6: 0 | AG6: 0
A7: 5 | B7: 吳嘉銘 | C7: =SUM(D7:AG7) -> 32 | D7: 0 | E7: 16 | F7: 0 | K7: 0 | L7: 0 | M7: 0 | N7: 16 | O7: 0 | R7: 0 | S7: 0 | T7: 0 | U7: 0 | V7: 0 | Y7: 0 | Z7: 0 | AA7: 0 | AB7: 0 | AC7: 0 | AF7: 0 | AG7: 0
A8: 6 | B8: 林詠書 | C8: =SUM(D8:AG8) -> 0 | D8: 0 | E8: 0 | F8: 0 | K8: 0 | L8: 0 | M8: 0 | N8: 0 | O8: 0 | R8: 0 | S8: 0 | T8: 0 | U8: 0 | V8: 0 | Y8: 0 | Z8: 0 | AA8: 0 | AB8: 0 | AC8: 0 | AF8: 0 | AG8: 0
A9: 7 | B9: 謝秉宏 | C9: =SUM(D9:AG9) -> 5 | D9: 0 | E9: 3 | F9: 0 | K9: 0 | L9: 0 | M9: 0 | N9: 0 | O9: 0 | R9: 0 | S9: 0 | T9: 0 | U9: 0 | V9: 0 | Y9: 0 | Z9: 0 | AA9: 0 | AB9: 0 | AC9: 2 | AF9: 0 | AG9: 0
A10: 8 | B10: 林建宏 | C10: =SUM(D10:AG10) -> 0 | D10: 0 | E10: 0 | F10: 0 | K10: 0 | L10: 0 | M10: 0 | N10: 0 | O10: 0 | R10: 0 | S10: 0 | T10: 0 | U10: 0 | V10: 0 | Y10: 0 | Z10: 0 | AA10: 0 | AB10: 0 | AC10: 0 | AF10: 0 | AG10: 0
A11: 9 | B11: 蘇景郁 | C11: =SUM(D11:AG11) -> 39 | D11: 0 | E11: 16 | F11: 0 | K11: 0 | L11: 7 | M11: 0 | N11: 16 | O11: 0 | R11: 0 | S11: 0 | T11: 0 | U11: 0 | V11: 0 | Y11: 0 | Z11: 0 | AA11: 0 | AB11: 0 | AC11: 0 | AF11: 0 | AG11: 0
A12: 10 | B12: 潘其昌 | C12: =SUM(D12:AG12) -> 0 | D12: 0 | E12: 0 | F12: 0 | K12: 0 | L12: 0 | M12: 0 | N12: 0 | O12: 0 | R12: 0 | S12: 0 | T12: 0 | U12: 0 | V12: 0 | Y12: 0 | Z12: 0 | AA12: 0 | AB12: 0 | AC12: 0 | AF12: 0 | AG12: 0
A13: 11 | B13: 陳俊男 | C13: =SUM(D13:AG13) -> 22 | D13: 0 | E13: 0 | F13: 0 | K13: 4 | L13: 0 | M13: 0 | N13: 2 | O13: 16 | R13: 0 | S13: 0 | T13: 0 | U13: 0 | V13: 0 | Y13: 0 | Z13: 0 | AA13: 0 | AB13: 0 | AC13: 0 | AF13: 0 | AG13: 0
A14: 12 | B14: 林政宏 | C14: =SUM(D14:AG14) -> 16 | D14: 0 | E14: 0 | F14: 0 | K14: 0 | L14: 0 | M14: 0 | N14: 0 | O14: 0 | R14: 0 | S14: 0 | T14: 0 | U14: 16 | V14: 0 | Y14: 0 | Z14: 0 | AA14: 0 | AB14: 0 | AC14: 0 | AF14: 0 | AG14: 0
... A16: 14 | B16: 劉益豪 | C16: =SUM(D16:AG16) -> 33 | D16: 0 | E16: 0 | F16: 0 | K16: 0 | L16: 0 | M16: 0 | N16: 0 | O16: 0 | R16: 0 | S16: 0 | T16: 0 | U16: 1 | V16: 16 | Y16: 0 | Z16: 0 | AA16: 0 | AB16: 0 | AC16: 0 | AF16: 16 | AG16: 0

Sheet TP4月份加班
A1: TP加班 | C1: 四月累計 (0.5小時/單位) | D1: 45383 | E1: 45384 | F1: 45385 | G1: 45386 | H1: 45387 | I1: 45388 | J1: 45389 | K1: 45390 | L1: 45391 | M1: 45392 | N1: 45393 | O1: 45394 | P1: 45395 | Q1: 45396 | R1: 45397 | S1: 45398 | T1: 45399 | U1: 45400 | V1: 45401 | W1: 45402 | X1: 45403 | Y1: 45404 | Z1: 45405 | AA1: 45406 | AB1: 45407 | AC1: 45408 | AD1: 45409 | AE1: 45410 | AF1: 45411 | AG1: 45412
A2: NO. | B2: 姓名
A3: 1 | B3: 郭先弘 | C3: =SUM(D3:AG3) -> 0 | D3: 0 | E3: 0 | F3: 0 | K3: 0 | L3: 0 | M3: 0 | N3: 0 | O3: 0 | R3: 0 | S3: 0 | T3: 0 | U3: 0 | V3: 0 | Y3: 0 | Z3: 0 | AA3: 0 | AB3: 0 | AC3: 0 | AF3: 0 | AG3: 0
A4: 2 | B4: 陳淑芬 | C4: =SUM(D4:AG4) -> 5 | D4: 0 | E4: 0 | F4: 0 | K4: 0 | L4: 0 | M4: 0 | N4: 0 | O4: 0 | R4: 0 | S4: 0 | T4: 0 | U4: 5 | V4: 0 | Y4: 0 | Z4: 0 | AA4: 0 | AB4: 0 | AC4: 0 | AF4: 0 | AG4: 0
A5: 3 | B5: 林世彬 | C5: =SUM(D5:AG5) -> 0 | D5: 0 | E5: 0 | F5: 0 | K5: 0 | L5: 0 | M5: 0 | N5: 0 | O5: 0 | R5: 0 | S5: 0 | T5: 0 | U5: 0 | V5: 0 | Y5: 0 | Z5: 0 | AA5: 0 | AB5: 0 | AC5: 0 | AF5: 0 | AG5: 0
A6: 4 | B6: 何彥璋 | C6: =SUM(D6:AG6) -> 11 | D6: 0 | E6: 0 | F6: 0 | K6: 0 | L6: 0 | M6: 0 | N6: 6 | O6: 0 | R6: 0 | S6: 0 | T6: 0 | U6: 5 | V6: 0 | Y6: 0 | Z6: 0 | AA6: 0 | AB6: 0 | AC6: 0 | AF6: 0 | AG6: 0
A7: 5 | B7: 吳嘉銘 | C7: =SUM(D7:AG7) -> 5 | D7: 0 | E7: 0 | F7: 0 | K7: 0 | L7: 0 | M7: 0 | N7: 0 | O7: 0 | R7: 0 | S7: 0 | T7: 0 | U7: 5 | V7: 0 | Y7: 0 | Z7: 0 | AA7: 0 | AB7: 0 | AC7: 0 | AF7: 0 | AG7: 0
A8: 6 | B8: 林詠書 | C8: =SUM(D8:AG8) -> 19 | D8: 1 | E8: 2 | F8: 1 | K8: 2 | L8: 3 | M8: 1 | N8: 0 | O8: 1 | R8: 1 | S8: 1 | T8: 0 | U8: 2 | V8: 0 | Y8: 0 | Z8: 1 | AA8: 1 | AB8: 1 | AC8: 1 | AF8: 0 | AG8: 0
A9: 7 | B9: 謝秉宏 | C9: =SUM(D9:AG9) -> 23 | D9: 1 | E9: 0 | F9: 0 | K9: 1 | L9: 0 | M9: 0 | N9: 1 | O9: 1 | R9: 1 | S9: 1 | T9: 1 | U9: 1 | V9: 0 | Y9: 2 | Z9: 7 | AA9: 0 | AB9: 6 | AC9: 0 | AF9: 0 | AG9: 0
A10: 8 | B10: 林建宏 | C10: =SUM(D10:AG10) -> 11 | D10: 0 | E10: 0 | F10: 0 | K10: 0 | L10: 0 | M10: 0 | N10: 6 | O10: 0 | R10: 0 | S10: 0 | T10: 0 | U10: 5 | V10: 0 | Y10: 0 | Z10: 0 | AA10: 0 | AB10: 0 | AC10: 0 | AF10: 0 | AG10: 0
A11: 9 | B11: 蘇景郁 | C11: =SUM(D11:AG11) -> 8 | D11: 0 | E11: 0 | F11: 0 | K11: 1 | L11: 2 | M11: 0 | N11: 0 | O11: 0 | R11: 0 | S11: 0 | T11: 0 | U11: 5 | V11: 0 | Y11: 0 | Z11: 0 | AA11: 0 | AB11: 0 | AC11: 0 | AF11: 0 | AG11: 0
A12: 10 | B12: 潘其昌 | C12: =SUM(D12:AG12) -> 22 | D12: 0 | E12: 0 | F12: 0 | K12: 0 | L12: 0 | M12: 0 | N12: 6 | O12: 0 | R12: 0 | S12: 0 | T12: 0 | U12: 0 | V12: 0 | W12: 16 | Y12: 0 | Z12: 0 | AA12: 0 | AB12: 0 | AC12: 0 | AF12: 0 | AG12: 0
A13: 11 | B13: 陳俊男 | C13: =SUM(D13:AG13) -> 60 | D13: 0 | E13: 0 | F13: 0 | K13: 0 | L13: 5 | M13: 0 | N13: 0 | O13: 0 | R13: 0 | S13: 8 | T13: 9 | U13: 10 | V13: 8 | Y13: 0 | Z13: 0 | AA13: 0 | AB13: 8 | AC13: 6 | AF13: 6 | AG13: 0
